2018-08-07 10:56:38,339 - Utils.log_utils - ERROR - Traceback (most recent call last):
  File "F:\scribe2\venv\lib\site-packages\socks.py", line 832, in connect
    super(socksocket, self).connect(proxy_addr)
socket.timeout: timed out

During handling of the above exception, another exception occurred:

Traceback (most recent call last):
  File "F:\scribe2\venv\lib\site-packages\urllib3\contrib\socks.py", line 88, in _new_conn
    **extra_kw
  File "F:\scribe2\venv\lib\site-packages\socks.py", line 262, in create_connection
    raise err
  File "F:\scribe2\venv\lib\site-packages\socks.py", line 252, in create_connection
    sock.connect((remote_host, remote_port))
  File "F:\scribe2\venv\lib\site-packages\socks.py", line 100, in wrapper
    return function(*args, **kwargs)
  File "F:\scribe2\venv\lib\site-packages\socks.py", line 844, in connect
    raise ProxyConnectionError(msg, error)
socks.ProxyConnectionError: Error connecting to SOCKS5 proxy 188.120.234.190:31214: timed out

During handling of the above exception, another exception occurred:

Traceback (most recent call last):
  File "F:\scribe2\venv\lib\site-packages\urllib3\connectionpool.py", line 601, in urlopen
    chunked=chunked)
  File "F:\scribe2\venv\lib\site-packages\urllib3\connectionpool.py", line 346, in _make_request
    self._validate_conn(conn)
  File "F:\scribe2\venv\lib\site-packages\urllib3\connectionpool.py", line 850, in _validate_conn
    conn.connect()
  File "F:\scribe2\venv\lib\site-packages\urllib3\connection.py", line 284, in connect
    conn = self._new_conn()
  File "F:\scribe2\venv\lib\site-packages\urllib3\contrib\socks.py", line 105, in _new_conn
    (self.host, self.timeout)
urllib3.exceptions.ConnectTimeoutError: (<urllib3.contrib.socks.SOCKSHTTPSConnection object at 0x0000000006189CC0>, 'Connection to www.baidu.com timed out. (connect timeout=10)')

During handling of the above exception, another exception occurred:

Traceback (most recent call last):
  File "F:\scribe2\venv\lib\site-packages\requests\adapters.py", line 440, in send
    timeout=timeout
  File "F:\scribe2\venv\lib\site-packages\urllib3\connectionpool.py", line 639, in urlopen
    _stacktrace=sys.exc_info()[2])
  File "F:\scribe2\venv\lib\site-packages\urllib3\util\retry.py", line 388, in increment
    raise MaxRetryError(_pool, url, error or ResponseError(cause))
urllib3.exceptions.MaxRetryError: SOCKSHTTPSConnectionPool(host='www.baidu.com', port=443): Max retries exceeded with url: / (Caused by ConnectTimeoutError(<urllib3.contrib.socks.SOCKSHTTPSConnection object at 0x0000000006189CC0>, 'Connection to www.baidu.com timed out. (connect timeout=10)'))

During handling of the above exception, another exception occurred:

Traceback (most recent call last):
  File "F:\scribe2\Server\Service\fanqiang_ip_service.py", line 20, in get_random_ip_port_dict
    test_proxy(ip_port_dict)
  File "F:\scribe2\Server\Service\fanqiang_ip_service.py", line 65, in test_proxy
    timeout=10)
  File "F:\scribe2\venv\lib\site-packages\requests\api.py", line 72, in get
    return request('get', url, params=params, **kwargs)
  File "F:\scribe2\venv\lib\site-packages\requests\api.py", line 58, in request
    return session.request(method=method, url=url, **kwargs)
  File "F:\scribe2\venv\lib\site-packages\requests\sessions.py", line 508, in request
    resp = self.send(prep, **send_kwargs)
  File "F:\scribe2\venv\lib\site-packages\requests\sessions.py", line 618, in send
    r = adapter.send(request, **kwargs)
  File "F:\scribe2\venv\lib\site-packages\requests\adapters.py", line 496, in send
    raise ConnectTimeout(e, request=request)
requests.exceptions.ConnectTimeout: SOCKSHTTPSConnectionPool(host='www.baidu.com', port=443): Max retries exceeded with url: / (Caused by ConnectTimeoutError(<urllib3.contrib.socks.SOCKSHTTPSConnection object at 0x0000000006189CC0>, 'Connection to www.baidu.com timed out. (connect timeout=10)'))

During handling of the above exception, another exception occurred:

Traceback (most recent call last):
  File "F:/scribe2/Server/server.py", line 28, in get_lans_data
    ip_with_port=fanqiang_ip_service.get_random_ip_port_dict()
  File "F:\scribe2\Server\Service\fanqiang_ip_service.py", line 24, in get_random_ip_port_dict
    return get_random_ip_port_dict()
  File "F:\scribe2\Server\Service\fanqiang_ip_service.py", line 20, in get_random_ip_port_dict
    test_proxy(ip_port_dict)
  File "F:\scribe2\Server\Service\fanqiang_ip_service.py", line 67, in test_proxy
    location = scribe_utils.get_location(ip_with_port.split(':')[0])
  File "F:\scribe2\Utils\scribe_utils.py", line 215, in get_location
    reader = geoip2.database.Reader('file/GeoLite2-City_20180501/GeoLite2-City.mmdb')
  File "F:\scribe2\venv\lib\site-packages\geoip2\database.py", line 86, in __init__
    self._db_reader = maxminddb.open_database(fileish, mode)
  File "F:\scribe2\venv\lib\site-packages\maxminddb\__init__.py", line 41, in open_database
    return maxminddb.reader.Reader(database, mode)
  File "F:\scribe2\venv\lib\site-packages\maxminddb\reader.py", line 52, in __init__
    with open(database, 'rb') as db_file:
FileNotFoundError: [Errno 2] No such file or directory: 'file/GeoLite2-City_20180501/GeoLite2-City.mmdb'

2018-08-07 11:00:04,126 - Utils.log_utils - ERROR - Traceback (most recent call last):
  File "F:\scribe2\venv\lib\site-packages\socks.py", line 832, in connect
    super(socksocket, self).connect(proxy_addr)
socket.timeout: timed out

During handling of the above exception, another exception occurred:

Traceback (most recent call last):
  File "F:\scribe2\venv\lib\site-packages\urllib3\contrib\socks.py", line 88, in _new_conn
    **extra_kw
  File "F:\scribe2\venv\lib\site-packages\socks.py", line 262, in create_connection
    raise err
  File "F:\scribe2\venv\lib\site-packages\socks.py", line 252, in create_connection
    sock.connect((remote_host, remote_port))
  File "F:\scribe2\venv\lib\site-packages\socks.py", line 100, in wrapper
    return function(*args, **kwargs)
  File "F:\scribe2\venv\lib\site-packages\socks.py", line 844, in connect
    raise ProxyConnectionError(msg, error)
socks.ProxyConnectionError: Error connecting to SOCKS5 proxy 188.120.224.172:51036: timed out

During handling of the above exception, another exception occurred:

Traceback (most recent call last):
  File "F:\scribe2\venv\lib\site-packages\urllib3\connectionpool.py", line 601, in urlopen
    chunked=chunked)
  File "F:\scribe2\venv\lib\site-packages\urllib3\connectionpool.py", line 346, in _make_request
    self._validate_conn(conn)
  File "F:\scribe2\venv\lib\site-packages\urllib3\connectionpool.py", line 850, in _validate_conn
    conn.connect()
  File "F:\scribe2\venv\lib\site-packages\urllib3\connection.py", line 284, in connect
    conn = self._new_conn()
  File "F:\scribe2\venv\lib\site-packages\urllib3\contrib\socks.py", line 105, in _new_conn
    (self.host, self.timeout)
urllib3.exceptions.ConnectTimeoutError: (<urllib3.contrib.socks.SOCKSHTTPSConnection object at 0x0000000006542C18>, 'Connection to www.baidu.com timed out. (connect timeout=10)')

During handling of the above exception, another exception occurred:

Traceback (most recent call last):
  File "F:\scribe2\venv\lib\site-packages\requests\adapters.py", line 440, in send
    timeout=timeout
  File "F:\scribe2\venv\lib\site-packages\urllib3\connectionpool.py", line 639, in urlopen
    _stacktrace=sys.exc_info()[2])
  File "F:\scribe2\venv\lib\site-packages\urllib3\util\retry.py", line 388, in increment
    raise MaxRetryError(_pool, url, error or ResponseError(cause))
urllib3.exceptions.MaxRetryError: SOCKSHTTPSConnectionPool(host='www.baidu.com', port=443): Max retries exceeded with url: / (Caused by ConnectTimeoutError(<urllib3.contrib.socks.SOCKSHTTPSConnection object at 0x0000000006542C18>, 'Connection to www.baidu.com timed out. (connect timeout=10)'))

During handling of the above exception, another exception occurred:

Traceback (most recent call last):
  File "F:\scribe2\Server\Service\fanqiang_ip_service.py", line 20, in get_random_ip_port_dict
    test_proxy(ip_port_dict)
  File "F:\scribe2\Server\Service\fanqiang_ip_service.py", line 65, in test_proxy
    timeout=10)
  File "F:\scribe2\venv\lib\site-packages\requests\api.py", line 72, in get
    return request('get', url, params=params, **kwargs)
  File "F:\scribe2\venv\lib\site-packages\requests\api.py", line 58, in request
    return session.request(method=method, url=url, **kwargs)
  File "F:\scribe2\venv\lib\site-packages\requests\sessions.py", line 508, in request
    resp = self.send(prep, **send_kwargs)
  File "F:\scribe2\venv\lib\site-packages\requests\sessions.py", line 618, in send
    r = adapter.send(request, **kwargs)
  File "F:\scribe2\venv\lib\site-packages\requests\adapters.py", line 496, in send
    raise ConnectTimeout(e, request=request)
requests.exceptions.ConnectTimeout: SOCKSHTTPSConnectionPool(host='www.baidu.com', port=443): Max retries exceeded with url: / (Caused by ConnectTimeoutError(<urllib3.contrib.socks.SOCKSHTTPSConnection object at 0x0000000006542C18>, 'Connection to www.baidu.com timed out. (connect timeout=10)'))

During handling of the above exception, another exception occurred:

Traceback (most recent call last):
  File "F:/scribe2/Server/server.py", line 28, in get_lans_data
    ip_with_port=fanqiang_ip_service.get_random_ip_port_dict()
  File "F:\scribe2\Server\Service\fanqiang_ip_service.py", line 24, in get_random_ip_port_dict
    return get_random_ip_port_dict()
  File "F:\scribe2\Server\Service\fanqiang_ip_service.py", line 20, in get_random_ip_port_dict
    test_proxy(ip_port_dict)
  File "F:\scribe2\Server\Service\fanqiang_ip_service.py", line 67, in test_proxy
    location = scribe_utils.get_location(ip_with_port.split(':')[0])
  File "F:\scribe2\Utils\scribe_utils.py", line 215, in get_location
    reader = geoip2.database.Reader('file/GeoLite2-City_20180501/GeoLite2-City.mmdb')
  File "F:\scribe2\venv\lib\site-packages\geoip2\database.py", line 86, in __init__
    self._db_reader = maxminddb.open_database(fileish, mode)
  File "F:\scribe2\venv\lib\site-packages\maxminddb\__init__.py", line 41, in open_database
    return maxminddb.reader.Reader(database, mode)
  File "F:\scribe2\venv\lib\site-packages\maxminddb\reader.py", line 52, in __init__
    with open(database, 'rb') as db_file:
FileNotFoundError: [Errno 2] No such file or directory: 'file/GeoLite2-City_20180501/GeoLite2-City.mmdb'

