2018-08-07 10:56:38,339 - Utils.log_utils - ERROR - Traceback (most recent call last):
  File "F:\scribe2\venv\lib\site-packages\socks.py", line 832, in connect
    super(socksocket, self).connect(proxy_addr)
socket.timeout: timed out

During handling of the above exception, another exception occurred:

Traceback (most recent call last):
  File "F:\scribe2\venv\lib\site-packages\urllib3\contrib\socks.py", line 88, in _new_conn
    **extra_kw
  File "F:\scribe2\venv\lib\site-packages\socks.py", line 262, in create_connection
    raise err
  File "F:\scribe2\venv\lib\site-packages\socks.py", line 252, in create_connection
    sock.connect((remote_host, remote_port))
  File "F:\scribe2\venv\lib\site-packages\socks.py", line 100, in wrapper
    return function(*args, **kwargs)
  File "F:\scribe2\venv\lib\site-packages\socks.py", line 844, in connect
    raise ProxyConnectionError(msg, error)
socks.ProxyConnectionError: Error connecting to SOCKS5 proxy 188.120.234.190:31214: timed out

During handling of the above exception, another exception occurred:

Traceback (most recent call last):
  File "F:\scribe2\venv\lib\site-packages\urllib3\connectionpool.py", line 601, in urlopen
    chunked=chunked)
  File "F:\scribe2\venv\lib\site-packages\urllib3\connectionpool.py", line 346, in _make_request
    self._validate_conn(conn)
  File "F:\scribe2\venv\lib\site-packages\urllib3\connectionpool.py", line 850, in _validate_conn
    conn.connect()
  File "F:\scribe2\venv\lib\site-packages\urllib3\connection.py", line 284, in connect
    conn = self._new_conn()
  File "F:\scribe2\venv\lib\site-packages\urllib3\contrib\socks.py", line 105, in _new_conn
    (self.host, self.timeout)
urllib3.exceptions.ConnectTimeoutError: (<urllib3.contrib.socks.SOCKSHTTPSConnection object at 0x0000000006189CC0>, 'Connection to www.baidu.com timed out. (connect timeout=10)')

During handling of the above exception, another exception occurred:

Traceback (most recent call last):
  File "F:\scribe2\venv\lib\site-packages\requests\adapters.py", line 440, in send
    timeout=timeout
  File "F:\scribe2\venv\lib\site-packages\urllib3\connectionpool.py", line 639, in urlopen
    _stacktrace=sys.exc_info()[2])
  File "F:\scribe2\venv\lib\site-packages\urllib3\util\retry.py", line 388, in increment
    raise MaxRetryError(_pool, url, error or ResponseError(cause))
urllib3.exceptions.MaxRetryError: SOCKSHTTPSConnectionPool(host='www.baidu.com', port=443): Max retries exceeded with url: / (Caused by ConnectTimeoutError(<urllib3.contrib.socks.SOCKSHTTPSConnection object at 0x0000000006189CC0>, 'Connection to www.baidu.com timed out. (connect timeout=10)'))

During handling of the above exception, another exception occurred:

Traceback (most recent call last):
  File "F:\scribe2\Server\Service\fanqiang_ip_service.py", line 20, in get_random_ip_port_dict
    test_proxy(ip_port_dict)
  File "F:\scribe2\Server\Service\fanqiang_ip_service.py", line 65, in test_proxy
    timeout=10)
  File "F:\scribe2\venv\lib\site-packages\requests\api.py", line 72, in get
    return request('get', url, params=params, **kwargs)
  File "F:\scribe2\venv\lib\site-packages\requests\api.py", line 58, in request
    return session.request(method=method, url=url, **kwargs)
  File "F:\scribe2\venv\lib\site-packages\requests\sessions.py", line 508, in request
    resp = self.send(prep, **send_kwargs)
  File "F:\scribe2\venv\lib\site-packages\requests\sessions.py", line 618, in send
    r = adapter.send(request, **kwargs)
  File "F:\scribe2\venv\lib\site-packages\requests\adapters.py", line 496, in send
    raise ConnectTimeout(e, request=request)
requests.exceptions.ConnectTimeout: SOCKSHTTPSConnectionPool(host='www.baidu.com', port=443): Max retries exceeded with url: / (Caused by ConnectTimeoutError(<urllib3.contrib.socks.SOCKSHTTPSConnection object at 0x0000000006189CC0>, 'Connection to www.baidu.com timed out. (connect timeout=10)'))

During handling of the above exception, another exception occurred:

Traceback (most recent call last):
  File "F:/scribe2/Server/server.py", line 28, in get_lans_data
    ip_with_port=fanqiang_ip_service.get_random_ip_port_dict()
  File "F:\scribe2\Server\Service\fanqiang_ip_service.py", line 24, in get_random_ip_port_dict
    return get_random_ip_port_dict()
  File "F:\scribe2\Server\Service\fanqiang_ip_service.py", line 20, in get_random_ip_port_dict
    test_proxy(ip_port_dict)
  File "F:\scribe2\Server\Service\fanqiang_ip_service.py", line 67, in test_proxy
    location = scribe_utils.get_location(ip_with_port.split(':')[0])
  File "F:\scribe2\Utils\scribe_utils.py", line 215, in get_location
    reader = geoip2.database.Reader('file/GeoLite2-City_20180501/GeoLite2-City.mmdb')
  File "F:\scribe2\venv\lib\site-packages\geoip2\database.py", line 86, in __init__
    self._db_reader = maxminddb.open_database(fileish, mode)
  File "F:\scribe2\venv\lib\site-packages\maxminddb\__init__.py", line 41, in open_database
    return maxminddb.reader.Reader(database, mode)
  File "F:\scribe2\venv\lib\site-packages\maxminddb\reader.py", line 52, in __init__
    with open(database, 'rb') as db_file:
FileNotFoundError: [Errno 2] No such file or directory: 'file/GeoLite2-City_20180501/GeoLite2-City.mmdb'

2018-08-07 11:00:04,126 - Utils.log_utils - ERROR - Traceback (most recent call last):
  File "F:\scribe2\venv\lib\site-packages\socks.py", line 832, in connect
    super(socksocket, self).connect(proxy_addr)
socket.timeout: timed out

During handling of the above exception, another exception occurred:

Traceback (most recent call last):
  File "F:\scribe2\venv\lib\site-packages\urllib3\contrib\socks.py", line 88, in _new_conn
    **extra_kw
  File "F:\scribe2\venv\lib\site-packages\socks.py", line 262, in create_connection
    raise err
  File "F:\scribe2\venv\lib\site-packages\socks.py", line 252, in create_connection
    sock.connect((remote_host, remote_port))
  File "F:\scribe2\venv\lib\site-packages\socks.py", line 100, in wrapper
    return function(*args, **kwargs)
  File "F:\scribe2\venv\lib\site-packages\socks.py", line 844, in connect
    raise ProxyConnectionError(msg, error)
socks.ProxyConnectionError: Error connecting to SOCKS5 proxy 188.120.224.172:51036: timed out

During handling of the above exception, another exception occurred:

Traceback (most recent call last):
  File "F:\scribe2\venv\lib\site-packages\urllib3\connectionpool.py", line 601, in urlopen
    chunked=chunked)
  File "F:\scribe2\venv\lib\site-packages\urllib3\connectionpool.py", line 346, in _make_request
    self._validate_conn(conn)
  File "F:\scribe2\venv\lib\site-packages\urllib3\connectionpool.py", line 850, in _validate_conn
    conn.connect()
  File "F:\scribe2\venv\lib\site-packages\urllib3\connection.py", line 284, in connect
    conn = self._new_conn()
  File "F:\scribe2\venv\lib\site-packages\urllib3\contrib\socks.py", line 105, in _new_conn
    (self.host, self.timeout)
urllib3.exceptions.ConnectTimeoutError: (<urllib3.contrib.socks.SOCKSHTTPSConnection object at 0x0000000006542C18>, 'Connection to www.baidu.com timed out. (connect timeout=10)')

During handling of the above exception, another exception occurred:

Traceback (most recent call last):
  File "F:\scribe2\venv\lib\site-packages\requests\adapters.py", line 440, in send
    timeout=timeout
  File "F:\scribe2\venv\lib\site-packages\urllib3\connectionpool.py", line 639, in urlopen
    _stacktrace=sys.exc_info()[2])
  File "F:\scribe2\venv\lib\site-packages\urllib3\util\retry.py", line 388, in increment
    raise MaxRetryError(_pool, url, error or ResponseError(cause))
urllib3.exceptions.MaxRetryError: SOCKSHTTPSConnectionPool(host='www.baidu.com', port=443): Max retries exceeded with url: / (Caused by ConnectTimeoutError(<urllib3.contrib.socks.SOCKSHTTPSConnection object at 0x0000000006542C18>, 'Connection to www.baidu.com timed out. (connect timeout=10)'))

During handling of the above exception, another exception occurred:

Traceback (most recent call last):
  File "F:\scribe2\Server\Service\fanqiang_ip_service.py", line 20, in get_random_ip_port_dict
    test_proxy(ip_port_dict)
  File "F:\scribe2\Server\Service\fanqiang_ip_service.py", line 65, in test_proxy
    timeout=10)
  File "F:\scribe2\venv\lib\site-packages\requests\api.py", line 72, in get
    return request('get', url, params=params, **kwargs)
  File "F:\scribe2\venv\lib\site-packages\requests\api.py", line 58, in request
    return session.request(method=method, url=url, **kwargs)
  File "F:\scribe2\venv\lib\site-packages\requests\sessions.py", line 508, in request
    resp = self.send(prep, **send_kwargs)
  File "F:\scribe2\venv\lib\site-packages\requests\sessions.py", line 618, in send
    r = adapter.send(request, **kwargs)
  File "F:\scribe2\venv\lib\site-packages\requests\adapters.py", line 496, in send
    raise ConnectTimeout(e, request=request)
requests.exceptions.ConnectTimeout: SOCKSHTTPSConnectionPool(host='www.baidu.com', port=443): Max retries exceeded with url: / (Caused by ConnectTimeoutError(<urllib3.contrib.socks.SOCKSHTTPSConnection object at 0x0000000006542C18>, 'Connection to www.baidu.com timed out. (connect timeout=10)'))

During handling of the above exception, another exception occurred:

Traceback (most recent call last):
  File "F:/scribe2/Server/server.py", line 28, in get_lans_data
    ip_with_port=fanqiang_ip_service.get_random_ip_port_dict()
  File "F:\scribe2\Server\Service\fanqiang_ip_service.py", line 24, in get_random_ip_port_dict
    return get_random_ip_port_dict()
  File "F:\scribe2\Server\Service\fanqiang_ip_service.py", line 20, in get_random_ip_port_dict
    test_proxy(ip_port_dict)
  File "F:\scribe2\Server\Service\fanqiang_ip_service.py", line 67, in test_proxy
    location = scribe_utils.get_location(ip_with_port.split(':')[0])
  File "F:\scribe2\Utils\scribe_utils.py", line 215, in get_location
    reader = geoip2.database.Reader('file/GeoLite2-City_20180501/GeoLite2-City.mmdb')
  File "F:\scribe2\venv\lib\site-packages\geoip2\database.py", line 86, in __init__
    self._db_reader = maxminddb.open_database(fileish, mode)
  File "F:\scribe2\venv\lib\site-packages\maxminddb\__init__.py", line 41, in open_database
    return maxminddb.reader.Reader(database, mode)
  File "F:\scribe2\venv\lib\site-packages\maxminddb\reader.py", line 52, in __init__
    with open(database, 'rb') as db_file:
FileNotFoundError: [Errno 2] No such file or directory: 'file/GeoLite2-City_20180501/GeoLite2-City.mmdb'

2018-08-07 14:56:33,594 - Utils.log_utils - ERROR - f8891082-9a0e-11e8-96b7-005056c00008 - Traceback (most recent call last):
  File "F:\scribe2\venv\lib\site-packages\socks.py", line 832, in connect
    super(socksocket, self).connect(proxy_addr)
socket.timeout: timed out

During handling of the above exception, another exception occurred:

Traceback (most recent call last):
  File "F:\scribe2\venv\lib\site-packages\urllib3\contrib\socks.py", line 88, in _new_conn
    **extra_kw
  File "F:\scribe2\venv\lib\site-packages\socks.py", line 262, in create_connection
    raise err
  File "F:\scribe2\venv\lib\site-packages\socks.py", line 252, in create_connection
    sock.connect((remote_host, remote_port))
  File "F:\scribe2\venv\lib\site-packages\socks.py", line 100, in wrapper
    return function(*args, **kwargs)
  File "F:\scribe2\venv\lib\site-packages\socks.py", line 844, in connect
    raise ProxyConnectionError(msg, error)
socks.ProxyConnectionError: Error connecting to SOCKS5 proxy 132.148.129.183:47617: timed out

During handling of the above exception, another exception occurred:

Traceback (most recent call last):
  File "F:\scribe2\venv\lib\site-packages\urllib3\connectionpool.py", line 601, in urlopen
    chunked=chunked)
  File "F:\scribe2\venv\lib\site-packages\urllib3\connectionpool.py", line 346, in _make_request
    self._validate_conn(conn)
  File "F:\scribe2\venv\lib\site-packages\urllib3\connectionpool.py", line 850, in _validate_conn
    conn.connect()
  File "F:\scribe2\venv\lib\site-packages\urllib3\connection.py", line 284, in connect
    conn = self._new_conn()
  File "F:\scribe2\venv\lib\site-packages\urllib3\contrib\socks.py", line 105, in _new_conn
    (self.host, self.timeout)
urllib3.exceptions.ConnectTimeoutError: (<urllib3.contrib.socks.SOCKSHTTPSConnection object at 0x00000000072162E8>, 'Connection to www.baidu.com timed out. (connect timeout=10)')

During handling of the above exception, another exception occurred:

Traceback (most recent call last):
  File "F:\scribe2\venv\lib\site-packages\requests\adapters.py", line 440, in send
    timeout=timeout
  File "F:\scribe2\venv\lib\site-packages\urllib3\connectionpool.py", line 639, in urlopen
    _stacktrace=sys.exc_info()[2])
  File "F:\scribe2\venv\lib\site-packages\urllib3\util\retry.py", line 388, in increment
    raise MaxRetryError(_pool, url, error or ResponseError(cause))
urllib3.exceptions.MaxRetryError: SOCKSHTTPSConnectionPool(host='www.baidu.com', port=443): Max retries exceeded with url: / (Caused by ConnectTimeoutError(<urllib3.contrib.socks.SOCKSHTTPSConnection object at 0x00000000072162E8>, 'Connection to www.baidu.com timed out. (connect timeout=10)'))

During handling of the above exception, another exception occurred:

Traceback (most recent call last):
  File "F:\scribe2\Server\Service\fanqiang_ip_service.py", line 21, in get_random_ip_port_dict
    test_proxy(ip_port_dict)
  File "F:\scribe2\Server\Service\fanqiang_ip_service.py", line 42, in test_proxy
    timeout=10)
  File "F:\scribe2\venv\lib\site-packages\requests\api.py", line 72, in get
    return request('get', url, params=params, **kwargs)
  File "F:\scribe2\venv\lib\site-packages\requests\api.py", line 58, in request
    return session.request(method=method, url=url, **kwargs)
  File "F:\scribe2\venv\lib\site-packages\requests\sessions.py", line 508, in request
    resp = self.send(prep, **send_kwargs)
  File "F:\scribe2\venv\lib\site-packages\requests\sessions.py", line 618, in send
    r = adapter.send(request, **kwargs)
  File "F:\scribe2\venv\lib\site-packages\requests\adapters.py", line 496, in send
    raise ConnectTimeout(e, request=request)
requests.exceptions.ConnectTimeout: SOCKSHTTPSConnectionPool(host='www.baidu.com', port=443): Max retries exceeded with url: / (Caused by ConnectTimeoutError(<urllib3.contrib.socks.SOCKSHTTPSConnection object at 0x00000000072162E8>, 'Connection to www.baidu.com timed out. (connect timeout=10)'))

During handling of the above exception, another exception occurred:

Traceback (most recent call last):
  File "F:\scribe2\venv\lib\site-packages\urllib3\contrib\socks.py", line 88, in _new_conn
    **extra_kw
  File "F:\scribe2\venv\lib\site-packages\socks.py", line 262, in create_connection
    raise err
  File "F:\scribe2\venv\lib\site-packages\socks.py", line 252, in create_connection
    sock.connect((remote_host, remote_port))
  File "F:\scribe2\venv\lib\site-packages\socks.py", line 100, in wrapper
    return function(*args, **kwargs)
  File "F:\scribe2\venv\lib\site-packages\socks.py", line 844, in connect
    raise ProxyConnectionError(msg, error)
socks.ProxyConnectionError: Error connecting to SOCKS5 proxy 103.216.82.148:6667: timed out

During handling of the above exception, another exception occurred:

Traceback (most recent call last):
  File "F:\scribe2\venv\lib\site-packages\urllib3\connectionpool.py", line 601, in urlopen
    chunked=chunked)
  File "F:\scribe2\venv\lib\site-packages\urllib3\connectionpool.py", line 346, in _make_request
    self._validate_conn(conn)
  File "F:\scribe2\venv\lib\site-packages\urllib3\connectionpool.py", line 850, in _validate_conn
    conn.connect()
  File "F:\scribe2\venv\lib\site-packages\urllib3\connection.py", line 284, in connect
    conn = self._new_conn()
  File "F:\scribe2\venv\lib\site-packages\urllib3\contrib\socks.py", line 105, in _new_conn
    (self.host, self.timeout)
urllib3.exceptions.ConnectTimeoutError: (<urllib3.contrib.socks.SOCKSHTTPSConnection object at 0x0000000007299630>, 'Connection to www.baidu.com timed out. (connect timeout=10)')

During handling of the above exception, another exception occurred:

Traceback (most recent call last):
  File "F:\scribe2\venv\lib\site-packages\requests\adapters.py", line 440, in send
    timeout=timeout
  File "F:\scribe2\venv\lib\site-packages\urllib3\connectionpool.py", line 639, in urlopen
    _stacktrace=sys.exc_info()[2])
  File "F:\scribe2\venv\lib\site-packages\urllib3\util\retry.py", line 388, in increment
    raise MaxRetryError(_pool, url, error or ResponseError(cause))
urllib3.exceptions.MaxRetryError: SOCKSHTTPSConnectionPool(host='www.baidu.com', port=443): Max retries exceeded with url: / (Caused by ConnectTimeoutError(<urllib3.contrib.socks.SOCKSHTTPSConnection object at 0x0000000007299630>, 'Connection to www.baidu.com timed out. (connect timeout=10)'))

During handling of the above exception, another exception occurred:

Traceback (most recent call last):
  File "F:\scribe2\Server\Service\fanqiang_ip_service.py", line 21, in get_random_ip_port_dict
    test_proxy(ip_port_dict)
  File "F:\scribe2\Server\Service\fanqiang_ip_service.py", line 42, in test_proxy
    timeout=10)
  File "F:\scribe2\venv\lib\site-packages\requests\api.py", line 72, in get
    return request('get', url, params=params, **kwargs)
  File "F:\scribe2\venv\lib\site-packages\requests\api.py", line 58, in request
    return session.request(method=method, url=url, **kwargs)
  File "F:\scribe2\venv\lib\site-packages\requests\sessions.py", line 508, in request
    resp = self.send(prep, **send_kwargs)
  File "F:\scribe2\venv\lib\site-packages\requests\sessions.py", line 618, in send
    r = adapter.send(request, **kwargs)
  File "F:\scribe2\venv\lib\site-packages\requests\adapters.py", line 496, in send
    raise ConnectTimeout(e, request=request)
requests.exceptions.ConnectTimeout: SOCKSHTTPSConnectionPool(host='www.baidu.com', port=443): Max retries exceeded with url: / (Caused by ConnectTimeoutError(<urllib3.contrib.socks.SOCKSHTTPSConnection object at 0x0000000007299630>, 'Connection to www.baidu.com timed out. (connect timeout=10)'))

During handling of the above exception, another exception occurred:

Traceback (most recent call last):
  File "F:/scribe2/Server/server.py", line 28, in get_lans_data
    ip_with_port=fanqiang_ip_service.get_random_ip_port_dict()
  File "F:\scribe2\Server\Service\fanqiang_ip_service.py", line 25, in get_random_ip_port_dict
    return get_random_ip_port_dict()
  File "F:\scribe2\Server\Service\fanqiang_ip_service.py", line 25, in get_random_ip_port_dict
    return get_random_ip_port_dict()
  File "F:\scribe2\Server\Service\fanqiang_ip_service.py", line 19, in get_random_ip_port_dict
    ip_port_dict = ip_list[math.floor(random.random() * len(ip_list))]
IndexError: list index out of range

2018-08-07 14:56:38,005 - Utils.log_utils - ERROR - c3671322-9a0e-11e8-a41f-005056c00008 - Traceback (most recent call last):
  File "F:\scribe2\venv\lib\site-packages\socks.py", line 832, in connect
    super(socksocket, self).connect(proxy_addr)
socket.timeout: timed out

During handling of the above exception, another exception occurred:

Traceback (most recent call last):
  File "F:\scribe2\venv\lib\site-packages\urllib3\contrib\socks.py", line 88, in _new_conn
    **extra_kw
  File "F:\scribe2\venv\lib\site-packages\socks.py", line 262, in create_connection
    raise err
  File "F:\scribe2\venv\lib\site-packages\socks.py", line 252, in create_connection
    sock.connect((remote_host, remote_port))
  File "F:\scribe2\venv\lib\site-packages\socks.py", line 100, in wrapper
    return function(*args, **kwargs)
  File "F:\scribe2\venv\lib\site-packages\socks.py", line 844, in connect
    raise ProxyConnectionError(msg, error)
socks.ProxyConnectionError: Error connecting to SOCKS5 proxy 192.169.180.124:1342: timed out

During handling of the above exception, another exception occurred:

Traceback (most recent call last):
  File "F:\scribe2\venv\lib\site-packages\urllib3\connectionpool.py", line 601, in urlopen
    chunked=chunked)
  File "F:\scribe2\venv\lib\site-packages\urllib3\connectionpool.py", line 346, in _make_request
    self._validate_conn(conn)
  File "F:\scribe2\venv\lib\site-packages\urllib3\connectionpool.py", line 850, in _validate_conn
    conn.connect()
  File "F:\scribe2\venv\lib\site-packages\urllib3\connection.py", line 284, in connect
    conn = self._new_conn()
  File "F:\scribe2\venv\lib\site-packages\urllib3\contrib\socks.py", line 105, in _new_conn
    (self.host, self.timeout)
urllib3.exceptions.ConnectTimeoutError: (<urllib3.contrib.socks.SOCKSHTTPSConnection object at 0x0000000006AACA90>, 'Connection to www.baidu.com timed out. (connect timeout=10)')

During handling of the above exception, another exception occurred:

Traceback (most recent call last):
  File "F:\scribe2\venv\lib\site-packages\requests\adapters.py", line 440, in send
    timeout=timeout
  File "F:\scribe2\venv\lib\site-packages\urllib3\connectionpool.py", line 639, in urlopen
    _stacktrace=sys.exc_info()[2])
  File "F:\scribe2\venv\lib\site-packages\urllib3\util\retry.py", line 388, in increment
    raise MaxRetryError(_pool, url, error or ResponseError(cause))
urllib3.exceptions.MaxRetryError: SOCKSHTTPSConnectionPool(host='www.baidu.com', port=443): Max retries exceeded with url: / (Caused by ConnectTimeoutError(<urllib3.contrib.socks.SOCKSHTTPSConnection object at 0x0000000006AACA90>, 'Connection to www.baidu.com timed out. (connect timeout=10)'))

During handling of the above exception, another exception occurred:

Traceback (most recent call last):
  File "F:\scribe2\Server\Service\fanqiang_ip_service.py", line 21, in get_random_ip_port_dict
    test_proxy(ip_port_dict)
  File "F:\scribe2\Server\Service\fanqiang_ip_service.py", line 42, in test_proxy
    timeout=10)
  File "F:\scribe2\venv\lib\site-packages\requests\api.py", line 72, in get
    return request('get', url, params=params, **kwargs)
  File "F:\scribe2\venv\lib\site-packages\requests\api.py", line 58, in request
    return session.request(method=method, url=url, **kwargs)
  File "F:\scribe2\venv\lib\site-packages\requests\sessions.py", line 508, in request
    resp = self.send(prep, **send_kwargs)
  File "F:\scribe2\venv\lib\site-packages\requests\sessions.py", line 618, in send
    r = adapter.send(request, **kwargs)
  File "F:\scribe2\venv\lib\site-packages\requests\adapters.py", line 496, in send
    raise ConnectTimeout(e, request=request)
requests.exceptions.ConnectTimeout: SOCKSHTTPSConnectionPool(host='www.baidu.com', port=443): Max retries exceeded with url: / (Caused by ConnectTimeoutError(<urllib3.contrib.socks.SOCKSHTTPSConnection object at 0x0000000006AACA90>, 'Connection to www.baidu.com timed out. (connect timeout=10)'))

During handling of the above exception, another exception occurred:

Traceback (most recent call last):
  File "F:\scribe2\venv\lib\site-packages\urllib3\contrib\socks.py", line 88, in _new_conn
    **extra_kw
  File "F:\scribe2\venv\lib\site-packages\socks.py", line 262, in create_connection
    raise err
  File "F:\scribe2\venv\lib\site-packages\socks.py", line 252, in create_connection
    sock.connect((remote_host, remote_port))
  File "F:\scribe2\venv\lib\site-packages\socks.py", line 100, in wrapper
    return function(*args, **kwargs)
  File "F:\scribe2\venv\lib\site-packages\socks.py", line 844, in connect
    raise ProxyConnectionError(msg, error)
socks.ProxyConnectionError: Error connecting to SOCKS5 proxy 132.148.129.183:1628: timed out

During handling of the above exception, another exception occurred:

Traceback (most recent call last):
  File "F:\scribe2\venv\lib\site-packages\urllib3\connectionpool.py", line 601, in urlopen
    chunked=chunked)
  File "F:\scribe2\venv\lib\site-packages\urllib3\connectionpool.py", line 346, in _make_request
    self._validate_conn(conn)
  File "F:\scribe2\venv\lib\site-packages\urllib3\connectionpool.py", line 850, in _validate_conn
    conn.connect()
  File "F:\scribe2\venv\lib\site-packages\urllib3\connection.py", line 284, in connect
    conn = self._new_conn()
  File "F:\scribe2\venv\lib\site-packages\urllib3\contrib\socks.py", line 105, in _new_conn
    (self.host, self.timeout)
urllib3.exceptions.ConnectTimeoutError: (<urllib3.contrib.socks.SOCKSHTTPSConnection object at 0x0000000006B22828>, 'Connection to www.baidu.com timed out. (connect timeout=10)')

During handling of the above exception, another exception occurred:

Traceback (most recent call last):
  File "F:\scribe2\venv\lib\site-packages\requests\adapters.py", line 440, in send
    timeout=timeout
  File "F:\scribe2\venv\lib\site-packages\urllib3\connectionpool.py", line 639, in urlopen
    _stacktrace=sys.exc_info()[2])
  File "F:\scribe2\venv\lib\site-packages\urllib3\util\retry.py", line 388, in increment
    raise MaxRetryError(_pool, url, error or ResponseError(cause))
urllib3.exceptions.MaxRetryError: SOCKSHTTPSConnectionPool(host='www.baidu.com', port=443): Max retries exceeded with url: / (Caused by ConnectTimeoutError(<urllib3.contrib.socks.SOCKSHTTPSConnection object at 0x0000000006B22828>, 'Connection to www.baidu.com timed out. (connect timeout=10)'))

During handling of the above exception, another exception occurred:

Traceback (most recent call last):
  File "F:\scribe2\Server\Service\fanqiang_ip_service.py", line 21, in get_random_ip_port_dict
    test_proxy(ip_port_dict)
  File "F:\scribe2\Server\Service\fanqiang_ip_service.py", line 42, in test_proxy
    timeout=10)
  File "F:\scribe2\venv\lib\site-packages\requests\api.py", line 72, in get
    return request('get', url, params=params, **kwargs)
  File "F:\scribe2\venv\lib\site-packages\requests\api.py", line 58, in request
    return session.request(method=method, url=url, **kwargs)
  File "F:\scribe2\venv\lib\site-packages\requests\sessions.py", line 508, in request
    resp = self.send(prep, **send_kwargs)
  File "F:\scribe2\venv\lib\site-packages\requests\sessions.py", line 618, in send
    r = adapter.send(request, **kwargs)
  File "F:\scribe2\venv\lib\site-packages\requests\adapters.py", line 496, in send
    raise ConnectTimeout(e, request=request)
requests.exceptions.ConnectTimeout: SOCKSHTTPSConnectionPool(host='www.baidu.com', port=443): Max retries exceeded with url: / (Caused by ConnectTimeoutError(<urllib3.contrib.socks.SOCKSHTTPSConnection object at 0x0000000006B22828>, 'Connection to www.baidu.com timed out. (connect timeout=10)'))

During handling of the above exception, another exception occurred:

Traceback (most recent call last):
  File "F:\scribe2\venv\lib\site-packages\urllib3\contrib\socks.py", line 88, in _new_conn
    **extra_kw
  File "F:\scribe2\venv\lib\site-packages\socks.py", line 262, in create_connection
    raise err
  File "F:\scribe2\venv\lib\site-packages\socks.py", line 252, in create_connection
    sock.connect((remote_host, remote_port))
  File "F:\scribe2\venv\lib\site-packages\socks.py", line 100, in wrapper
    return function(*args, **kwargs)
  File "F:\scribe2\venv\lib\site-packages\socks.py", line 844, in connect
    raise ProxyConnectionError(msg, error)
socks.ProxyConnectionError: Error connecting to SOCKS5 proxy 195.25.25.132:58920: timed out

During handling of the above exception, another exception occurred:

Traceback (most recent call last):
  File "F:\scribe2\venv\lib\site-packages\urllib3\connectionpool.py", line 601, in urlopen
    chunked=chunked)
  File "F:\scribe2\venv\lib\site-packages\urllib3\connectionpool.py", line 346, in _make_request
    self._validate_conn(conn)
  File "F:\scribe2\venv\lib\site-packages\urllib3\connectionpool.py", line 850, in _validate_conn
    conn.connect()
  File "F:\scribe2\venv\lib\site-packages\urllib3\connection.py", line 284, in connect
    conn = self._new_conn()
  File "F:\scribe2\venv\lib\site-packages\urllib3\contrib\socks.py", line 105, in _new_conn
    (self.host, self.timeout)
urllib3.exceptions.ConnectTimeoutError: (<urllib3.contrib.socks.SOCKSHTTPSConnection object at 0x0000000006D80320>, 'Connection to www.baidu.com timed out. (connect timeout=10)')

During handling of the above exception, another exception occurred:

Traceback (most recent call last):
  File "F:\scribe2\venv\lib\site-packages\requests\adapters.py", line 440, in send
    timeout=timeout
  File "F:\scribe2\venv\lib\site-packages\urllib3\connectionpool.py", line 639, in urlopen
    _stacktrace=sys.exc_info()[2])
  File "F:\scribe2\venv\lib\site-packages\urllib3\util\retry.py", line 388, in increment
    raise MaxRetryError(_pool, url, error or ResponseError(cause))
urllib3.exceptions.MaxRetryError: SOCKSHTTPSConnectionPool(host='www.baidu.com', port=443): Max retries exceeded with url: / (Caused by ConnectTimeoutError(<urllib3.contrib.socks.SOCKSHTTPSConnection object at 0x0000000006D80320>, 'Connection to www.baidu.com timed out. (connect timeout=10)'))

During handling of the above exception, another exception occurred:

Traceback (most recent call last):
  File "F:\scribe2\Server\Service\fanqiang_ip_service.py", line 21, in get_random_ip_port_dict
    test_proxy(ip_port_dict)
  File "F:\scribe2\Server\Service\fanqiang_ip_service.py", line 42, in test_proxy
    timeout=10)
  File "F:\scribe2\venv\lib\site-packages\requests\api.py", line 72, in get
    return request('get', url, params=params, **kwargs)
  File "F:\scribe2\venv\lib\site-packages\requests\api.py", line 58, in request
    return session.request(method=method, url=url, **kwargs)
  File "F:\scribe2\venv\lib\site-packages\requests\sessions.py", line 508, in request
    resp = self.send(prep, **send_kwargs)
  File "F:\scribe2\venv\lib\site-packages\requests\sessions.py", line 618, in send
    r = adapter.send(request, **kwargs)
  File "F:\scribe2\venv\lib\site-packages\requests\adapters.py", line 496, in send
    raise ConnectTimeout(e, request=request)
requests.exceptions.ConnectTimeout: SOCKSHTTPSConnectionPool(host='www.baidu.com', port=443): Max retries exceeded with url: / (Caused by ConnectTimeoutError(<urllib3.contrib.socks.SOCKSHTTPSConnection object at 0x0000000006D80320>, 'Connection to www.baidu.com timed out. (connect timeout=10)'))

During handling of the above exception, another exception occurred:

Traceback (most recent call last):
  File "F:\scribe2\venv\lib\site-packages\urllib3\contrib\socks.py", line 88, in _new_conn
    **extra_kw
  File "F:\scribe2\venv\lib\site-packages\socks.py", line 262, in create_connection
    raise err
  File "F:\scribe2\venv\lib\site-packages\socks.py", line 252, in create_connection
    sock.connect((remote_host, remote_port))
  File "F:\scribe2\venv\lib\site-packages\socks.py", line 100, in wrapper
    return function(*args, **kwargs)
  File "F:\scribe2\venv\lib\site-packages\socks.py", line 844, in connect
    raise ProxyConnectionError(msg, error)
socks.ProxyConnectionError: Error connecting to SOCKS5 proxy 109.200.132.144:8888: timed out

During handling of the above exception, another exception occurred:

Traceback (most recent call last):
  File "F:\scribe2\venv\lib\site-packages\urllib3\connectionpool.py", line 601, in urlopen
    chunked=chunked)
  File "F:\scribe2\venv\lib\site-packages\urllib3\connectionpool.py", line 346, in _make_request
    self._validate_conn(conn)
  File "F:\scribe2\venv\lib\site-packages\urllib3\connectionpool.py", line 850, in _validate_conn
    conn.connect()
  File "F:\scribe2\venv\lib\site-packages\urllib3\connection.py", line 284, in connect
    conn = self._new_conn()
  File "F:\scribe2\venv\lib\site-packages\urllib3\contrib\socks.py", line 105, in _new_conn
    (self.host, self.timeout)
urllib3.exceptions.ConnectTimeoutError: (<urllib3.contrib.socks.SOCKSHTTPSConnection object at 0x0000000006DC8C50>, 'Connection to www.baidu.com timed out. (connect timeout=10)')

During handling of the above exception, another exception occurred:

Traceback (most recent call last):
  File "F:\scribe2\venv\lib\site-packages\requests\adapters.py", line 440, in send
    timeout=timeout
  File "F:\scribe2\venv\lib\site-packages\urllib3\connectionpool.py", line 639, in urlopen
    _stacktrace=sys.exc_info()[2])
  File "F:\scribe2\venv\lib\site-packages\urllib3\util\retry.py", line 388, in increment
    raise MaxRetryError(_pool, url, error or ResponseError(cause))
urllib3.exceptions.MaxRetryError: SOCKSHTTPSConnectionPool(host='www.baidu.com', port=443): Max retries exceeded with url: / (Caused by ConnectTimeoutError(<urllib3.contrib.socks.SOCKSHTTPSConnection object at 0x0000000006DC8C50>, 'Connection to www.baidu.com timed out. (connect timeout=10)'))

During handling of the above exception, another exception occurred:

Traceback (most recent call last):
  File "F:\scribe2\Server\Service\fanqiang_ip_service.py", line 21, in get_random_ip_port_dict
    test_proxy(ip_port_dict)
  File "F:\scribe2\Server\Service\fanqiang_ip_service.py", line 42, in test_proxy
    timeout=10)
  File "F:\scribe2\venv\lib\site-packages\requests\api.py", line 72, in get
    return request('get', url, params=params, **kwargs)
  File "F:\scribe2\venv\lib\site-packages\requests\api.py", line 58, in request
    return session.request(method=method, url=url, **kwargs)
  File "F:\scribe2\venv\lib\site-packages\requests\sessions.py", line 508, in request
    resp = self.send(prep, **send_kwargs)
  File "F:\scribe2\venv\lib\site-packages\requests\sessions.py", line 618, in send
    r = adapter.send(request, **kwargs)
  File "F:\scribe2\venv\lib\site-packages\requests\adapters.py", line 496, in send
    raise ConnectTimeout(e, request=request)
requests.exceptions.ConnectTimeout: SOCKSHTTPSConnectionPool(host='www.baidu.com', port=443): Max retries exceeded with url: / (Caused by ConnectTimeoutError(<urllib3.contrib.socks.SOCKSHTTPSConnection object at 0x0000000006DC8C50>, 'Connection to www.baidu.com timed out. (connect timeout=10)'))

During handling of the above exception, another exception occurred:

Traceback (most recent call last):
  File "F:\scribe2\venv\lib\site-packages\urllib3\contrib\socks.py", line 88, in _new_conn
    **extra_kw
  File "F:\scribe2\venv\lib\site-packages\socks.py", line 262, in create_connection
    raise err
  File "F:\scribe2\venv\lib\site-packages\socks.py", line 252, in create_connection
    sock.connect((remote_host, remote_port))
  File "F:\scribe2\venv\lib\site-packages\socks.py", line 100, in wrapper
    return function(*args, **kwargs)
  File "F:\scribe2\venv\lib\site-packages\socks.py", line 844, in connect
    raise ProxyConnectionError(msg, error)
socks.ProxyConnectionError: Error connecting to SOCKS5 proxy 185.87.49.185:46918: timed out

During handling of the above exception, another exception occurred:

Traceback (most recent call last):
  File "F:\scribe2\venv\lib\site-packages\urllib3\connectionpool.py", line 601, in urlopen
    chunked=chunked)
  File "F:\scribe2\venv\lib\site-packages\urllib3\connectionpool.py", line 346, in _make_request
    self._validate_conn(conn)
  File "F:\scribe2\venv\lib\site-packages\urllib3\connectionpool.py", line 850, in _validate_conn
    conn.connect()
  File "F:\scribe2\venv\lib\site-packages\urllib3\connection.py", line 284, in connect
    conn = self._new_conn()
  File "F:\scribe2\venv\lib\site-packages\urllib3\contrib\socks.py", line 105, in _new_conn
    (self.host, self.timeout)
urllib3.exceptions.ConnectTimeoutError: (<urllib3.contrib.socks.SOCKSHTTPSConnection object at 0x0000000006E15438>, 'Connection to www.baidu.com timed out. (connect timeout=10)')

During handling of the above exception, another exception occurred:

Traceback (most recent call last):
  File "F:\scribe2\venv\lib\site-packages\requests\adapters.py", line 440, in send
    timeout=timeout
  File "F:\scribe2\venv\lib\site-packages\urllib3\connectionpool.py", line 639, in urlopen
    _stacktrace=sys.exc_info()[2])
  File "F:\scribe2\venv\lib\site-packages\urllib3\util\retry.py", line 388, in increment
    raise MaxRetryError(_pool, url, error or ResponseError(cause))
urllib3.exceptions.MaxRetryError: SOCKSHTTPSConnectionPool(host='www.baidu.com', port=443): Max retries exceeded with url: / (Caused by ConnectTimeoutError(<urllib3.contrib.socks.SOCKSHTTPSConnection object at 0x0000000006E15438>, 'Connection to www.baidu.com timed out. (connect timeout=10)'))

During handling of the above exception, another exception occurred:

Traceback (most recent call last):
  File "F:\scribe2\Server\Service\fanqiang_ip_service.py", line 21, in get_random_ip_port_dict
    test_proxy(ip_port_dict)
  File "F:\scribe2\Server\Service\fanqiang_ip_service.py", line 42, in test_proxy
    timeout=10)
  File "F:\scribe2\venv\lib\site-packages\requests\api.py", line 72, in get
    return request('get', url, params=params, **kwargs)
  File "F:\scribe2\venv\lib\site-packages\requests\api.py", line 58, in request
    return session.request(method=method, url=url, **kwargs)
  File "F:\scribe2\venv\lib\site-packages\requests\sessions.py", line 508, in request
    resp = self.send(prep, **send_kwargs)
  File "F:\scribe2\venv\lib\site-packages\requests\sessions.py", line 618, in send
    r = adapter.send(request, **kwargs)
  File "F:\scribe2\venv\lib\site-packages\requests\adapters.py", line 496, in send
    raise ConnectTimeout(e, request=request)
requests.exceptions.ConnectTimeout: SOCKSHTTPSConnectionPool(host='www.baidu.com', port=443): Max retries exceeded with url: / (Caused by ConnectTimeoutError(<urllib3.contrib.socks.SOCKSHTTPSConnection object at 0x0000000006E15438>, 'Connection to www.baidu.com timed out. (connect timeout=10)'))

During handling of the above exception, another exception occurred:

Traceback (most recent call last):
  File "F:\scribe2\venv\lib\site-packages\urllib3\contrib\socks.py", line 88, in _new_conn
    **extra_kw
  File "F:\scribe2\venv\lib\site-packages\socks.py", line 262, in create_connection
    raise err
  File "F:\scribe2\venv\lib\site-packages\socks.py", line 252, in create_connection
    sock.connect((remote_host, remote_port))
  File "F:\scribe2\venv\lib\site-packages\socks.py", line 100, in wrapper
    return function(*args, **kwargs)
  File "F:\scribe2\venv\lib\site-packages\socks.py", line 844, in connect
    raise ProxyConnectionError(msg, error)
socks.ProxyConnectionError: Error connecting to SOCKS5 proxy 192.169.189.215:7432: timed out

During handling of the above exception, another exception occurred:

Traceback (most recent call last):
  File "F:\scribe2\venv\lib\site-packages\urllib3\connectionpool.py", line 601, in urlopen
    chunked=chunked)
  File "F:\scribe2\venv\lib\site-packages\urllib3\connectionpool.py", line 346, in _make_request
    self._validate_conn(conn)
  File "F:\scribe2\venv\lib\site-packages\urllib3\connectionpool.py", line 850, in _validate_conn
    conn.connect()
  File "F:\scribe2\venv\lib\site-packages\urllib3\connection.py", line 284, in connect
    conn = self._new_conn()
  File "F:\scribe2\venv\lib\site-packages\urllib3\contrib\socks.py", line 105, in _new_conn
    (self.host, self.timeout)
urllib3.exceptions.ConnectTimeoutError: (<urllib3.contrib.socks.SOCKSHTTPSConnection object at 0x0000000006E5CA58>, 'Connection to www.baidu.com timed out. (connect timeout=10)')

During handling of the above exception, another exception occurred:

Traceback (most recent call last):
  File "F:\scribe2\venv\lib\site-packages\requests\adapters.py", line 440, in send
    timeout=timeout
  File "F:\scribe2\venv\lib\site-packages\urllib3\connectionpool.py", line 639, in urlopen
    _stacktrace=sys.exc_info()[2])
  File "F:\scribe2\venv\lib\site-packages\urllib3\util\retry.py", line 388, in increment
    raise MaxRetryError(_pool, url, error or ResponseError(cause))
urllib3.exceptions.MaxRetryError: SOCKSHTTPSConnectionPool(host='www.baidu.com', port=443): Max retries exceeded with url: / (Caused by ConnectTimeoutError(<urllib3.contrib.socks.SOCKSHTTPSConnection object at 0x0000000006E5CA58>, 'Connection to www.baidu.com timed out. (connect timeout=10)'))

During handling of the above exception, another exception occurred:

Traceback (most recent call last):
  File "F:\scribe2\Server\Service\fanqiang_ip_service.py", line 21, in get_random_ip_port_dict
    test_proxy(ip_port_dict)
  File "F:\scribe2\Server\Service\fanqiang_ip_service.py", line 42, in test_proxy
    timeout=10)
  File "F:\scribe2\venv\lib\site-packages\requests\api.py", line 72, in get
    return request('get', url, params=params, **kwargs)
  File "F:\scribe2\venv\lib\site-packages\requests\api.py", line 58, in request
    return session.request(method=method, url=url, **kwargs)
  File "F:\scribe2\venv\lib\site-packages\requests\sessions.py", line 508, in request
    resp = self.send(prep, **send_kwargs)
  File "F:\scribe2\venv\lib\site-packages\requests\sessions.py", line 618, in send
    r = adapter.send(request, **kwargs)
  File "F:\scribe2\venv\lib\site-packages\requests\adapters.py", line 496, in send
    raise ConnectTimeout(e, request=request)
requests.exceptions.ConnectTimeout: SOCKSHTTPSConnectionPool(host='www.baidu.com', port=443): Max retries exceeded with url: / (Caused by ConnectTimeoutError(<urllib3.contrib.socks.SOCKSHTTPSConnection object at 0x0000000006E5CA58>, 'Connection to www.baidu.com timed out. (connect timeout=10)'))

During handling of the above exception, another exception occurred:

Traceback (most recent call last):
  File "F:\scribe2\venv\lib\site-packages\urllib3\contrib\socks.py", line 88, in _new_conn
    **extra_kw
  File "F:\scribe2\venv\lib\site-packages\socks.py", line 262, in create_connection
    raise err
  File "F:\scribe2\venv\lib\site-packages\socks.py", line 252, in create_connection
    sock.connect((remote_host, remote_port))
  File "F:\scribe2\venv\lib\site-packages\socks.py", line 100, in wrapper
    return function(*args, **kwargs)
  File "F:\scribe2\venv\lib\site-packages\socks.py", line 844, in connect
    raise ProxyConnectionError(msg, error)
socks.ProxyConnectionError: Error connecting to SOCKS5 proxy 192.169.182.200:24408: timed out

During handling of the above exception, another exception occurred:

Traceback (most recent call last):
  File "F:\scribe2\venv\lib\site-packages\urllib3\connectionpool.py", line 601, in urlopen
    chunked=chunked)
  File "F:\scribe2\venv\lib\site-packages\urllib3\connectionpool.py", line 346, in _make_request
    self._validate_conn(conn)
  File "F:\scribe2\venv\lib\site-packages\urllib3\connectionpool.py", line 850, in _validate_conn
    conn.connect()
  File "F:\scribe2\venv\lib\site-packages\urllib3\connection.py", line 284, in connect
    conn = self._new_conn()
  File "F:\scribe2\venv\lib\site-packages\urllib3\contrib\socks.py", line 105, in _new_conn
    (self.host, self.timeout)
urllib3.exceptions.ConnectTimeoutError: (<urllib3.contrib.socks.SOCKSHTTPSConnection object at 0x00000000070DCB38>, 'Connection to www.baidu.com timed out. (connect timeout=10)')

During handling of the above exception, another exception occurred:

Traceback (most recent call last):
  File "F:\scribe2\venv\lib\site-packages\requests\adapters.py", line 440, in send
    timeout=timeout
  File "F:\scribe2\venv\lib\site-packages\urllib3\connectionpool.py", line 639, in urlopen
    _stacktrace=sys.exc_info()[2])
  File "F:\scribe2\venv\lib\site-packages\urllib3\util\retry.py", line 388, in increment
    raise MaxRetryError(_pool, url, error or ResponseError(cause))
urllib3.exceptions.MaxRetryError: SOCKSHTTPSConnectionPool(host='www.baidu.com', port=443): Max retries exceeded with url: / (Caused by ConnectTimeoutError(<urllib3.contrib.socks.SOCKSHTTPSConnection object at 0x00000000070DCB38>, 'Connection to www.baidu.com timed out. (connect timeout=10)'))

During handling of the above exception, another exception occurred:

Traceback (most recent call last):
  File "F:\scribe2\Server\Service\fanqiang_ip_service.py", line 21, in get_random_ip_port_dict
    test_proxy(ip_port_dict)
  File "F:\scribe2\Server\Service\fanqiang_ip_service.py", line 42, in test_proxy
    timeout=10)
  File "F:\scribe2\venv\lib\site-packages\requests\api.py", line 72, in get
    return request('get', url, params=params, **kwargs)
  File "F:\scribe2\venv\lib\site-packages\requests\api.py", line 58, in request
    return session.request(method=method, url=url, **kwargs)
  File "F:\scribe2\venv\lib\site-packages\requests\sessions.py", line 508, in request
    resp = self.send(prep, **send_kwargs)
  File "F:\scribe2\venv\lib\site-packages\requests\sessions.py", line 618, in send
    r = adapter.send(request, **kwargs)
  File "F:\scribe2\venv\lib\site-packages\requests\adapters.py", line 496, in send
    raise ConnectTimeout(e, request=request)
requests.exceptions.ConnectTimeout: SOCKSHTTPSConnectionPool(host='www.baidu.com', port=443): Max retries exceeded with url: / (Caused by ConnectTimeoutError(<urllib3.contrib.socks.SOCKSHTTPSConnection object at 0x00000000070DCB38>, 'Connection to www.baidu.com timed out. (connect timeout=10)'))

During handling of the above exception, another exception occurred:

Traceback (most recent call last):
  File "F:\scribe2\venv\lib\site-packages\urllib3\contrib\socks.py", line 88, in _new_conn
    **extra_kw
  File "F:\scribe2\venv\lib\site-packages\socks.py", line 262, in create_connection
    raise err
  File "F:\scribe2\venv\lib\site-packages\socks.py", line 252, in create_connection
    sock.connect((remote_host, remote_port))
  File "F:\scribe2\venv\lib\site-packages\socks.py", line 100, in wrapper
    return function(*args, **kwargs)
  File "F:\scribe2\venv\lib\site-packages\socks.py", line 844, in connect
    raise ProxyConnectionError(msg, error)
socks.ProxyConnectionError: Error connecting to SOCKS5 proxy 94.177.216.219:8888: timed out

During handling of the above exception, another exception occurred:

Traceback (most recent call last):
  File "F:\scribe2\venv\lib\site-packages\urllib3\connectionpool.py", line 601, in urlopen
    chunked=chunked)
  File "F:\scribe2\venv\lib\site-packages\urllib3\connectionpool.py", line 346, in _make_request
    self._validate_conn(conn)
  File "F:\scribe2\venv\lib\site-packages\urllib3\connectionpool.py", line 850, in _validate_conn
    conn.connect()
  File "F:\scribe2\venv\lib\site-packages\urllib3\connection.py", line 284, in connect
    conn = self._new_conn()
  File "F:\scribe2\venv\lib\site-packages\urllib3\contrib\socks.py", line 105, in _new_conn
    (self.host, self.timeout)
urllib3.exceptions.ConnectTimeoutError: (<urllib3.contrib.socks.SOCKSHTTPSConnection object at 0x000000000715B198>, 'Connection to www.baidu.com timed out. (connect timeout=10)')

During handling of the above exception, another exception occurred:

Traceback (most recent call last):
  File "F:\scribe2\venv\lib\site-packages\requests\adapters.py", line 440, in send
    timeout=timeout
  File "F:\scribe2\venv\lib\site-packages\urllib3\connectionpool.py", line 639, in urlopen
    _stacktrace=sys.exc_info()[2])
  File "F:\scribe2\venv\lib\site-packages\urllib3\util\retry.py", line 388, in increment
    raise MaxRetryError(_pool, url, error or ResponseError(cause))
urllib3.exceptions.MaxRetryError: SOCKSHTTPSConnectionPool(host='www.baidu.com', port=443): Max retries exceeded with url: / (Caused by ConnectTimeoutError(<urllib3.contrib.socks.SOCKSHTTPSConnection object at 0x000000000715B198>, 'Connection to www.baidu.com timed out. (connect timeout=10)'))

During handling of the above exception, another exception occurred:

Traceback (most recent call last):
  File "F:\scribe2\Server\Service\fanqiang_ip_service.py", line 21, in get_random_ip_port_dict
    test_proxy(ip_port_dict)
  File "F:\scribe2\Server\Service\fanqiang_ip_service.py", line 42, in test_proxy
    timeout=10)
  File "F:\scribe2\venv\lib\site-packages\requests\api.py", line 72, in get
    return request('get', url, params=params, **kwargs)
  File "F:\scribe2\venv\lib\site-packages\requests\api.py", line 58, in request
    return session.request(method=method, url=url, **kwargs)
  File "F:\scribe2\venv\lib\site-packages\requests\sessions.py", line 508, in request
    resp = self.send(prep, **send_kwargs)
  File "F:\scribe2\venv\lib\site-packages\requests\sessions.py", line 618, in send
    r = adapter.send(request, **kwargs)
  File "F:\scribe2\venv\lib\site-packages\requests\adapters.py", line 496, in send
    raise ConnectTimeout(e, request=request)
requests.exceptions.ConnectTimeout: SOCKSHTTPSConnectionPool(host='www.baidu.com', port=443): Max retries exceeded with url: / (Caused by ConnectTimeoutError(<urllib3.contrib.socks.SOCKSHTTPSConnection object at 0x000000000715B198>, 'Connection to www.baidu.com timed out. (connect timeout=10)'))

During handling of the above exception, another exception occurred:

Traceback (most recent call last):
  File "F:\scribe2\venv\lib\site-packages\urllib3\contrib\socks.py", line 88, in _new_conn
    **extra_kw
  File "F:\scribe2\venv\lib\site-packages\socks.py", line 262, in create_connection
    raise err
  File "F:\scribe2\venv\lib\site-packages\socks.py", line 252, in create_connection
    sock.connect((remote_host, remote_port))
  File "F:\scribe2\venv\lib\site-packages\socks.py", line 100, in wrapper
    return function(*args, **kwargs)
  File "F:\scribe2\venv\lib\site-packages\socks.py", line 855, in connect
    raise GeneralProxyError("Socket error", error)
socks.GeneralProxyError: Socket error: timed out

During handling of the above exception, another exception occurred:

Traceback (most recent call last):
  File "F:\scribe2\venv\lib\site-packages\urllib3\connectionpool.py", line 601, in urlopen
    chunked=chunked)
  File "F:\scribe2\venv\lib\site-packages\urllib3\connectionpool.py", line 346, in _make_request
    self._validate_conn(conn)
  File "F:\scribe2\venv\lib\site-packages\urllib3\connectionpool.py", line 850, in _validate_conn
    conn.connect()
  File "F:\scribe2\venv\lib\site-packages\urllib3\connection.py", line 284, in connect
    conn = self._new_conn()
  File "F:\scribe2\venv\lib\site-packages\urllib3\contrib\socks.py", line 105, in _new_conn
    (self.host, self.timeout)
urllib3.exceptions.ConnectTimeoutError: (<urllib3.contrib.socks.SOCKSHTTPSConnection object at 0x0000000007183E80>, 'Connection to www.baidu.com timed out. (connect timeout=10)')

During handling of the above exception, another exception occurred:

Traceback (most recent call last):
  File "F:\scribe2\venv\lib\site-packages\requests\adapters.py", line 440, in send
    timeout=timeout
  File "F:\scribe2\venv\lib\site-packages\urllib3\connectionpool.py", line 639, in urlopen
    _stacktrace=sys.exc_info()[2])
  File "F:\scribe2\venv\lib\site-packages\urllib3\util\retry.py", line 388, in increment
    raise MaxRetryError(_pool, url, error or ResponseError(cause))
urllib3.exceptions.MaxRetryError: SOCKSHTTPSConnectionPool(host='www.baidu.com', port=443): Max retries exceeded with url: / (Caused by ConnectTimeoutError(<urllib3.contrib.socks.SOCKSHTTPSConnection object at 0x0000000007183E80>, 'Connection to www.baidu.com timed out. (connect timeout=10)'))

During handling of the above exception, another exception occurred:

Traceback (most recent call last):
  File "F:\scribe2\Server\Service\fanqiang_ip_service.py", line 21, in get_random_ip_port_dict
    test_proxy(ip_port_dict)
  File "F:\scribe2\Server\Service\fanqiang_ip_service.py", line 42, in test_proxy
    timeout=10)
  File "F:\scribe2\venv\lib\site-packages\requests\api.py", line 72, in get
    return request('get', url, params=params, **kwargs)
  File "F:\scribe2\venv\lib\site-packages\requests\api.py", line 58, in request
    return session.request(method=method, url=url, **kwargs)
  File "F:\scribe2\venv\lib\site-packages\requests\sessions.py", line 508, in request
    resp = self.send(prep, **send_kwargs)
  File "F:\scribe2\venv\lib\site-packages\requests\sessions.py", line 618, in send
    r = adapter.send(request, **kwargs)
  File "F:\scribe2\venv\lib\site-packages\requests\adapters.py", line 496, in send
    raise ConnectTimeout(e, request=request)
requests.exceptions.ConnectTimeout: SOCKSHTTPSConnectionPool(host='www.baidu.com', port=443): Max retries exceeded with url: / (Caused by ConnectTimeoutError(<urllib3.contrib.socks.SOCKSHTTPSConnection object at 0x0000000007183E80>, 'Connection to www.baidu.com timed out. (connect timeout=10)'))

During handling of the above exception, another exception occurred:

Traceback (most recent call last):
  File "F:\scribe2\venv\lib\site-packages\urllib3\contrib\socks.py", line 88, in _new_conn
    **extra_kw
  File "F:\scribe2\venv\lib\site-packages\socks.py", line 262, in create_connection
    raise err
  File "F:\scribe2\venv\lib\site-packages\socks.py", line 252, in create_connection
    sock.connect((remote_host, remote_port))
  File "F:\scribe2\venv\lib\site-packages\socks.py", line 100, in wrapper
    return function(*args, **kwargs)
  File "F:\scribe2\venv\lib\site-packages\socks.py", line 844, in connect
    raise ProxyConnectionError(msg, error)
socks.ProxyConnectionError: Error connecting to SOCKS5 proxy 192.169.188.105:7432: timed out

During handling of the above exception, another exception occurred:

Traceback (most recent call last):
  File "F:\scribe2\venv\lib\site-packages\urllib3\connectionpool.py", line 601, in urlopen
    chunked=chunked)
  File "F:\scribe2\venv\lib\site-packages\urllib3\connectionpool.py", line 346, in _make_request
    self._validate_conn(conn)
  File "F:\scribe2\venv\lib\site-packages\urllib3\connectionpool.py", line 850, in _validate_conn
    conn.connect()
  File "F:\scribe2\venv\lib\site-packages\urllib3\connection.py", line 284, in connect
    conn = self._new_conn()
  File "F:\scribe2\venv\lib\site-packages\urllib3\contrib\socks.py", line 105, in _new_conn
    (self.host, self.timeout)
urllib3.exceptions.ConnectTimeoutError: (<urllib3.contrib.socks.SOCKSHTTPSConnection object at 0x0000000007216FD0>, 'Connection to www.baidu.com timed out. (connect timeout=10)')

During handling of the above exception, another exception occurred:

Traceback (most recent call last):
  File "F:\scribe2\venv\lib\site-packages\requests\adapters.py", line 440, in send
    timeout=timeout
  File "F:\scribe2\venv\lib\site-packages\urllib3\connectionpool.py", line 639, in urlopen
    _stacktrace=sys.exc_info()[2])
  File "F:\scribe2\venv\lib\site-packages\urllib3\util\retry.py", line 388, in increment
    raise MaxRetryError(_pool, url, error or ResponseError(cause))
urllib3.exceptions.MaxRetryError: SOCKSHTTPSConnectionPool(host='www.baidu.com', port=443): Max retries exceeded with url: / (Caused by ConnectTimeoutError(<urllib3.contrib.socks.SOCKSHTTPSConnection object at 0x0000000007216FD0>, 'Connection to www.baidu.com timed out. (connect timeout=10)'))

During handling of the above exception, another exception occurred:

Traceback (most recent call last):
  File "F:\scribe2\Server\Service\fanqiang_ip_service.py", line 21, in get_random_ip_port_dict
    test_proxy(ip_port_dict)
  File "F:\scribe2\Server\Service\fanqiang_ip_service.py", line 42, in test_proxy
    timeout=10)
  File "F:\scribe2\venv\lib\site-packages\requests\api.py", line 72, in get
    return request('get', url, params=params, **kwargs)
  File "F:\scribe2\venv\lib\site-packages\requests\api.py", line 58, in request
    return session.request(method=method, url=url, **kwargs)
  File "F:\scribe2\venv\lib\site-packages\requests\sessions.py", line 508, in request
    resp = self.send(prep, **send_kwargs)
  File "F:\scribe2\venv\lib\site-packages\requests\sessions.py", line 618, in send
    r = adapter.send(request, **kwargs)
  File "F:\scribe2\venv\lib\site-packages\requests\adapters.py", line 496, in send
    raise ConnectTimeout(e, request=request)
requests.exceptions.ConnectTimeout: SOCKSHTTPSConnectionPool(host='www.baidu.com', port=443): Max retries exceeded with url: / (Caused by ConnectTimeoutError(<urllib3.contrib.socks.SOCKSHTTPSConnection object at 0x0000000007216FD0>, 'Connection to www.baidu.com timed out. (connect timeout=10)'))

During handling of the above exception, another exception occurred:

Traceback (most recent call last):
  File "F:\scribe2\venv\lib\site-packages\urllib3\contrib\socks.py", line 88, in _new_conn
    **extra_kw
  File "F:\scribe2\venv\lib\site-packages\socks.py", line 262, in create_connection
    raise err
  File "F:\scribe2\venv\lib\site-packages\socks.py", line 252, in create_connection
    sock.connect((remote_host, remote_port))
  File "F:\scribe2\venv\lib\site-packages\socks.py", line 100, in wrapper
    return function(*args, **kwargs)
  File "F:\scribe2\venv\lib\site-packages\socks.py", line 844, in connect
    raise ProxyConnectionError(msg, error)
socks.ProxyConnectionError: Error connecting to SOCKS5 proxy 103.216.82.148:6667: timed out

During handling of the above exception, another exception occurred:

Traceback (most recent call last):
  File "F:\scribe2\venv\lib\site-packages\urllib3\connectionpool.py", line 601, in urlopen
    chunked=chunked)
  File "F:\scribe2\venv\lib\site-packages\urllib3\connectionpool.py", line 346, in _make_request
    self._validate_conn(conn)
  File "F:\scribe2\venv\lib\site-packages\urllib3\connectionpool.py", line 850, in _validate_conn
    conn.connect()
  File "F:\scribe2\venv\lib\site-packages\urllib3\connection.py", line 284, in connect
    conn = self._new_conn()
  File "F:\scribe2\venv\lib\site-packages\urllib3\contrib\socks.py", line 105, in _new_conn
    (self.host, self.timeout)
urllib3.exceptions.ConnectTimeoutError: (<urllib3.contrib.socks.SOCKSHTTPSConnection object at 0x0000000007299F60>, 'Connection to www.baidu.com timed out. (connect timeout=10)')

During handling of the above exception, another exception occurred:

Traceback (most recent call last):
  File "F:\scribe2\venv\lib\site-packages\requests\adapters.py", line 440, in send
    timeout=timeout
  File "F:\scribe2\venv\lib\site-packages\urllib3\connectionpool.py", line 639, in urlopen
    _stacktrace=sys.exc_info()[2])
  File "F:\scribe2\venv\lib\site-packages\urllib3\util\retry.py", line 388, in increment
    raise MaxRetryError(_pool, url, error or ResponseError(cause))
urllib3.exceptions.MaxRetryError: SOCKSHTTPSConnectionPool(host='www.baidu.com', port=443): Max retries exceeded with url: / (Caused by ConnectTimeoutError(<urllib3.contrib.socks.SOCKSHTTPSConnection object at 0x0000000007299F60>, 'Connection to www.baidu.com timed out. (connect timeout=10)'))

During handling of the above exception, another exception occurred:

Traceback (most recent call last):
  File "F:\scribe2\Server\Service\fanqiang_ip_service.py", line 21, in get_random_ip_port_dict
    test_proxy(ip_port_dict)
  File "F:\scribe2\Server\Service\fanqiang_ip_service.py", line 42, in test_proxy
    timeout=10)
  File "F:\scribe2\venv\lib\site-packages\requests\api.py", line 72, in get
    return request('get', url, params=params, **kwargs)
  File "F:\scribe2\venv\lib\site-packages\requests\api.py", line 58, in request
    return session.request(method=method, url=url, **kwargs)
  File "F:\scribe2\venv\lib\site-packages\requests\sessions.py", line 508, in request
    resp = self.send(prep, **send_kwargs)
  File "F:\scribe2\venv\lib\site-packages\requests\sessions.py", line 618, in send
    r = adapter.send(request, **kwargs)
  File "F:\scribe2\venv\lib\site-packages\requests\adapters.py", line 496, in send
    raise ConnectTimeout(e, request=request)
requests.exceptions.ConnectTimeout: SOCKSHTTPSConnectionPool(host='www.baidu.com', port=443): Max retries exceeded with url: / (Caused by ConnectTimeoutError(<urllib3.contrib.socks.SOCKSHTTPSConnection object at 0x0000000007299F60>, 'Connection to www.baidu.com timed out. (connect timeout=10)'))

During handling of the above exception, another exception occurred:

Traceback (most recent call last):
  File "F:/scribe2/Server/server.py", line 28, in get_lans_data
    ip_with_port=fanqiang_ip_service.get_random_ip_port_dict()
  File "F:\scribe2\Server\Service\fanqiang_ip_service.py", line 25, in get_random_ip_port_dict
    return get_random_ip_port_dict()
  File "F:\scribe2\Server\Service\fanqiang_ip_service.py", line 25, in get_random_ip_port_dict
    return get_random_ip_port_dict()
  File "F:\scribe2\Server\Service\fanqiang_ip_service.py", line 25, in get_random_ip_port_dict
    return get_random_ip_port_dict()
  [Previous line repeated 7 more times]
  File "F:\scribe2\Server\Service\fanqiang_ip_service.py", line 19, in get_random_ip_port_dict
    ip_port_dict = ip_list[math.floor(random.random() * len(ip_list))]
IndexError: list index out of range

2018-08-07 14:56:42,094 - Utils.log_utils - ERROR - e5bce674-9a0e-11e8-b843-005056c00008 - Traceback (most recent call last):
  File "F:\scribe2\venv\lib\site-packages\socks.py", line 832, in connect
    super(socksocket, self).connect(proxy_addr)
socket.timeout: timed out

During handling of the above exception, another exception occurred:

Traceback (most recent call last):
  File "F:\scribe2\venv\lib\site-packages\urllib3\contrib\socks.py", line 88, in _new_conn
    **extra_kw
  File "F:\scribe2\venv\lib\site-packages\socks.py", line 262, in create_connection
    raise err
  File "F:\scribe2\venv\lib\site-packages\socks.py", line 252, in create_connection
    sock.connect((remote_host, remote_port))
  File "F:\scribe2\venv\lib\site-packages\socks.py", line 100, in wrapper
    return function(*args, **kwargs)
  File "F:\scribe2\venv\lib\site-packages\socks.py", line 844, in connect
    raise ProxyConnectionError(msg, error)
socks.ProxyConnectionError: Error connecting to SOCKS5 proxy 192.169.182.200:24408: timed out

During handling of the above exception, another exception occurred:

Traceback (most recent call last):
  File "F:\scribe2\venv\lib\site-packages\urllib3\connectionpool.py", line 601, in urlopen
    chunked=chunked)
  File "F:\scribe2\venv\lib\site-packages\urllib3\connectionpool.py", line 346, in _make_request
    self._validate_conn(conn)
  File "F:\scribe2\venv\lib\site-packages\urllib3\connectionpool.py", line 850, in _validate_conn
    conn.connect()
  File "F:\scribe2\venv\lib\site-packages\urllib3\connection.py", line 284, in connect
    conn = self._new_conn()
  File "F:\scribe2\venv\lib\site-packages\urllib3\contrib\socks.py", line 105, in _new_conn
    (self.host, self.timeout)
urllib3.exceptions.ConnectTimeoutError: (<urllib3.contrib.socks.SOCKSHTTPSConnection object at 0x0000000006EA96D8>, 'Connection to www.baidu.com timed out. (connect timeout=10)')

During handling of the above exception, another exception occurred:

Traceback (most recent call last):
  File "F:\scribe2\venv\lib\site-packages\requests\adapters.py", line 440, in send
    timeout=timeout
  File "F:\scribe2\venv\lib\site-packages\urllib3\connectionpool.py", line 639, in urlopen
    _stacktrace=sys.exc_info()[2])
  File "F:\scribe2\venv\lib\site-packages\urllib3\util\retry.py", line 388, in increment
    raise MaxRetryError(_pool, url, error or ResponseError(cause))
urllib3.exceptions.MaxRetryError: SOCKSHTTPSConnectionPool(host='www.baidu.com', port=443): Max retries exceeded with url: / (Caused by ConnectTimeoutError(<urllib3.contrib.socks.SOCKSHTTPSConnection object at 0x0000000006EA96D8>, 'Connection to www.baidu.com timed out. (connect timeout=10)'))

During handling of the above exception, another exception occurred:

Traceback (most recent call last):
  File "F:\scribe2\Server\Service\fanqiang_ip_service.py", line 21, in get_random_ip_port_dict
    test_proxy(ip_port_dict)
  File "F:\scribe2\Server\Service\fanqiang_ip_service.py", line 42, in test_proxy
    timeout=10)
  File "F:\scribe2\venv\lib\site-packages\requests\api.py", line 72, in get
    return request('get', url, params=params, **kwargs)
  File "F:\scribe2\venv\lib\site-packages\requests\api.py", line 58, in request
    return session.request(method=method, url=url, **kwargs)
  File "F:\scribe2\venv\lib\site-packages\requests\sessions.py", line 508, in request
    resp = self.send(prep, **send_kwargs)
  File "F:\scribe2\venv\lib\site-packages\requests\sessions.py", line 618, in send
    r = adapter.send(request, **kwargs)
  File "F:\scribe2\venv\lib\site-packages\requests\adapters.py", line 496, in send
    raise ConnectTimeout(e, request=request)
requests.exceptions.ConnectTimeout: SOCKSHTTPSConnectionPool(host='www.baidu.com', port=443): Max retries exceeded with url: / (Caused by ConnectTimeoutError(<urllib3.contrib.socks.SOCKSHTTPSConnection object at 0x0000000006EA96D8>, 'Connection to www.baidu.com timed out. (connect timeout=10)'))

During handling of the above exception, another exception occurred:

Traceback (most recent call last):
  File "F:\scribe2\venv\lib\site-packages\urllib3\contrib\socks.py", line 88, in _new_conn
    **extra_kw
  File "F:\scribe2\venv\lib\site-packages\socks.py", line 262, in create_connection
    raise err
  File "F:\scribe2\venv\lib\site-packages\socks.py", line 252, in create_connection
    sock.connect((remote_host, remote_port))
  File "F:\scribe2\venv\lib\site-packages\socks.py", line 100, in wrapper
    return function(*args, **kwargs)
  File "F:\scribe2\venv\lib\site-packages\socks.py", line 844, in connect
    raise ProxyConnectionError(msg, error)
socks.ProxyConnectionError: Error connecting to SOCKS5 proxy 95.110.227.5:57201: timed out

During handling of the above exception, another exception occurred:

Traceback (most recent call last):
  File "F:\scribe2\venv\lib\site-packages\urllib3\connectionpool.py", line 601, in urlopen
    chunked=chunked)
  File "F:\scribe2\venv\lib\site-packages\urllib3\connectionpool.py", line 346, in _make_request
    self._validate_conn(conn)
  File "F:\scribe2\venv\lib\site-packages\urllib3\connectionpool.py", line 850, in _validate_conn
    conn.connect()
  File "F:\scribe2\venv\lib\site-packages\urllib3\connection.py", line 284, in connect
    conn = self._new_conn()
  File "F:\scribe2\venv\lib\site-packages\urllib3\contrib\socks.py", line 105, in _new_conn
    (self.host, self.timeout)
urllib3.exceptions.ConnectTimeoutError: (<urllib3.contrib.socks.SOCKSHTTPSConnection object at 0x0000000007118E48>, 'Connection to www.baidu.com timed out. (connect timeout=10)')

During handling of the above exception, another exception occurred:

Traceback (most recent call last):
  File "F:\scribe2\venv\lib\site-packages\requests\adapters.py", line 440, in send
    timeout=timeout
  File "F:\scribe2\venv\lib\site-packages\urllib3\connectionpool.py", line 639, in urlopen
    _stacktrace=sys.exc_info()[2])
  File "F:\scribe2\venv\lib\site-packages\urllib3\util\retry.py", line 388, in increment
    raise MaxRetryError(_pool, url, error or ResponseError(cause))
urllib3.exceptions.MaxRetryError: SOCKSHTTPSConnectionPool(host='www.baidu.com', port=443): Max retries exceeded with url: / (Caused by ConnectTimeoutError(<urllib3.contrib.socks.SOCKSHTTPSConnection object at 0x0000000007118E48>, 'Connection to www.baidu.com timed out. (connect timeout=10)'))

During handling of the above exception, another exception occurred:

Traceback (most recent call last):
  File "F:\scribe2\Server\Service\fanqiang_ip_service.py", line 21, in get_random_ip_port_dict
    test_proxy(ip_port_dict)
  File "F:\scribe2\Server\Service\fanqiang_ip_service.py", line 42, in test_proxy
    timeout=10)
  File "F:\scribe2\venv\lib\site-packages\requests\api.py", line 72, in get
    return request('get', url, params=params, **kwargs)
  File "F:\scribe2\venv\lib\site-packages\requests\api.py", line 58, in request
    return session.request(method=method, url=url, **kwargs)
  File "F:\scribe2\venv\lib\site-packages\requests\sessions.py", line 508, in request
    resp = self.send(prep, **send_kwargs)
  File "F:\scribe2\venv\lib\site-packages\requests\sessions.py", line 618, in send
    r = adapter.send(request, **kwargs)
  File "F:\scribe2\venv\lib\site-packages\requests\adapters.py", line 496, in send
    raise ConnectTimeout(e, request=request)
requests.exceptions.ConnectTimeout: SOCKSHTTPSConnectionPool(host='www.baidu.com', port=443): Max retries exceeded with url: / (Caused by ConnectTimeoutError(<urllib3.contrib.socks.SOCKSHTTPSConnection object at 0x0000000007118E48>, 'Connection to www.baidu.com timed out. (connect timeout=10)'))

During handling of the above exception, another exception occurred:

Traceback (most recent call last):
  File "F:\scribe2\venv\lib\site-packages\urllib3\contrib\socks.py", line 88, in _new_conn
    **extra_kw
  File "F:\scribe2\venv\lib\site-packages\socks.py", line 262, in create_connection
    raise err
  File "F:\scribe2\venv\lib\site-packages\socks.py", line 252, in create_connection
    sock.connect((remote_host, remote_port))
  File "F:\scribe2\venv\lib\site-packages\socks.py", line 100, in wrapper
    return function(*args, **kwargs)
  File "F:\scribe2\venv\lib\site-packages\socks.py", line 844, in connect
    raise ProxyConnectionError(msg, error)
socks.ProxyConnectionError: Error connecting to SOCKS5 proxy 146.252.241.90:56037: timed out

During handling of the above exception, another exception occurred:

Traceback (most recent call last):
  File "F:\scribe2\venv\lib\site-packages\urllib3\connectionpool.py", line 601, in urlopen
    chunked=chunked)
  File "F:\scribe2\venv\lib\site-packages\urllib3\connectionpool.py", line 346, in _make_request
    self._validate_conn(conn)
  File "F:\scribe2\venv\lib\site-packages\urllib3\connectionpool.py", line 850, in _validate_conn
    conn.connect()
  File "F:\scribe2\venv\lib\site-packages\urllib3\connection.py", line 284, in connect
    conn = self._new_conn()
  File "F:\scribe2\venv\lib\site-packages\urllib3\contrib\socks.py", line 105, in _new_conn
    (self.host, self.timeout)
urllib3.exceptions.ConnectTimeoutError: (<urllib3.contrib.socks.SOCKSHTTPSConnection object at 0x0000000006D800B8>, 'Connection to www.baidu.com timed out. (connect timeout=10)')

During handling of the above exception, another exception occurred:

Traceback (most recent call last):
  File "F:\scribe2\venv\lib\site-packages\requests\adapters.py", line 440, in send
    timeout=timeout
  File "F:\scribe2\venv\lib\site-packages\urllib3\connectionpool.py", line 639, in urlopen
    _stacktrace=sys.exc_info()[2])
  File "F:\scribe2\venv\lib\site-packages\urllib3\util\retry.py", line 388, in increment
    raise MaxRetryError(_pool, url, error or ResponseError(cause))
urllib3.exceptions.MaxRetryError: SOCKSHTTPSConnectionPool(host='www.baidu.com', port=443): Max retries exceeded with url: / (Caused by ConnectTimeoutError(<urllib3.contrib.socks.SOCKSHTTPSConnection object at 0x0000000006D800B8>, 'Connection to www.baidu.com timed out. (connect timeout=10)'))

During handling of the above exception, another exception occurred:

Traceback (most recent call last):
  File "F:\scribe2\Server\Service\fanqiang_ip_service.py", line 21, in get_random_ip_port_dict
    test_proxy(ip_port_dict)
  File "F:\scribe2\Server\Service\fanqiang_ip_service.py", line 42, in test_proxy
    timeout=10)
  File "F:\scribe2\venv\lib\site-packages\requests\api.py", line 72, in get
    return request('get', url, params=params, **kwargs)
  File "F:\scribe2\venv\lib\site-packages\requests\api.py", line 58, in request
    return session.request(method=method, url=url, **kwargs)
  File "F:\scribe2\venv\lib\site-packages\requests\sessions.py", line 508, in request
    resp = self.send(prep, **send_kwargs)
  File "F:\scribe2\venv\lib\site-packages\requests\sessions.py", line 618, in send
    r = adapter.send(request, **kwargs)
  File "F:\scribe2\venv\lib\site-packages\requests\adapters.py", line 496, in send
    raise ConnectTimeout(e, request=request)
requests.exceptions.ConnectTimeout: SOCKSHTTPSConnectionPool(host='www.baidu.com', port=443): Max retries exceeded with url: / (Caused by ConnectTimeoutError(<urllib3.contrib.socks.SOCKSHTTPSConnection object at 0x0000000006D800B8>, 'Connection to www.baidu.com timed out. (connect timeout=10)'))

During handling of the above exception, another exception occurred:

Traceback (most recent call last):
  File "F:\scribe2\venv\lib\site-packages\urllib3\contrib\socks.py", line 88, in _new_conn
    **extra_kw
  File "F:\scribe2\venv\lib\site-packages\socks.py", line 262, in create_connection
    raise err
  File "F:\scribe2\venv\lib\site-packages\socks.py", line 252, in create_connection
    sock.connect((remote_host, remote_port))
  File "F:\scribe2\venv\lib\site-packages\socks.py", line 100, in wrapper
    return function(*args, **kwargs)
  File "F:\scribe2\venv\lib\site-packages\socks.py", line 844, in connect
    raise ProxyConnectionError(msg, error)
socks.ProxyConnectionError: Error connecting to SOCKS5 proxy 192.169.217.40:35968: timed out

During handling of the above exception, another exception occurred:

Traceback (most recent call last):
  File "F:\scribe2\venv\lib\site-packages\urllib3\connectionpool.py", line 601, in urlopen
    chunked=chunked)
  File "F:\scribe2\venv\lib\site-packages\urllib3\connectionpool.py", line 346, in _make_request
    self._validate_conn(conn)
  File "F:\scribe2\venv\lib\site-packages\urllib3\connectionpool.py", line 850, in _validate_conn
    conn.connect()
  File "F:\scribe2\venv\lib\site-packages\urllib3\connection.py", line 284, in connect
    conn = self._new_conn()
  File "F:\scribe2\venv\lib\site-packages\urllib3\contrib\socks.py", line 105, in _new_conn
    (self.host, self.timeout)
urllib3.exceptions.ConnectTimeoutError: (<urllib3.contrib.socks.SOCKSHTTPSConnection object at 0x00000000071CCEF0>, 'Connection to www.baidu.com timed out. (connect timeout=10)')

During handling of the above exception, another exception occurred:

Traceback (most recent call last):
  File "F:\scribe2\venv\lib\site-packages\requests\adapters.py", line 440, in send
    timeout=timeout
  File "F:\scribe2\venv\lib\site-packages\urllib3\connectionpool.py", line 639, in urlopen
    _stacktrace=sys.exc_info()[2])
  File "F:\scribe2\venv\lib\site-packages\urllib3\util\retry.py", line 388, in increment
    raise MaxRetryError(_pool, url, error or ResponseError(cause))
urllib3.exceptions.MaxRetryError: SOCKSHTTPSConnectionPool(host='www.baidu.com', port=443): Max retries exceeded with url: / (Caused by ConnectTimeoutError(<urllib3.contrib.socks.SOCKSHTTPSConnection object at 0x00000000071CCEF0>, 'Connection to www.baidu.com timed out. (connect timeout=10)'))

During handling of the above exception, another exception occurred:

Traceback (most recent call last):
  File "F:\scribe2\Server\Service\fanqiang_ip_service.py", line 21, in get_random_ip_port_dict
    test_proxy(ip_port_dict)
  File "F:\scribe2\Server\Service\fanqiang_ip_service.py", line 42, in test_proxy
    timeout=10)
  File "F:\scribe2\venv\lib\site-packages\requests\api.py", line 72, in get
    return request('get', url, params=params, **kwargs)
  File "F:\scribe2\venv\lib\site-packages\requests\api.py", line 58, in request
    return session.request(method=method, url=url, **kwargs)
  File "F:\scribe2\venv\lib\site-packages\requests\sessions.py", line 508, in request
    resp = self.send(prep, **send_kwargs)
  File "F:\scribe2\venv\lib\site-packages\requests\sessions.py", line 618, in send
    r = adapter.send(request, **kwargs)
  File "F:\scribe2\venv\lib\site-packages\requests\adapters.py", line 496, in send
    raise ConnectTimeout(e, request=request)
requests.exceptions.ConnectTimeout: SOCKSHTTPSConnectionPool(host='www.baidu.com', port=443): Max retries exceeded with url: / (Caused by ConnectTimeoutError(<urllib3.contrib.socks.SOCKSHTTPSConnection object at 0x00000000071CCEF0>, 'Connection to www.baidu.com timed out. (connect timeout=10)'))

During handling of the above exception, another exception occurred:

Traceback (most recent call last):
  File "F:\scribe2\venv\lib\site-packages\urllib3\contrib\socks.py", line 88, in _new_conn
    **extra_kw
  File "F:\scribe2\venv\lib\site-packages\socks.py", line 262, in create_connection
    raise err
  File "F:\scribe2\venv\lib\site-packages\socks.py", line 252, in create_connection
    sock.connect((remote_host, remote_port))
  File "F:\scribe2\venv\lib\site-packages\socks.py", line 100, in wrapper
    return function(*args, **kwargs)
  File "F:\scribe2\venv\lib\site-packages\socks.py", line 844, in connect
    raise ProxyConnectionError(msg, error)
socks.ProxyConnectionError: Error connecting to SOCKS5 proxy 192.169.188.105:7432: timed out

During handling of the above exception, another exception occurred:

Traceback (most recent call last):
  File "F:\scribe2\venv\lib\site-packages\urllib3\connectionpool.py", line 601, in urlopen
    chunked=chunked)
  File "F:\scribe2\venv\lib\site-packages\urllib3\connectionpool.py", line 346, in _make_request
    self._validate_conn(conn)
  File "F:\scribe2\venv\lib\site-packages\urllib3\connectionpool.py", line 850, in _validate_conn
    conn.connect()
  File "F:\scribe2\venv\lib\site-packages\urllib3\connection.py", line 284, in connect
    conn = self._new_conn()
  File "F:\scribe2\venv\lib\site-packages\urllib3\contrib\socks.py", line 105, in _new_conn
    (self.host, self.timeout)
urllib3.exceptions.ConnectTimeoutError: (<urllib3.contrib.socks.SOCKSHTTPSConnection object at 0x0000000007258AC8>, 'Connection to www.baidu.com timed out. (connect timeout=10)')

During handling of the above exception, another exception occurred:

Traceback (most recent call last):
  File "F:\scribe2\venv\lib\site-packages\requests\adapters.py", line 440, in send
    timeout=timeout
  File "F:\scribe2\venv\lib\site-packages\urllib3\connectionpool.py", line 639, in urlopen
    _stacktrace=sys.exc_info()[2])
  File "F:\scribe2\venv\lib\site-packages\urllib3\util\retry.py", line 388, in increment
    raise MaxRetryError(_pool, url, error or ResponseError(cause))
urllib3.exceptions.MaxRetryError: SOCKSHTTPSConnectionPool(host='www.baidu.com', port=443): Max retries exceeded with url: / (Caused by ConnectTimeoutError(<urllib3.contrib.socks.SOCKSHTTPSConnection object at 0x0000000007258AC8>, 'Connection to www.baidu.com timed out. (connect timeout=10)'))

During handling of the above exception, another exception occurred:

Traceback (most recent call last):
  File "F:\scribe2\Server\Service\fanqiang_ip_service.py", line 21, in get_random_ip_port_dict
    test_proxy(ip_port_dict)
  File "F:\scribe2\Server\Service\fanqiang_ip_service.py", line 42, in test_proxy
    timeout=10)
  File "F:\scribe2\venv\lib\site-packages\requests\api.py", line 72, in get
    return request('get', url, params=params, **kwargs)
  File "F:\scribe2\venv\lib\site-packages\requests\api.py", line 58, in request
    return session.request(method=method, url=url, **kwargs)
  File "F:\scribe2\venv\lib\site-packages\requests\sessions.py", line 508, in request
    resp = self.send(prep, **send_kwargs)
  File "F:\scribe2\venv\lib\site-packages\requests\sessions.py", line 618, in send
    r = adapter.send(request, **kwargs)
  File "F:\scribe2\venv\lib\site-packages\requests\adapters.py", line 496, in send
    raise ConnectTimeout(e, request=request)
requests.exceptions.ConnectTimeout: SOCKSHTTPSConnectionPool(host='www.baidu.com', port=443): Max retries exceeded with url: / (Caused by ConnectTimeoutError(<urllib3.contrib.socks.SOCKSHTTPSConnection object at 0x0000000007258AC8>, 'Connection to www.baidu.com timed out. (connect timeout=10)'))

During handling of the above exception, another exception occurred:

Traceback (most recent call last):
  File "F:\scribe2\venv\lib\site-packages\urllib3\contrib\socks.py", line 88, in _new_conn
    **extra_kw
  File "F:\scribe2\venv\lib\site-packages\socks.py", line 262, in create_connection
    raise err
  File "F:\scribe2\venv\lib\site-packages\socks.py", line 252, in create_connection
    sock.connect((remote_host, remote_port))
  File "F:\scribe2\venv\lib\site-packages\socks.py", line 100, in wrapper
    return function(*args, **kwargs)
  File "F:\scribe2\venv\lib\site-packages\socks.py", line 844, in connect
    raise ProxyConnectionError(msg, error)
socks.ProxyConnectionError: Error connecting to SOCKS5 proxy 103.216.82.148:6667: timed out

During handling of the above exception, another exception occurred:

Traceback (most recent call last):
  File "F:\scribe2\venv\lib\site-packages\urllib3\connectionpool.py", line 601, in urlopen
    chunked=chunked)
  File "F:\scribe2\venv\lib\site-packages\urllib3\connectionpool.py", line 346, in _make_request
    self._validate_conn(conn)
  File "F:\scribe2\venv\lib\site-packages\urllib3\connectionpool.py", line 850, in _validate_conn
    conn.connect()
  File "F:\scribe2\venv\lib\site-packages\urllib3\connection.py", line 284, in connect
    conn = self._new_conn()
  File "F:\scribe2\venv\lib\site-packages\urllib3\contrib\socks.py", line 105, in _new_conn
    (self.host, self.timeout)
urllib3.exceptions.ConnectTimeoutError: (<urllib3.contrib.socks.SOCKSHTTPSConnection object at 0x00000000072EE8D0>, 'Connection to www.baidu.com timed out. (connect timeout=10)')

During handling of the above exception, another exception occurred:

Traceback (most recent call last):
  File "F:\scribe2\venv\lib\site-packages\requests\adapters.py", line 440, in send
    timeout=timeout
  File "F:\scribe2\venv\lib\site-packages\urllib3\connectionpool.py", line 639, in urlopen
    _stacktrace=sys.exc_info()[2])
  File "F:\scribe2\venv\lib\site-packages\urllib3\util\retry.py", line 388, in increment
    raise MaxRetryError(_pool, url, error or ResponseError(cause))
urllib3.exceptions.MaxRetryError: SOCKSHTTPSConnectionPool(host='www.baidu.com', port=443): Max retries exceeded with url: / (Caused by ConnectTimeoutError(<urllib3.contrib.socks.SOCKSHTTPSConnection object at 0x00000000072EE8D0>, 'Connection to www.baidu.com timed out. (connect timeout=10)'))

During handling of the above exception, another exception occurred:

Traceback (most recent call last):
  File "F:\scribe2\Server\Service\fanqiang_ip_service.py", line 21, in get_random_ip_port_dict
    test_proxy(ip_port_dict)
  File "F:\scribe2\Server\Service\fanqiang_ip_service.py", line 42, in test_proxy
    timeout=10)
  File "F:\scribe2\venv\lib\site-packages\requests\api.py", line 72, in get
    return request('get', url, params=params, **kwargs)
  File "F:\scribe2\venv\lib\site-packages\requests\api.py", line 58, in request
    return session.request(method=method, url=url, **kwargs)
  File "F:\scribe2\venv\lib\site-packages\requests\sessions.py", line 508, in request
    resp = self.send(prep, **send_kwargs)
  File "F:\scribe2\venv\lib\site-packages\requests\sessions.py", line 618, in send
    r = adapter.send(request, **kwargs)
  File "F:\scribe2\venv\lib\site-packages\requests\adapters.py", line 496, in send
    raise ConnectTimeout(e, request=request)
requests.exceptions.ConnectTimeout: SOCKSHTTPSConnectionPool(host='www.baidu.com', port=443): Max retries exceeded with url: / (Caused by ConnectTimeoutError(<urllib3.contrib.socks.SOCKSHTTPSConnection object at 0x00000000072EE8D0>, 'Connection to www.baidu.com timed out. (connect timeout=10)'))

During handling of the above exception, another exception occurred:

Traceback (most recent call last):
  File "F:/scribe2/Server/server.py", line 28, in get_lans_data
    ip_with_port=fanqiang_ip_service.get_random_ip_port_dict()
  File "F:\scribe2\Server\Service\fanqiang_ip_service.py", line 25, in get_random_ip_port_dict
    return get_random_ip_port_dict()
  File "F:\scribe2\Server\Service\fanqiang_ip_service.py", line 25, in get_random_ip_port_dict
    return get_random_ip_port_dict()
  File "F:\scribe2\Server\Service\fanqiang_ip_service.py", line 25, in get_random_ip_port_dict
    return get_random_ip_port_dict()
  [Previous line repeated 2 more times]
  File "F:\scribe2\Server\Service\fanqiang_ip_service.py", line 19, in get_random_ip_port_dict
    ip_port_dict = ip_list[math.floor(random.random() * len(ip_list))]
IndexError: list index out of range

2018-08-09 10:41:02,731 - Utils.log_utils - ERROR - a7672c34-9b7d-11e8-9073-005056c00008 - Traceback (most recent call last):
  File "F:/scribe2/Server/server.py", line 36, in get_new_ip_port
    ip_with_port_1,ip_with_port_2 = user_service.update_and_get_using_ip_port(account)
  File "F:\scribe2\Server\Service\user_service.py", line 30, in update_and_get_using_ip_port
    ip_port_1 , ip_port_2 = ''
ValueError: not enough values to unpack (expected 2, got 0)

2018-08-09 10:41:02,731 - Utils.log_utils - ERROR - a7672c34-9b7d-11e8-9073-005056c00008 - Traceback (most recent call last):
  File "F:/scribe2/Server/server.py", line 36, in get_new_ip_port
    ip_with_port_1,ip_with_port_2 = user_service.update_and_get_using_ip_port(account)
  File "F:\scribe2\Server\Service\user_service.py", line 30, in update_and_get_using_ip_port
    ip_port_1 , ip_port_2 = ''
ValueError: not enough values to unpack (expected 2, got 0)

2018-08-17 14:28:25,954 - Server.Service.fanqiang_ip_service - DEBUG - 开始测试123.206.56.247:1080
2018-08-17 14:29:41,914 - Server.Service.fanqiang_ip_service - DEBUG - 开始测试47.97.45.181:1080
2018-08-17 14:29:42,023 - Server.Service.fanqiang_ip_service - DEBUG - 开始测试45.195.200.132:1080
2018-08-17 14:29:42,048 - Server.Service.fanqiang_ip_service - DEBUG - 开始测试188.120.239.196:12249
2018-08-17 14:29:42,074 - Server.Service.fanqiang_ip_service - DEBUG - 开始测试192.169.217.40:5756
2018-08-17 14:29:42,083 - Server.Service.fanqiang_ip_service - DEBUG - 开始测试45.195.200.132:1080
2018-08-17 14:29:42,095 - Server.Service.fanqiang_ip_service - DEBUG - 开始测试50.63.153.173:12510
2018-08-17 14:29:42,108 - Server.Service.fanqiang_ip_service - DEBUG - 开始测试192.169.199.36:15199
2018-08-17 14:29:42,133 - Server.Service.fanqiang_ip_service - DEBUG - 开始测试103.216.82.186:6667
2018-08-17 14:29:42,148 - Server.Service.fanqiang_ip_service - DEBUG - 45.195.200.132:1080 失败
2018-08-17 14:29:42,203 - Server.Service.fanqiang_ip_service - DEBUG - 开始测试192.169.199.36:15199
2018-08-17 14:29:42,223 - Server.Service.fanqiang_ip_service - DEBUG - 开始测试109.200.132.146:8888
2018-08-17 14:29:42,227 - Server.Service.fanqiang_ip_service - DEBUG - 开始测试114.67.131.222:1080
2018-08-17 14:29:42,233 - Server.Service.fanqiang_ip_service - DEBUG - 开始测试176.118.131.136:6667
2018-08-17 14:29:42,239 - Server.Service.fanqiang_ip_service - DEBUG - 开始测试114.67.131.222:1080
2018-08-17 14:29:42,241 - Server.Service.fanqiang_ip_service - DEBUG - 开始测试192.169.189.215:60962
2018-08-17 14:29:42,258 - Server.Service.fanqiang_ip_service - DEBUG - 开始测试50.63.153.173:12510
2018-08-17 14:29:42,264 - Server.Service.fanqiang_ip_service - DEBUG - 45.195.200.132:1080 失败
2018-08-17 14:29:42,276 - Server.Service.fanqiang_ip_service - DEBUG - 开始测试192.169.189.215:60962
2018-08-17 14:29:42,285 - Server.Service.fanqiang_ip_service - DEBUG - 开始测试103.216.82.213:6667
2018-08-17 14:29:42,309 - Server.Service.fanqiang_ip_service - DEBUG - 开始测试50.63.167.72:48038
2018-08-17 14:29:42,322 - Server.Service.fanqiang_ip_service - DEBUG - 开始测试118.139.176.242:40440
2018-08-17 14:29:42,343 - Server.Service.fanqiang_ip_service - DEBUG - 开始测试47.97.45.181:1080
2018-08-17 14:29:42,351 - Server.Service.fanqiang_ip_service - DEBUG - 开始测试50.63.153.173:12510
2018-08-17 14:29:42,407 - Server.Service.fanqiang_ip_service - DEBUG - 开始测试91.142.208.125:9910
2018-08-17 14:29:43,144 - Server.Service.fanqiang_ip_service - DEBUG - 114.67.131.222:1080 失败
2018-08-17 14:29:43,149 - Server.Service.fanqiang_ip_service - DEBUG - 开始测试103.216.82.206:6667
2018-08-17 14:29:43,795 - Server.Service.fanqiang_ip_service - DEBUG - 50.63.153.173:12510 失败
2018-08-17 14:29:43,798 - Server.Service.fanqiang_ip_service - DEBUG - 开始测试103.216.82.199:6667
2018-08-17 14:29:43,827 - Server.Service.fanqiang_ip_service - DEBUG - 192.169.199.36:15199 失败
2018-08-17 14:29:43,830 - Server.Service.fanqiang_ip_service - DEBUG - 开始测试47.97.45.181:1080
2018-08-17 14:29:43,946 - Server.Service.fanqiang_ip_service - DEBUG - 192.169.199.36:15199 失败
2018-08-17 14:29:43,956 - Server.Service.fanqiang_ip_service - DEBUG - 开始测试50.63.167.72:48038
2018-08-17 14:29:44,001 - Server.Service.fanqiang_ip_service - DEBUG - 50.63.167.72:48038 失败
2018-08-17 14:29:44,006 - Server.Service.fanqiang_ip_service - DEBUG - 开始测试103.216.82.206:6667
2018-08-17 14:29:44,024 - Server.Service.fanqiang_ip_service - DEBUG - 50.63.153.173:12510 失败
2018-08-17 14:29:44,027 - Server.Service.fanqiang_ip_service - DEBUG - 开始测试192.169.233.2:3898
2018-08-17 14:29:44,098 - Server.Service.fanqiang_ip_service - DEBUG - 50.63.153.173:12510 失败
2018-08-17 14:29:44,101 - Server.Service.fanqiang_ip_service - DEBUG - 开始测试64.118.86.56:12890
2018-08-17 14:29:44,536 - Server.Service.fanqiang_ip_service - DEBUG - 91.142.208.125:9910 失败
2018-08-17 14:29:44,538 - Server.Service.fanqiang_ip_service - DEBUG - 开始测试192.169.233.2:3898
2018-08-17 14:29:44,772 - Server.Service.fanqiang_ip_service - DEBUG - 114.67.131.222:1080 失败
2018-08-17 14:29:44,774 - Server.Service.fanqiang_ip_service - DEBUG - 开始测试118.139.176.242:40440
2018-08-17 14:29:45,517 - Server.Service.fanqiang_ip_service - DEBUG - 50.63.167.72:48038 失败
2018-08-17 14:29:45,520 - Server.Service.fanqiang_ip_service - DEBUG - 开始测试103.216.82.186:6667
2018-08-17 14:29:45,569 - Server.Service.fanqiang_ip_service - DEBUG - 192.169.233.2:3898 失败
2018-08-17 14:29:45,571 - Server.Service.fanqiang_ip_service - DEBUG - 开始测试192.169.217.40:5756
2018-08-17 14:29:45,923 - Server.Service.fanqiang_ip_service - DEBUG - 64.118.86.56:12890 失败
2018-08-17 14:29:45,926 - Server.Service.fanqiang_ip_service - DEBUG - 开始测试132.148.130.208:17502
2018-08-17 14:29:46,064 - Server.Service.fanqiang_ip_service - DEBUG - 192.169.233.2:3898 失败
2018-08-17 14:29:46,067 - Server.Service.fanqiang_ip_service - DEBUG - 开始测试103.216.82.186:6667
2018-08-17 14:29:47,453 - Server.Service.fanqiang_ip_service - DEBUG - 132.148.130.208:17502 失败
2018-08-17 14:29:47,455 - Server.Service.fanqiang_ip_service - DEBUG - 开始测试103.216.82.199:6667
2018-08-17 14:29:52,250 - Server.Service.fanqiang_ip_service - DEBUG - 103.216.82.186:6667 失败
2018-08-17 14:29:52,252 - Server.Service.fanqiang_ip_service - DEBUG - 开始测试103.216.82.199:6667
2018-08-17 14:29:52,346 - Server.Service.fanqiang_ip_service - DEBUG - 109.200.132.146:8888 失败
2018-08-17 14:29:52,348 - Server.Service.fanqiang_ip_service - DEBUG - 开始测试103.85.92.132:1080
2018-08-17 14:29:53,169 - Server.Service.fanqiang_ip_service - DEBUG - 103.216.82.206:6667 失败
2018-08-17 14:29:53,171 - Server.Service.fanqiang_ip_service - DEBUG - 开始测试123.112.203.209:1080
2018-08-17 14:29:53,814 - Server.Service.fanqiang_ip_service - DEBUG - 103.216.82.199:6667 失败
2018-08-17 14:29:53,817 - Server.Service.fanqiang_ip_service - DEBUG - 开始测试64.118.87.12:12890
2018-08-17 14:29:54,028 - Server.Service.fanqiang_ip_service - DEBUG - 103.216.82.206:6667 失败
2018-08-17 14:29:54,031 - Server.Service.fanqiang_ip_service - DEBUG - 开始测试123.206.56.247:1080
2018-08-17 14:29:55,139 - Server.Service.fanqiang_ip_service - DEBUG - 103.85.92.132:1080 失败
2018-08-17 14:29:55,142 - Server.Service.fanqiang_ip_service - DEBUG - 开始测试188.120.239.196:12249
2018-08-17 14:29:55,495 - Server.Service.fanqiang_ip_service - DEBUG - 64.118.87.12:12890 失败
2018-08-17 14:29:55,498 - Server.Service.fanqiang_ip_service - DEBUG - 开始测试124.195.19.18:1080
2018-08-17 14:30:03,190 - Server.Service.fanqiang_ip_service - DEBUG - 123.112.203.209:1080 失败
2018-08-17 14:30:03,193 - Server.Service.fanqiang_ip_service - DEBUG - 开始测试118.139.164.224:1864
2018-08-17 14:30:04,927 - Server.Service.fanqiang_ip_service - DEBUG - 118.139.164.224:1864 失败
2018-08-17 14:30:04,929 - Server.Service.fanqiang_ip_service - DEBUG - 开始测试188.120.234.190:9261
2018-08-17 14:30:05,519 - Server.Service.fanqiang_ip_service - DEBUG - 124.195.19.18:1080 失败
2018-08-17 14:30:05,522 - Server.Service.fanqiang_ip_service - DEBUG - 开始测试192.169.189.215:60962
2018-08-17 17:31:42,071 - __main__ - ERROR - 58e96e6c-a200-11e8-b5e4-005056c00008 - Traceback (most recent call last):
  File "F:/scribe2/Server/server.py", line 36, in get_new_ip_port
    vertify_pass,not_pass_reason = user_service.vertify_user(account,password)
ValueError: too many values to unpack (expected 2)

2018-08-17 17:35:17,702 - __main__ - ERROR - b20d8f8a-a200-11e8-8d0a-005056c00008 - Traceback (most recent call last):
  File "F:/scribe2/Server/server.py", line 36, in get_new_ip_port
    vertify_pass,not_pass_reason = user_service.vertify_user(account,password)[:1]
ValueError: not enough values to unpack (expected 2, got 1)

2018-08-17 17:44:02,919 - Server.Service.fanqiang_ip_service - DEBUG - 开始测试123.206.56.247:1080
2018-08-27 16:51:47,651 - Server.Service.fanqiang_ip_service - DEBUG - 开始测试123.206.56.247:1080
2018-08-27 16:51:57,756 - Server.Service.fanqiang_ip_service - DEBUG - 开始测试192.169.202.104:32991
2018-08-27 16:52:11,405 - Server.Service.fanqiang_ip_service - DEBUG - 192.169.202.104:32991 失败
2018-08-27 16:52:11,407 - Server.Service.fanqiang_ip_service - DEBUG - 开始测试78.31.106.146:8080
2018-08-27 16:52:22,074 - Server.Service.fanqiang_ip_service - DEBUG - 78.31.106.146:8080 失败
2018-08-27 16:52:22,076 - Server.Service.fanqiang_ip_service - DEBUG - 开始测试5.2.67.213:1080
2018-08-27 16:52:23,972 - Server.Service.fanqiang_ip_service - DEBUG - 5.2.67.213:1080 失败
2018-08-27 16:52:23,974 - Server.Service.fanqiang_ip_service - DEBUG - 开始测试171.25.175.22:6667
2018-08-28 13:47:33,432 - Server.Service.fanqiang_ip_service - DEBUG - 开始测试171.25.175.22:6667
2018-08-29 16:49:53,524 - __main__ - ERROR - 7dbad992-ab68-11e8-8d46-005056c00008 - Traceback (most recent call last):
  File "F:/scribe2/Server/server.py", line 40, in get_new_ip_port
    ip_with_port_1,ip_with_port_2 = user_service.update_and_get_using_ip_port(account)
  File "F:\scribe2\Server\Service\user_service.py", line 83, in update_and_get_using_ip_port
    ip_with_port_dict_1 = ip_collection.query({'ip_with_port':user['ip_with_port_1']}).next()
  File "F:\scribe2\venv\lib\site-packages\pymongo\cursor.py", line 1197, in next
    raise StopIteration
StopIteration

2018-08-29 16:52:07,410 - __main__ - ERROR - ce79c764-ab68-11e8-a50b-005056c00008 - Traceback (most recent call last):
  File "F:/scribe2/Server/server.py", line 40, in get_new_ip_port
    ip_with_port_1,ip_with_port_2 = user_service.update_and_get_using_ip_port(account)
  File "F:\scribe2\Server\Service\user_service.py", line 83, in update_and_get_using_ip_port
    ip_with_port_dict_1 = ip_collection.query({'ip_with_port':user['ip_with_port_1']}).next()
  File "F:\scribe2\venv\lib\site-packages\pymongo\cursor.py", line 1197, in next
    raise StopIteration
StopIteration

2018-08-29 16:56:07,663 - __main__ - ERROR - 5d9f7074-ab69-11e8-bfc9-005056c00008 - Traceback (most recent call last):
  File "F:/scribe2/Server/server.py", line 40, in get_new_ip_port
    ip_with_port_1,ip_with_port_2 = user_service.update_and_get_using_ip_port(account)
  File "F:\scribe2\Server\Service\user_service.py", line 83, in update_and_get_using_ip_port
    ip_with_port_dict_1 = ip_collection.query({'ip_with_port':user['ip_with_port_1']}).next()
  File "F:\scribe2\venv\lib\site-packages\pymongo\cursor.py", line 1197, in next
    raise StopIteration
StopIteration

2018-08-29 17:16:19,583 - Server.Service.fanqiang_ip_service - DEBUG - 开始测试192.169.189.215:60962
2018-08-29 17:16:22,570 - Server.Service.fanqiang_ip_service - DEBUG - 开始测试192.169.189.215:60962
2018-08-29 18:27:18,578 - Server.Service.fanqiang_ip_service - DEBUG - 开始测试50.63.167.72:12645
2018-08-29 18:27:24,159 - Server.Service.fanqiang_ip_service - DEBUG - 开始测试50.63.167.72:12645
2018-08-30 11:01:43,380 - Server.Service.fanqiang_ip_service - DEBUG - 开始测试50.63.167.72:28232
2018-08-30 11:01:53,023 - Server.Service.fanqiang_ip_service - DEBUG - 开始测试50.63.167.72:28232
2018-08-30 11:12:13,744 - Server.Service.fanqiang_ip_service - DEBUG - 开始测试192.169.218.61:63677
2018-08-30 11:12:19,683 - Server.Service.fanqiang_ip_service - DEBUG - 开始测试192.169.218.61:63677
2018-08-30 11:12:32,920 - Server.Service.fanqiang_ip_service - DEBUG - 开始测试95.110.207.71:26187
2018-08-30 11:12:40,541 - Server.Service.fanqiang_ip_service - DEBUG - 开始测试95.110.207.71:26187
2018-08-30 11:33:15,636 - Server.Service.fanqiang_ip_service - DEBUG - 开始测试94.23.115.227:3328
2018-08-30 11:33:17,610 - Server.Service.fanqiang_ip_service - DEBUG - 94.23.115.227:3328 失败
2018-08-30 11:33:17,615 - Server.Service.fanqiang_ip_service - DEBUG - 开始测试31.148.219.150:1443
2018-08-30 11:33:18,124 - Server.Service.fanqiang_ip_service - DEBUG - 31.148.219.150:1443 失败
2018-08-30 11:33:18,134 - Server.Service.fanqiang_ip_service - DEBUG - 开始测试192.169.189.215:26973
2018-08-30 11:33:28,150 - Server.Service.fanqiang_ip_service - DEBUG - 192.169.189.215:26973 失败
2018-08-30 11:33:28,154 - Server.Service.fanqiang_ip_service - DEBUG - 开始测试166.62.39.86:14182
2018-08-30 11:33:37,272 - Server.Service.fanqiang_ip_service - DEBUG - 开始测试166.62.39.86:14182
2018-08-30 14:51:54,819 - Server.Service.fanqiang_ip_service - DEBUG - 开始测试50.62.35.225:16040
2018-08-30 14:52:03,912 - Server.Service.fanqiang_ip_service - DEBUG - 开始测试50.62.35.225:16040
2018-08-30 15:38:34,989 - Server.Service.fanqiang_ip_service - DEBUG - 开始测试132.148.130.208:42210
2018-08-30 15:38:53,497 - Server.Service.fanqiang_ip_service - DEBUG - 开始测试132.148.130.208:42210
2018-08-30 15:51:38,509 - Server.Service.fanqiang_ip_service - DEBUG - 开始测试46.255.216.130:1080
2018-08-30 15:51:48,636 - Server.Service.fanqiang_ip_service - DEBUG - 46.255.216.130:1080 失败
2018-08-30 15:51:48,651 - Server.Service.fanqiang_ip_service - DEBUG - 开始测试185.81.96.184:1080
2018-08-30 15:52:14,219 - Server.Service.fanqiang_ip_service - DEBUG - 开始测试185.81.96.184:1080
2018-08-30 16:17:37,401 - Server.Service.user_service - WARNING - 出现ip_port被删而没有更新数据库的情况
2018-08-30 16:17:49,349 - Server.Service.fanqiang_ip_service - DEBUG - 开始测试36.66.133.247:49834
2018-08-30 16:17:59,475 - Server.Service.fanqiang_ip_service - DEBUG - 36.66.133.247:49834 失败
2018-08-30 16:17:59,490 - Server.Service.fanqiang_ip_service - DEBUG - 开始测试192.169.140.100:27734
2018-08-30 16:18:12,205 - Server.Service.fanqiang_ip_service - DEBUG - 开始测试192.169.140.100:27734
2018-08-30 16:39:07,042 - Server.Service.fanqiang_ip_service - DEBUG - 开始测试192.169.140.100:27734
2018-08-30 16:49:30,503 - Server.Service.fanqiang_ip_service - DEBUG - 开始测试192.169.140.100:27734
2018-08-30 16:59:58,643 - Server.Service.fanqiang_ip_service - DEBUG - 开始测试192.169.140.100:27734
2018-08-30 18:01:42,493 - Server.Service.fanqiang_ip_service - DEBUG - 开始测试192.169.140.100:27734
2018-08-30 18:12:04,393 - Server.Service.fanqiang_ip_service - DEBUG - 开始测试192.169.140.100:27734
2018-08-30 18:12:23,607 - Server.Service.user_service - DEBUG - 代理 192.169.140.100:27734 已失效
2018-08-30 18:12:23,704 - Server.Service.fanqiang_ip_service - DEBUG - 开始测试132.148.130.208:42210
2018-08-30 18:12:33,770 - Server.Service.fanqiang_ip_service - DEBUG - 132.148.130.208:42210 失败
2018-08-30 18:12:33,779 - Server.Service.fanqiang_ip_service - DEBUG - 开始测试192.169.140.100:12645
2018-08-30 18:12:35,335 - Server.Service.fanqiang_ip_service - DEBUG - 192.169.140.100:12645 失败
2018-08-30 18:12:35,345 - Server.Service.fanqiang_ip_service - DEBUG - 开始测试192.169.189.215:47385
2018-08-30 18:22:52,356 - Server.Service.fanqiang_ip_service - DEBUG - 开始测试192.169.189.215:47385
2018-08-30 18:23:02,399 - Server.Service.user_service - DEBUG - 代理 192.169.189.215:47385 已失效
2018-08-30 18:23:02,426 - Server.Service.fanqiang_ip_service - DEBUG - 开始测试188.120.228.252:32773
2018-08-30 18:23:06,352 - Server.Service.fanqiang_ip_service - DEBUG - 188.120.228.252:32773 失败
2018-08-30 18:23:06,361 - Server.Service.fanqiang_ip_service - DEBUG - 开始测试114.67.131.222:1080
2018-08-30 18:33:15,315 - Server.Service.fanqiang_ip_service - DEBUG - 开始测试114.67.131.222:1080
2018-08-30 18:33:16,263 - Server.Service.user_service - DEBUG - 代理 114.67.131.222:1080 已失效
2018-08-30 18:33:16,301 - Server.Service.fanqiang_ip_service - DEBUG - 开始测试132.148.130.46:57681
2018-08-30 18:33:17,935 - Server.Service.fanqiang_ip_service - DEBUG - 132.148.130.46:57681 失败
2018-08-30 18:33:17,945 - Server.Service.fanqiang_ip_service - DEBUG - 开始测试192.169.138.184:64876
2018-08-30 20:04:23,832 - Server.Service.fanqiang_ip_service - DEBUG - 开始测试192.169.138.184:64876
2018-08-30 20:25:08,102 - Server.Service.fanqiang_ip_service - DEBUG - 开始测试192.169.138.184:64876
2018-08-30 20:25:18,145 - Server.Service.user_service - DEBUG - 代理 192.169.138.184:64876 已失效
2018-08-30 20:25:18,170 - Server.Service.fanqiang_ip_service - DEBUG - 开始测试166.62.39.86:14182
2018-08-30 20:25:19,721 - Server.Service.fanqiang_ip_service - DEBUG - 166.62.39.86:14182 失败
2018-08-30 20:25:19,730 - Server.Service.fanqiang_ip_service - DEBUG - 开始测试192.169.140.100:40880
2018-08-30 20:25:23,624 - Server.Service.fanqiang_ip_service - DEBUG - 192.169.140.100:40880 失败
2018-08-30 20:25:23,634 - Server.Service.fanqiang_ip_service - DEBUG - 开始测试50.63.13.254:19315
2018-08-30 20:25:25,211 - Server.Service.fanqiang_ip_service - DEBUG - 50.63.13.254:19315 失败
2018-08-30 20:25:25,220 - Server.Service.fanqiang_ip_service - DEBUG - 开始测试181.113.23.205:1080
2018-08-30 21:27:18,635 - Server.Service.fanqiang_ip_service - DEBUG - 开始测试181.113.23.205:1080
2018-08-30 21:27:47,963 - Server.Service.user_service - DEBUG - 代理 181.113.23.205:1080 已失效
2018-08-30 21:27:47,975 - Server.Service.fanqiang_ip_service - DEBUG - 开始测试50.63.153.173:31135
2018-08-30 21:27:58,024 - Server.Service.fanqiang_ip_service - DEBUG - 50.63.153.173:31135 失败
2018-08-30 21:27:58,033 - Server.Service.fanqiang_ip_service - DEBUG - 开始测试192.169.199.36:14818
2018-08-30 21:28:01,923 - Server.Service.fanqiang_ip_service - DEBUG - 192.169.199.36:14818 失败
2018-08-30 21:28:01,931 - Server.Service.fanqiang_ip_service - DEBUG - 开始测试192.169.188.105:26973
2018-08-30 21:28:21,154 - Server.Service.fanqiang_ip_service - DEBUG - 192.169.188.105:26973 失败
2018-08-30 21:28:21,163 - Server.Service.fanqiang_ip_service - DEBUG - 开始测试192.169.233.35:45888
2018-08-30 21:28:31,235 - Server.Service.fanqiang_ip_service - DEBUG - 192.169.233.35:45888 失败
2018-08-30 21:28:31,244 - Server.Service.fanqiang_ip_service - DEBUG - 开始测试165.227.130.164:1090
2018-08-30 22:19:29,207 - Server.Service.fanqiang_ip_service - DEBUG - 开始测试165.227.130.164:1090
2018-08-30 22:19:42,584 - Server.Service.user_service - DEBUG - 代理 165.227.130.164:1090 已失效
2018-08-30 22:19:42,604 - Server.Service.fanqiang_ip_service - DEBUG - 开始测试50.63.153.173:45995
2018-08-30 22:40:18,116 - Server.Service.fanqiang_ip_service - DEBUG - 开始测试50.63.153.173:45995
2018-08-30 23:00:55,078 - Server.Service.fanqiang_ip_service - DEBUG - 开始测试50.63.153.173:45995
2018-08-30 23:01:14,296 - Server.Service.user_service - DEBUG - 代理 50.63.153.173:45995 已失效
2018-08-30 23:01:14,307 - Server.Service.fanqiang_ip_service - DEBUG - 开始测试103.28.149.118:8088
2018-08-30 23:11:46,003 - Server.Service.fanqiang_ip_service - DEBUG - 开始测试103.28.149.118:8088
2018-08-30 23:52:44,771 - Server.Service.fanqiang_ip_service - DEBUG - 开始测试103.28.149.118:8088
2018-08-30 23:52:54,815 - Server.Service.user_service - DEBUG - 代理 103.28.149.118:8088 已失效
2018-08-30 23:52:54,850 - Server.Service.fanqiang_ip_service - DEBUG - 开始测试46.255.216.246:1080
2018-08-30 23:53:04,914 - Server.Service.fanqiang_ip_service - DEBUG - 46.255.216.246:1080 失败
2018-08-30 23:53:04,922 - Server.Service.fanqiang_ip_service - DEBUG - 开始测试185.81.96.184:1080
2018-08-30 23:53:06,884 - Server.Service.fanqiang_ip_service - DEBUG - 185.81.96.184:1080 失败
2018-08-30 23:53:06,892 - Server.Service.fanqiang_ip_service - DEBUG - 开始测试50.63.167.72:6131
2018-08-30 23:53:16,941 - Server.Service.fanqiang_ip_service - DEBUG - 50.63.167.72:6131 失败
2018-08-30 23:53:16,949 - Server.Service.fanqiang_ip_service - DEBUG - 开始测试192.169.218.61:63677
2018-08-31 00:03:34,145 - Server.Service.fanqiang_ip_service - DEBUG - 开始测试192.169.218.61:63677
2018-08-31 00:34:02,869 - Server.Service.fanqiang_ip_service - DEBUG - 开始测试192.169.218.61:63677
2018-08-31 01:35:13,574 - Server.Service.fanqiang_ip_service - DEBUG - 开始测试192.169.218.61:63677
2018-08-31 02:16:07,272 - Server.Service.fanqiang_ip_service - DEBUG - 开始测试192.169.218.61:63677
2018-08-31 02:26:32,639 - Server.Service.fanqiang_ip_service - DEBUG - 开始测试192.169.218.61:63677
2018-08-31 02:26:42,693 - Server.Service.user_service - DEBUG - 代理 192.169.218.61:63677 已失效
2018-08-31 02:26:42,705 - Server.Service.fanqiang_ip_service - DEBUG - 开始测试95.110.194.245:45007
2018-08-31 04:28:18,818 - Server.Service.fanqiang_ip_service - DEBUG - 开始测试95.110.194.245:45007
2018-08-31 04:28:28,862 - Server.Service.user_service - DEBUG - 代理 95.110.194.245:45007 已失效
2018-08-31 04:28:28,884 - Server.Service.fanqiang_ip_service - DEBUG - 开始测试50.63.167.72:38827
2018-08-31 04:28:39,122 - Server.Service.fanqiang_ip_service - DEBUG - 50.63.167.72:38827 失败
2018-08-31 04:28:39,130 - Server.Service.fanqiang_ip_service - DEBUG - 开始测试192.169.217.40:5756
2018-08-31 04:49:06,942 - Server.Service.fanqiang_ip_service - DEBUG - 开始测试192.169.217.40:5756
2018-08-31 04:49:16,986 - Server.Service.user_service - DEBUG - 代理 192.169.217.40:5756 已失效
2018-08-31 04:49:16,997 - Server.Service.fanqiang_ip_service - DEBUG - 开始测试31.31.73.178:10080
2018-08-31 04:49:27,261 - Server.Service.fanqiang_ip_service - DEBUG - 31.31.73.178:10080 失败
2018-08-31 04:49:27,269 - Server.Service.fanqiang_ip_service - DEBUG - 开始测试188.120.234.190:9261
2018-08-31 05:20:02,224 - Server.Service.fanqiang_ip_service - DEBUG - 开始测试188.120.234.190:9261
2018-08-31 05:40:25,836 - Server.Service.fanqiang_ip_service - DEBUG - 开始测试188.120.234.190:9261
2018-08-31 05:40:45,631 - Server.Service.user_service - DEBUG - 代理 188.120.234.190:9261 已失效
2018-08-31 05:40:45,642 - Server.Service.fanqiang_ip_service - DEBUG - 开始测试168.232.198.81:6667
2018-08-31 06:01:18,808 - Server.Service.fanqiang_ip_service - DEBUG - 开始测试168.232.198.81:6667
2018-08-31 06:21:48,509 - Server.Service.fanqiang_ip_service - DEBUG - 开始测试168.232.198.81:6667
2018-08-31 06:32:13,067 - Server.Service.fanqiang_ip_service - DEBUG - 开始测试168.232.198.81:6667
2018-08-31 06:32:23,110 - Server.Service.user_service - DEBUG - 代理 168.232.198.81:6667 已失效
2018-08-31 06:32:23,121 - Server.Service.fanqiang_ip_service - DEBUG - 开始测试97.74.230.16:7011
2018-08-31 07:43:43,796 - Server.Service.fanqiang_ip_service - DEBUG - 开始测试97.74.230.16:7011
2018-08-31 08:55:05,581 - Server.Service.fanqiang_ip_service - DEBUG - 开始测试97.74.230.16:7011
2018-08-31 09:25:50,974 - Server.Service.fanqiang_ip_service - DEBUG - 开始测试97.74.230.16:7011
2018-08-31 09:26:14,705 - Server.Service.user_service - DEBUG - 代理 97.74.230.16:7011 已失效
2018-08-31 09:26:14,711 - Server.Service.fanqiang_ip_service - DEBUG - 开始测试50.62.35.225:16040
2018-08-31 09:36:38,274 - Server.Service.fanqiang_ip_service - DEBUG - 开始测试50.62.35.225:16040
2018-08-31 09:36:48,292 - Server.Service.user_service - DEBUG - 代理 50.62.35.225:16040 已失效
2018-08-31 09:36:48,297 - Server.Service.fanqiang_ip_service - DEBUG - 开始测试192.169.136.232:19607
2018-08-31 09:37:12,556 - Server.Service.fanqiang_ip_service - DEBUG - 随机ip_port 192.169.136.232:19607 无法翻墙，从新获取
2018-08-31 09:37:12,560 - Server.Service.fanqiang_ip_service - DEBUG - 开始测试192.169.250.198:30336
2018-08-31 09:37:33,286 - Server.Service.fanqiang_ip_service - DEBUG - 随机ip_port 192.169.250.198:30336 无法翻墙，从新获取
2018-08-31 09:37:33,289 - Server.Service.fanqiang_ip_service - DEBUG - 开始测试192.169.188.105:47385
2018-08-31 09:58:01,814 - Server.Service.fanqiang_ip_service - DEBUG - 开始测试192.169.188.105:47385
2018-08-31 10:28:40,115 - Server.Service.fanqiang_ip_service - DEBUG - 开始测试192.169.188.105:47385
2018-08-31 11:09:28,057 - Server.Service.fanqiang_ip_service - DEBUG - 开始测试192.169.188.105:47385
2018-08-31 14:41:59,921 - Server.Service.fanqiang_ip_service - DEBUG - 开始测试192.169.188.105:47385
2018-08-31 14:52:28,697 - Server.Service.fanqiang_ip_service - DEBUG - 开始测试192.169.188.105:47385
2018-08-31 14:52:38,714 - Server.Service.user_service - DEBUG - 代理 192.169.188.105:47385 已失效
2018-08-31 15:02:18,551 - Server.Service.fanqiang_ip_service - DEBUG - 开始测试192.169.188.105:47385
2018-08-31 15:02:37,338 - __main__ - DEBUG - 代理 192.169.188.105:47385 已失效
2018-08-31 15:04:36,503 - Server.Service.fanqiang_ip_service - DEBUG - 开始测试192.169.188.105:47385
2018-08-31 15:04:46,513 - __main__ - DEBUG - 代理 192.169.188.105:47385 已失效
2018-08-31 15:05:05,436 - Server.Service.fanqiang_ip_service - DEBUG - 开始测试95.110.207.71:26187
2018-08-31 15:05:47,499 - Server.Service.fanqiang_ip_service - DEBUG - 开始测试192.169.188.105:47385
2018-08-31 15:16:09,398 - Server.Service.fanqiang_ip_service - DEBUG - 开始测试192.169.188.105:47385
2018-08-31 15:16:28,592 - Server.Service.user_service - DEBUG - 代理 192.169.188.105:47385 已失效
2018-08-31 15:16:28,613 - Server.Service.fanqiang_ip_service - DEBUG - 开始测试192.169.250.198:1125
2018-08-31 15:57:11,280 - Server.Service.fanqiang_ip_service - DEBUG - 开始测试192.169.250.198:1125
2018-09-03 15:56:09,448 - Server.Service.fanqiang_ip_service - DEBUG - 开始测试192.169.250.198:1125
2018-09-03 16:26:57,346 - Server.Service.fanqiang_ip_service - DEBUG - 开始测试192.169.250.198:1125
2018-09-03 16:27:17,156 - Server.Service.user_service - DEBUG - 代理 192.169.250.198:1125 已失效
2018-09-03 16:27:17,182 - Server.Service.fanqiang_ip_service - DEBUG - 开始测试50.63.13.254:35451
2018-09-03 17:09:06,874 - Server.Service.fanqiang_ip_service - DEBUG - 开始测试50.63.13.254:35451
2018-09-03 17:49:53,409 - Server.Service.fanqiang_ip_service - DEBUG - 开始测试50.63.13.254:35451
2018-09-03 22:22:35,414 - Server.Service.fanqiang_ip_service - DEBUG - 开始测试50.63.13.254:35451
2018-09-03 22:32:59,310 - Server.Service.fanqiang_ip_service - DEBUG - 开始测试50.63.13.254:35451
2018-09-03 22:33:12,658 - Server.Service.user_service - DEBUG - 代理 50.63.13.254:35451 已失效
2018-09-03 22:33:12,670 - Server.Service.fanqiang_ip_service - DEBUG - 开始测试95.110.207.71:26187
2018-09-03 22:33:22,686 - Server.Service.fanqiang_ip_service - DEBUG - 随机ip_port 95.110.207.71:26187 无法翻墙，从新获取
2018-09-03 22:33:22,696 - Server.Service.fanqiang_ip_service - DEBUG - 开始测试118.139.165.55:51602
2018-09-03 22:33:24,591 - Server.Service.fanqiang_ip_service - DEBUG - 随机ip_port 118.139.165.55:51602 无法翻墙，从新获取
2018-09-03 22:33:24,600 - Server.Service.fanqiang_ip_service - DEBUG - 开始测试192.169.202.104:32991
2018-09-03 22:33:38,174 - Server.Service.fanqiang_ip_service - DEBUG - 随机ip_port 192.169.202.104:32991 无法翻墙，从新获取
2018-09-03 22:33:38,183 - Server.Service.fanqiang_ip_service - DEBUG - 开始测试192.169.140.100:3016
2018-09-03 22:33:48,199 - Server.Service.fanqiang_ip_service - DEBUG - 随机ip_port 192.169.140.100:3016 无法翻墙，从新获取
2018-09-03 22:33:48,208 - Server.Service.fanqiang_ip_service - DEBUG - 开始测试50.63.153.173:31135
2018-09-03 22:54:43,771 - Server.Service.fanqiang_ip_service - DEBUG - 开始测试50.63.153.173:31135
2018-09-03 23:25:29,098 - Server.Service.fanqiang_ip_service - DEBUG - 开始测试50.63.153.173:31135
2018-09-03 23:25:48,303 - Server.Service.user_service - DEBUG - 代理 50.63.153.173:31135 已失效
2018-09-03 23:25:48,314 - Server.Service.fanqiang_ip_service - DEBUG - 开始测试103.216.82.211:6667
2018-09-03 23:36:11,465 - Server.Service.fanqiang_ip_service - DEBUG - 开始测试103.216.82.211:6667
2018-09-03 23:36:21,482 - Server.Service.user_service - DEBUG - 代理 103.216.82.211:6667 已失效
2018-09-03 23:36:21,493 - Server.Service.fanqiang_ip_service - DEBUG - 开始测试198.12.157.28:53213
2018-09-04 00:27:04,955 - Server.Service.fanqiang_ip_service - DEBUG - 开始测试198.12.157.28:53213
2018-09-04 03:38:54,415 - Server.Service.fanqiang_ip_service - DEBUG - 开始测试198.12.157.28:53213
2018-09-04 03:39:04,435 - Server.Service.user_service - DEBUG - 代理 198.12.157.28:53213 已失效
2018-09-04 03:39:04,447 - Server.Service.fanqiang_ip_service - DEBUG - 开始测试50.63.153.173:45995
2018-09-04 03:39:14,462 - Server.Service.fanqiang_ip_service - DEBUG - 随机ip_port 50.63.153.173:45995 无法翻墙，从新获取
2018-09-04 03:39:14,471 - Server.Service.fanqiang_ip_service - DEBUG - 开始测试37.187.44.39:10080
2018-09-04 03:39:16,155 - Server.Service.fanqiang_ip_service - DEBUG - 随机ip_port 37.187.44.39:10080 无法翻墙，从新获取
2018-09-04 03:39:16,167 - Server.Service.fanqiang_ip_service - DEBUG - 开始测试192.169.217.40:5756
2018-09-04 03:39:26,183 - Server.Service.fanqiang_ip_service - DEBUG - 随机ip_port 192.169.217.40:5756 无法翻墙，从新获取
2018-09-04 03:39:26,193 - Server.Service.fanqiang_ip_service - DEBUG - 开始测试64.118.87.28:53344
2018-09-04 03:39:27,910 - Server.Service.fanqiang_ip_service - DEBUG - 随机ip_port 64.118.87.28:53344 无法翻墙，从新获取
2018-09-04 03:39:27,919 - Server.Service.fanqiang_ip_service - DEBUG - 开始测试192.169.140.100:62734
2018-09-04 03:39:34,768 - Server.Service.fanqiang_ip_service - DEBUG - 随机ip_port 192.169.140.100:62734 无法翻墙，从新获取
2018-09-04 03:39:34,778 - Server.Service.fanqiang_ip_service - DEBUG - 开始测试192.169.193.54:52301
2018-09-04 03:39:44,794 - Server.Service.fanqiang_ip_service - DEBUG - 随机ip_port 192.169.193.54:52301 无法翻墙，从新获取
2018-09-04 03:39:44,804 - Server.Service.fanqiang_ip_service - DEBUG - 开始测试192.169.182.200:16425
2018-09-04 03:39:55,675 - Server.Service.fanqiang_ip_service - DEBUG - 随机ip_port 192.169.182.200:16425 无法翻墙，从新获取
2018-09-04 03:39:55,684 - Server.Service.fanqiang_ip_service - DEBUG - 开始测试192.169.188.105:60962
2018-09-04 03:40:05,702 - Server.Service.fanqiang_ip_service - DEBUG - 随机ip_port 192.169.188.105:60962 无法翻墙，从新获取
2018-09-04 03:40:05,712 - Server.Service.fanqiang_ip_service - DEBUG - 开始测试192.169.140.100:17365
2018-09-04 03:40:15,729 - Server.Service.fanqiang_ip_service - DEBUG - 随机ip_port 192.169.140.100:17365 无法翻墙，从新获取
2018-09-04 03:40:15,739 - Server.Service.fanqiang_ip_service - DEBUG - 开始测试50.63.13.254:35451
2018-09-04 03:40:25,757 - Server.Service.fanqiang_ip_service - DEBUG - 随机ip_port 50.63.13.254:35451 无法翻墙，从新获取
2018-09-04 03:40:25,768 - Server.Service.fanqiang_ip_service - DEBUG - 开始测试150.109.40.218:8090
2018-09-04 03:40:26,817 - Server.Service.fanqiang_ip_service - DEBUG - 随机ip_port 150.109.40.218:8090 无法翻墙，从新获取
2018-09-04 03:40:26,828 - Server.Service.fanqiang_ip_service - DEBUG - 开始测试12.226.243.150:65000
2018-09-04 03:40:36,846 - Server.Service.fanqiang_ip_service - DEBUG - 随机ip_port 12.226.243.150:65000 无法翻墙，从新获取
2018-09-04 03:40:36,856 - Server.Service.fanqiang_ip_service - DEBUG - 开始测试64.118.87.37:53344
2018-09-04 03:40:38,538 - Server.Service.fanqiang_ip_service - DEBUG - 随机ip_port 64.118.87.37:53344 无法翻墙，从新获取
2018-09-04 03:40:38,548 - Server.Service.fanqiang_ip_service - DEBUG - 开始测试192.169.188.105:47385
2018-09-04 03:40:48,567 - Server.Service.fanqiang_ip_service - DEBUG - 随机ip_port 192.169.188.105:47385 无法翻墙，从新获取
2018-09-04 03:40:48,577 - Server.Service.fanqiang_ip_service - DEBUG - 开始测试74.208.149.41:10080
2018-09-04 03:41:01,811 - Server.Service.fanqiang_ip_service - DEBUG - 随机ip_port 74.208.149.41:10080 无法翻墙，从新获取
2018-09-04 03:41:01,821 - Server.Service.fanqiang_ip_service - DEBUG - 开始测试47.148.113.244:15951
2018-09-04 03:41:03,626 - Server.Service.fanqiang_ip_service - DEBUG - 随机ip_port 47.148.113.244:15951 无法翻墙，从新获取
2018-09-04 03:41:03,636 - Server.Service.fanqiang_ip_service - DEBUG - 开始测试192.169.140.100:38827
2018-09-04 03:41:13,655 - Server.Service.fanqiang_ip_service - DEBUG - 随机ip_port 192.169.140.100:38827 无法翻墙，从新获取
2018-09-04 03:41:13,665 - Server.Service.fanqiang_ip_service - DEBUG - 开始测试95.110.207.71:26187
2018-09-04 03:41:15,447 - Server.Service.fanqiang_ip_service - DEBUG - 随机ip_port 95.110.207.71:26187 无法翻墙，从新获取
2018-09-04 03:41:15,459 - Server.Service.fanqiang_ip_service - DEBUG - 开始测试5.134.124.205:10080
2018-09-04 03:41:25,478 - Server.Service.fanqiang_ip_service - DEBUG - 随机ip_port 5.134.124.205:10080 无法翻墙，从新获取
2018-09-04 03:41:25,489 - Server.Service.fanqiang_ip_service - DEBUG - 开始测试192.169.140.100:58823
2018-09-04 03:41:35,509 - Server.Service.fanqiang_ip_service - DEBUG - 随机ip_port 192.169.140.100:58823 无法翻墙，从新获取
2018-09-04 03:41:35,519 - Server.Service.fanqiang_ip_service - DEBUG - 开始测试192.169.140.100:62935
2018-09-04 03:41:45,539 - Server.Service.fanqiang_ip_service - DEBUG - 随机ip_port 192.169.140.100:62935 无法翻墙，从新获取
2018-09-04 03:41:45,550 - Server.Service.fanqiang_ip_service - DEBUG - 开始测试72.143.74.250:10629
2018-09-04 03:41:47,355 - Server.Service.fanqiang_ip_service - DEBUG - 随机ip_port 72.143.74.250:10629 无法翻墙，从新获取
2018-09-04 03:41:47,367 - Server.Service.fanqiang_ip_service - DEBUG - 开始测试50.63.167.72:52701
2018-09-04 03:41:57,386 - Server.Service.fanqiang_ip_service - DEBUG - 随机ip_port 50.63.167.72:52701 无法翻墙，从新获取
2018-09-04 03:41:57,397 - Server.Service.fanqiang_ip_service - DEBUG - 开始测试178.32.222.125:9050
2018-09-04 03:42:07,417 - Server.Service.fanqiang_ip_service - DEBUG - 随机ip_port 178.32.222.125:9050 无法翻墙，从新获取
2018-09-04 03:42:07,428 - Server.Service.fanqiang_ip_service - DEBUG - 开始测试70.168.93.218:17026
2018-09-04 03:42:17,449 - Server.Service.fanqiang_ip_service - DEBUG - 随机ip_port 70.168.93.218:17026 无法翻墙，从新获取
2018-09-04 03:42:17,460 - Server.Service.fanqiang_ip_service - DEBUG - 开始测试132.148.129.183:54600
2018-09-04 03:42:27,481 - Server.Service.fanqiang_ip_service - DEBUG - 随机ip_port 132.148.129.183:54600 无法翻墙，从新获取
2018-09-04 03:42:27,493 - Server.Service.fanqiang_ip_service - DEBUG - 开始测试188.120.234.190:25299
2018-09-04 03:42:37,514 - Server.Service.fanqiang_ip_service - DEBUG - 随机ip_port 188.120.234.190:25299 无法翻墙，从新获取
2018-09-04 03:42:37,526 - Server.Service.fanqiang_ip_service - DEBUG - 开始测试95.110.194.245:45007
2018-09-04 03:42:39,297 - Server.Service.fanqiang_ip_service - DEBUG - 随机ip_port 95.110.194.245:45007 无法翻墙，从新获取
2018-09-04 03:42:39,309 - Server.Service.fanqiang_ip_service - DEBUG - 开始测试192.169.140.100:61993
2018-09-04 04:54:06,163 - Server.Service.fanqiang_ip_service - DEBUG - 开始测试192.169.140.100:61993
2018-09-04 06:25:34,813 - Server.Service.fanqiang_ip_service - DEBUG - 开始测试192.169.140.100:61993
2018-09-04 08:58:09,909 - Server.Service.fanqiang_ip_service - DEBUG - 开始测试192.169.140.100:61993
2018-09-04 09:28:44,540 - Server.Service.fanqiang_ip_service - DEBUG - 开始测试192.169.140.100:61993
2018-09-04 10:30:02,241 - Server.Service.fanqiang_ip_service - DEBUG - 开始测试192.169.140.100:61993
2018-09-04 10:30:12,259 - Server.Service.user_service - DEBUG - 代理 192.169.140.100:61993 已失效
2018-09-04 10:30:12,338 - Server.Service.fanqiang_ip_service - DEBUG - 开始测试192.169.202.104:62224
2018-09-04 10:30:29,474 - Server.Service.fanqiang_ip_service - DEBUG - 随机ip_port 192.169.202.104:62224 无法翻墙，从新获取
2018-09-04 10:30:29,484 - Server.Service.fanqiang_ip_service - DEBUG - 开始测试132.148.129.183:23194
2018-09-04 10:50:56,676 - Server.Service.fanqiang_ip_service - DEBUG - 开始测试132.148.129.183:23194
2018-09-04 10:51:07,044 - Server.Service.user_service - DEBUG - 代理 132.148.129.183:23194 已失效
2018-09-04 10:51:07,064 - Server.Service.fanqiang_ip_service - DEBUG - 开始测试192.169.199.36:24318
2018-09-04 11:41:38,479 - Server.Service.fanqiang_ip_service - DEBUG - 开始测试192.169.199.36:24318
2018-09-04 13:22:45,323 - Server.Service.fanqiang_ip_service - DEBUG - 开始测试192.169.199.36:24318
2018-09-04 13:43:13,668 - Server.Service.fanqiang_ip_service - DEBUG - 开始测试192.169.199.36:24318
2018-09-04 13:43:23,685 - Server.Service.user_service - DEBUG - 代理 192.169.199.36:24318 已失效
2018-09-04 13:43:24,013 - Server.Service.fanqiang_ip_service - DEBUG - 开始测试192.169.138.184:64876
2018-09-04 14:04:01,674 - Server.Service.fanqiang_ip_service - DEBUG - 开始测试192.169.138.184:64876
2018-09-04 14:04:11,849 - Server.Service.user_service - DEBUG - 代理 192.169.138.184:64876 已失效
2018-09-04 14:04:11,862 - Server.Service.fanqiang_ip_service - DEBUG - 开始测试125.224.61.126:56549
2018-09-04 14:04:12,965 - Server.Service.fanqiang_ip_service - DEBUG - 随机ip_port 125.224.61.126:56549 无法翻墙，从新获取
2018-09-04 14:04:12,976 - Server.Service.fanqiang_ip_service - DEBUG - 开始测试192.169.140.100:48647
2018-09-04 14:34:50,798 - Server.Service.fanqiang_ip_service - DEBUG - 开始测试192.169.140.100:48647
2018-09-04 14:55:21,336 - Server.Service.fanqiang_ip_service - DEBUG - 开始测试192.169.140.100:48647
2018-09-04 14:55:33,834 - Server.Service.user_service - DEBUG - 代理 192.169.140.100:48647 已失效
2018-09-04 14:55:33,871 - Server.Service.fanqiang_ip_service - DEBUG - 开始测试192.169.140.100:29460
2018-09-04 14:55:44,282 - Server.Service.fanqiang_ip_service - DEBUG - 随机ip_port 192.169.140.100:29460 无法翻墙，从新获取
2018-09-04 14:55:44,293 - Server.Service.fanqiang_ip_service - DEBUG - 开始测试46.105.57.149:7435
2018-09-04 14:55:45,582 - Server.Service.fanqiang_ip_service - DEBUG - 随机ip_port 46.105.57.149:7435 无法翻墙，从新获取
2018-09-04 14:55:45,602 - Server.Service.fanqiang_ip_service - DEBUG - 开始测试98.143.146.161:58785
2018-09-04 14:55:55,619 - Server.Service.fanqiang_ip_service - DEBUG - 随机ip_port 98.143.146.161:58785 无法翻墙，从新获取
2018-09-04 14:55:58,022 - Server.Service.fanqiang_ip_service - DEBUG - 开始测试188.120.239.196:12249
2018-09-04 14:55:59,811 - Server.Service.fanqiang_ip_service - DEBUG - 随机ip_port 188.120.239.196:12249 无法翻墙，从新获取
2018-09-04 14:55:59,822 - Server.Service.fanqiang_ip_service - DEBUG - 开始测试192.169.180.124:22428
2018-09-04 19:58:14,358 - Server.Service.fanqiang_ip_service - DEBUG - 开始测试192.169.180.124:22428
2018-09-04 20:08:37,535 - Server.Service.fanqiang_ip_service - DEBUG - 开始测试192.169.180.124:22428
2018-09-04 22:20:33,886 - Server.Service.fanqiang_ip_service - DEBUG - 开始测试192.169.180.124:22428
2018-09-04 22:20:45,659 - Server.Service.user_service - DEBUG - 代理 192.169.180.124:22428 已失效
2018-09-04 22:20:45,884 - Server.Service.fanqiang_ip_service - DEBUG - 开始测试192.169.218.61:63677
2018-09-05 20:18:04,312 - Server.Service.fanqiang_ip_service - DEBUG - 开始测试192.169.218.61:63677
2018-09-05 21:28:45,507 - Server.Service.fanqiang_ip_service - DEBUG - 开始测试192.169.218.61:63677
2018-09-05 21:28:55,525 - Server.Service.user_service - DEBUG - 代理 192.169.218.61:63677 已失效
2018-09-05 21:28:56,040 - Server.Service.fanqiang_ip_service - DEBUG - 开始测试185.44.68.182:1080
2018-09-05 21:39:21,784 - Server.Service.fanqiang_ip_service - DEBUG - 开始测试185.44.68.182:1080
2018-09-05 21:39:31,801 - Server.Service.user_service - DEBUG - 代理 185.44.68.182:1080 已失效
2018-09-05 21:39:31,867 - Server.Service.fanqiang_ip_service - DEBUG - 开始测试46.4.88.215:9050
2018-09-05 21:49:48,410 - Server.Service.fanqiang_ip_service - DEBUG - 开始测试46.4.88.215:9050
2018-09-05 22:00:39,518 - Server.Service.fanqiang_ip_service - DEBUG - 开始测试46.4.88.215:9050
2018-09-05 22:00:49,535 - Server.Service.user_service - DEBUG - 代理 46.4.88.215:9050 已失效
2018-09-05 22:00:49,578 - Server.Service.fanqiang_ip_service - DEBUG - 开始测试98.143.146.161:58785
2018-09-05 22:00:59,595 - Server.Service.fanqiang_ip_service - DEBUG - 随机ip_port 98.143.146.161:58785 无法翻墙，从新获取
2018-09-05 22:00:59,605 - Server.Service.fanqiang_ip_service - DEBUG - 开始测试132.148.129.183:13477
2018-09-05 22:52:22,165 - Server.Service.fanqiang_ip_service - DEBUG - 开始测试132.148.129.183:13477
2018-09-05 22:52:36,690 - Server.Service.user_service - DEBUG - 代理 132.148.129.183:13477 已失效
2018-09-05 22:52:36,714 - Server.Service.fanqiang_ip_service - DEBUG - 开始测试45.55.169.78:9467
2018-09-05 23:53:54,615 - Server.Service.fanqiang_ip_service - DEBUG - 开始测试45.55.169.78:9467
2018-09-05 23:54:14,310 - Server.Service.user_service - DEBUG - 代理 45.55.169.78:9467 已失效
2018-09-05 23:54:14,342 - Server.Service.fanqiang_ip_service - DEBUG - 开始测试67.197.147.243:53302
2018-09-05 23:54:16,052 - Server.Service.fanqiang_ip_service - DEBUG - 随机ip_port 67.197.147.243:53302 无法翻墙，从新获取
2018-09-05 23:54:16,062 - Server.Service.fanqiang_ip_service - DEBUG - 开始测试166.62.39.74:10080
2018-09-05 23:54:26,277 - Server.Service.fanqiang_ip_service - DEBUG - 随机ip_port 166.62.39.74:10080 无法翻墙，从新获取
2018-09-05 23:54:26,288 - Server.Service.fanqiang_ip_service - DEBUG - 开始测试192.169.199.36:24318
2018-09-06 00:25:11,515 - Server.Service.fanqiang_ip_service - DEBUG - 开始测试192.169.199.36:24318
2018-09-06 00:35:32,631 - Server.Service.fanqiang_ip_service - DEBUG - 开始测试192.169.199.36:24318
2018-09-06 00:46:06,915 - Server.Service.fanqiang_ip_service - DEBUG - 开始测试192.169.199.36:24318
2018-09-06 00:46:16,933 - Server.Service.user_service - DEBUG - 代理 192.169.199.36:24318 已失效
2018-09-06 00:46:16,979 - Server.Service.fanqiang_ip_service - DEBUG - 开始测试192.169.182.200:2502
2018-09-06 06:49:17,457 - Server.Service.fanqiang_ip_service - DEBUG - 开始测试192.169.182.200:2502
2018-09-06 06:49:27,522 - Server.Service.user_service - DEBUG - 代理 192.169.182.200:2502 已失效
2018-09-06 06:49:27,719 - Server.Service.fanqiang_ip_service - DEBUG - 开始测试188.120.234.190:25299
2018-09-06 09:10:30,674 - Server.Service.fanqiang_ip_service - DEBUG - 开始测试188.120.234.190:25299
2018-09-06 09:10:40,735 - Server.Service.user_service - DEBUG - 代理 188.120.234.190:25299 已失效
2018-09-06 09:10:40,985 - Server.Service.fanqiang_ip_service - DEBUG - 开始测试64.118.87.37:53344
2018-09-06 09:10:42,688 - Server.Service.fanqiang_ip_service - DEBUG - 随机ip_port 64.118.87.37:53344 无法翻墙，从新获取
2018-09-06 09:10:42,700 - Server.Service.fanqiang_ip_service - DEBUG - 开始测试192.169.188.105:26973
2018-09-06 13:42:57,298 - Server.Service.fanqiang_ip_service - DEBUG - 开始测试192.169.188.105:26973
2018-09-06 22:27:16,448 - Server.Service.fanqiang_ip_service - DEBUG - 开始测试192.169.188.105:26973
2018-09-06 23:08:21,584 - Server.Service.fanqiang_ip_service - DEBUG - 开始测试192.169.188.105:26973
2018-09-06 23:18:53,770 - Server.Service.fanqiang_ip_service - DEBUG - 开始测试192.169.188.105:26973
2018-09-06 23:19:04,092 - Server.Service.user_service - DEBUG - 代理 192.169.188.105:26973 已失效
2018-09-06 23:19:04,811 - Server.Service.fanqiang_ip_service - DEBUG - 开始测试206.223.248.173:42852
2018-09-06 23:19:06,507 - Server.Service.fanqiang_ip_service - DEBUG - 随机ip_port 206.223.248.173:42852 无法翻墙，从新获取
2018-09-06 23:19:06,512 - Server.Service.fanqiang_ip_service - DEBUG - 开始测试50.63.167.72:27051
2018-09-06 23:19:17,049 - Server.Service.fanqiang_ip_service - DEBUG - 随机ip_port 50.63.167.72:27051 无法翻墙，从新获取
2018-09-06 23:19:17,055 - Server.Service.fanqiang_ip_service - DEBUG - 开始测试132.148.130.46:12508
2018-09-06 23:19:18,821 - Server.Service.fanqiang_ip_service - DEBUG - 随机ip_port 132.148.130.46:12508 无法翻墙，从新获取
2018-09-06 23:19:18,827 - Server.Service.fanqiang_ip_service - DEBUG - 开始测试50.62.35.225:16040
2018-09-07 00:09:57,189 - Server.Service.fanqiang_ip_service - DEBUG - 开始测试50.62.35.225:16040
2018-09-07 00:10:07,389 - Server.Service.user_service - DEBUG - 代理 50.62.35.225:16040 已失效
2018-09-07 00:10:07,423 - Server.Service.fanqiang_ip_service - DEBUG - 开始测试132.148.129.183:22834
2018-09-07 00:41:06,158 - Server.Service.fanqiang_ip_service - DEBUG - 开始测试132.148.129.183:22834
2018-09-07 09:45:39,578 - Server.Service.fanqiang_ip_service - DEBUG - 开始测试132.148.129.183:22834
2018-09-07 11:26:18,807 - __main__ - ERROR - 631975da-b24d-11e8-a9d8-005056c00008 - Traceback (most recent call last):
  File "F:/scribe2/Server/server.py", line 59, in get_pac
    pac_type = request.args['type']
  File "F:\scribe2\venv\lib\site-packages\werkzeug\datastructures.py", line 431, in __getitem__
    raise exceptions.BadRequestKeyError(key)
werkzeug.exceptions.HTTPException.wrap.<locals>.newcls: 400 Bad Request: The browser (or proxy) sent a request that this server could not understand.

2018-09-07 11:40:51,704 - __main__ - ERROR - 631975da-b24d-11e8-a9d8-005056c00008 - Traceback (most recent call last):
  File "F:/scribe2/Server/server.py", line 59, in get_pac
    pac_type = request.args['type']
  File "F:\scribe2\venv\lib\site-packages\werkzeug\datastructures.py", line 431, in __getitem__
    raise exceptions.BadRequestKeyError(key)
werkzeug.exceptions.HTTPException.wrap.<locals>.newcls: 400 Bad Request: The browser (or proxy) sent a request that this server could not understand.

2018-09-07 11:42:39,702 - __main__ - ERROR - 631975da-b24d-11e8-a9d8-005056c00008 - Traceback (most recent call last):
  File "F:/scribe2/Server/server.py", line 63, in get_pac
    resp = make_response(send_file('file/pac/http_surge.pac'))
  File "F:\scribe2\venv\lib\site-packages\flask\helpers.py", line 588, in send_file
    file = open(filename, 'rb')
FileNotFoundError: [Errno 2] No such file or directory: 'F:\\scribe2\\Server\\file/pac/http_surge.pac'

2018-09-07 11:43:17,349 - __main__ - ERROR - 631975da-b24d-11e8-a9d8-005056c00008 - Traceback (most recent call last):
  File "F:/scribe2/Server/server.py", line 63, in get_pac
    resp = make_response(send_file('/file/pac/http_surge.pac'))
  File "F:\scribe2\venv\lib\site-packages\flask\helpers.py", line 588, in send_file
    file = open(filename, 'rb')
FileNotFoundError: [Errno 2] No such file or directory: '/file/pac/http_surge.pac'

2018-09-07 12:01:30,951 - __main__ - ERROR - 631975da-b24d-11e8-a9d8-005056c00008 - Traceback (most recent call last):
  File "F:/scribe2/Server/server.py", line 70, in get_pac
    with open('../file/pac/http_surge.pac','r') as fr:
FileNotFoundError: [Errno 2] No such file or directory: '../file/pac/http_surge.pac'

2018-09-07 14:36:18,229 - __main__ - ERROR - 631975da-b24d-11e8-a9d8-005056c00008 - Traceback (most recent call last):
  File "F:/scribe2/Server/server.py", line 61, in get_pac
    filename, pac = fanqiang_ip_service.get_dynamic_pac(pac_type,request.args['account'])
  File "F:\scribe2\Server\Service\fanqiang_ip_service.py", line 170, in get_dynamic_pac
    raise Exception('获取动态pac失败，{}获取了空值'.format('filename' if not filename else 'pac'))
Exception: 获取动态pac失败，filename获取了空值

2018-09-07 14:37:32,853 - __main__ - ERROR - 631975da-b24d-11e8-a9d8-005056c00008 - Traceback (most recent call last):
  File "F:/scribe2/Server/server.py", line 61, in get_pac
    filename, pac = fanqiang_ip_service.get_dynamic_pac(pac_type,request.args['account'])
  File "F:\scribe2\Server\Service\fanqiang_ip_service.py", line 153, in get_dynamic_pac
    proxy_replace_text, group_replace_text = generate_replace_text(ip_port_dict_list)
  File "F:\scribe2\Server\Service\fanqiang_ip_service.py", line 130, in generate_replace_text
    ip['ip_with_port'].replace(':', ',')) for index, ip in enumerate(ip_fanqiang_list)]
  File "F:\scribe2\Server\Service\fanqiang_ip_service.py", line 130, in <listcomp>
    ip['ip_with_port'].replace(':', ',')) for index, ip in enumerate(ip_fanqiang_list)]
  File "F:\scribe2\venv\lib\site-packages\pymongo\cursor.py", line 614, in __getitem__
    "instances" % index)
TypeError: index 'proxy_type' cannot be applied to Cursor instances

2018-09-07 14:40:44,329 - __main__ - ERROR - 631975da-b24d-11e8-a9d8-005056c00008 - Traceback (most recent call last):
  File "F:/scribe2/Server/server.py", line 61, in get_pac
    filename, pac = fanqiang_ip_service.get_dynamic_pac(pac_type,request.args['account'])
  File "F:\scribe2\Server\Service\fanqiang_ip_service.py", line 155, in get_dynamic_pac
    old_text)[0], proxy_replace_text)
IndexError: list index out of range

2018-09-07 14:41:23,530 - __main__ - ERROR - 631975da-b24d-11e8-a9d8-005056c00008 - Traceback (most recent call last):
  File "F:/scribe2/Server/server.py", line 61, in get_pac
    filename, pac = fanqiang_ip_service.get_dynamic_pac(pac_type,request.args['account'])
  File "F:\scribe2\Server\Service\fanqiang_ip_service.py", line 155, in get_dynamic_pac
    old_text)[0], proxy_replace_text)
IndexError: list index out of range

2018-09-19 17:59:59,739 - Server.Service.fanqiang_ip_service - DEBUG - 开始测试132.148.129.183:22834
2018-09-19 18:00:01,354 - Server.Service.user_service - DEBUG - 代理 132.148.129.183:22834 已失效
2018-09-19 18:00:01,497 - Server.Service.fanqiang_ip_service - DEBUG - 开始测试119.28.222.222:2282
2018-09-19 18:00:11,703 - Server.Service.fanqiang_ip_service - DEBUG - 随机ip_port 119.28.222.222:2282 无法翻墙，从新获取
2018-09-19 18:00:11,727 - Server.Service.fanqiang_ip_service - DEBUG - 开始测试151.237.173.212:39880
2018-09-19 18:00:30,923 - Server.Service.fanqiang_ip_service - DEBUG - 随机ip_port 151.237.173.212:39880 无法翻墙，从新获取
2018-09-19 18:00:30,948 - Server.Service.fanqiang_ip_service - DEBUG - 开始测试173.230.155.122:37915
2018-09-19 18:00:40,966 - Server.Service.fanqiang_ip_service - DEBUG - 随机ip_port 173.230.155.122:37915 无法翻墙，从新获取
2018-09-19 18:00:40,990 - Server.Service.fanqiang_ip_service - DEBUG - 开始测试192.171.248.184:42599
2018-09-19 18:00:51,234 - Server.Service.fanqiang_ip_service - DEBUG - 随机ip_port 192.171.248.184:42599 无法翻墙，从新获取
2018-09-19 18:00:51,261 - Server.Service.fanqiang_ip_service - DEBUG - 开始测试206.223.248.28:42599
2018-09-19 18:01:01,525 - Server.Service.fanqiang_ip_service - DEBUG - 随机ip_port 206.223.248.28:42599 无法翻墙，从新获取
2018-09-19 18:01:01,552 - Server.Service.fanqiang_ip_service - DEBUG - 开始测试173.214.155.218:47104
2018-09-19 18:01:03,293 - Server.Service.fanqiang_ip_service - DEBUG - 随机ip_port 173.214.155.218:47104 无法翻墙，从新获取
2018-09-19 18:01:03,357 - Server.Service.fanqiang_ip_service - DEBUG - 开始测试64.118.88.53:53344
2018-09-19 18:01:13,381 - Server.Service.fanqiang_ip_service - DEBUG - 随机ip_port 64.118.88.53:53344 无法翻墙，从新获取
2018-09-19 18:01:13,410 - Server.Service.fanqiang_ip_service - DEBUG - 开始测试89.108.107.22:16455
2018-09-19 18:01:15,146 - Server.Service.fanqiang_ip_service - DEBUG - 随机ip_port 89.108.107.22:16455 无法翻墙，从新获取
2018-09-19 18:01:15,175 - Server.Service.fanqiang_ip_service - DEBUG - 开始测试51.254.78.218:59390
2018-09-19 18:01:25,198 - Server.Service.fanqiang_ip_service - DEBUG - 随机ip_port 51.254.78.218:59390 无法翻墙，从新获取
2018-09-19 18:01:25,225 - Server.Service.fanqiang_ip_service - DEBUG - 开始测试66.63.178.137:19232
2018-09-19 18:01:35,247 - Server.Service.fanqiang_ip_service - DEBUG - 随机ip_port 66.63.178.137:19232 无法翻墙，从新获取
2018-09-19 18:01:35,277 - Server.Service.fanqiang_ip_service - DEBUG - 开始测试50.63.153.173:34203
2018-09-19 18:01:36,831 - Server.Service.fanqiang_ip_service - DEBUG - 随机ip_port 50.63.153.173:34203 无法翻墙，从新获取
2018-09-19 18:01:36,861 - Server.Service.fanqiang_ip_service - DEBUG - 开始测试173.219.43.147:55808
2018-09-19 18:01:38,652 - Server.Service.fanqiang_ip_service - DEBUG - 随机ip_port 173.219.43.147:55808 无法翻墙，从新获取
2018-09-19 18:01:38,681 - Server.Service.fanqiang_ip_service - DEBUG - 开始测试199.38.28.44:26583
2018-09-19 18:01:40,469 - Server.Service.fanqiang_ip_service - DEBUG - 随机ip_port 199.38.28.44:26583 无法翻墙，从新获取
2018-09-19 18:01:40,501 - Server.Service.fanqiang_ip_service - DEBUG - 开始测试149.56.23.5:64580
2018-09-19 18:01:42,324 - Server.Service.fanqiang_ip_service - DEBUG - 随机ip_port 149.56.23.5:64580 无法翻墙，从新获取
2018-09-19 18:01:42,352 - Server.Service.fanqiang_ip_service - DEBUG - 开始测试205.186.160.245:10080
2018-09-19 18:01:55,606 - Server.Service.fanqiang_ip_service - DEBUG - 随机ip_port 205.186.160.245:10080 无法翻墙，从新获取
2018-09-19 18:01:55,640 - Server.Service.fanqiang_ip_service - DEBUG - 开始测试192.169.250.198:11093
2018-09-19 18:01:57,233 - Server.Service.fanqiang_ip_service - DEBUG - 随机ip_port 192.169.250.198:11093 无法翻墙，从新获取
2018-09-19 18:01:57,260 - Server.Service.fanqiang_ip_service - DEBUG - 开始测试107.182.105.251:39880
2018-09-19 18:01:58,990 - Server.Service.fanqiang_ip_service - DEBUG - 随机ip_port 107.182.105.251:39880 无法翻墙，从新获取
2018-09-19 18:01:59,020 - Server.Service.fanqiang_ip_service - DEBUG - 开始测试64.118.88.54:12650
2018-09-19 18:02:09,043 - Server.Service.fanqiang_ip_service - DEBUG - 随机ip_port 64.118.88.54:12650 无法翻墙，从新获取
2018-09-19 18:02:09,100 - Server.Service.fanqiang_ip_service - DEBUG - 开始测试47.148.113.244:15696
2018-09-19 18:02:10,671 - Server.Service.fanqiang_ip_service - DEBUG - 随机ip_port 47.148.113.244:15696 无法翻墙，从新获取
2018-09-19 18:02:10,704 - Server.Service.fanqiang_ip_service - DEBUG - 开始测试107.170.7.132:47810
2018-09-19 18:22:37,385 - Server.Service.fanqiang_ip_service - DEBUG - 开始测试107.170.7.132:47810
2018-09-19 18:22:48,672 - Server.Service.user_service - DEBUG - 代理 107.170.7.132:47810 已失效
2018-09-19 18:22:48,715 - Server.Service.fanqiang_ip_service - DEBUG - 开始测试192.169.136.151:40809
2018-09-19 18:22:58,733 - Server.Service.fanqiang_ip_service - DEBUG - 随机ip_port 192.169.136.151:40809 无法翻墙，从新获取
2018-09-19 18:22:58,757 - Server.Service.fanqiang_ip_service - DEBUG - 开始测试37.187.44.39:10080
2018-09-19 18:23:00,583 - Server.Service.fanqiang_ip_service - DEBUG - 随机ip_port 37.187.44.39:10080 无法翻墙，从新获取
2018-09-19 18:23:00,606 - Server.Service.fanqiang_ip_service - DEBUG - 开始测试132.148.130.46:12508
2018-09-19 18:23:02,203 - Server.Service.fanqiang_ip_service - DEBUG - 随机ip_port 132.148.130.46:12508 无法翻墙，从新获取
2018-09-19 18:23:02,228 - Server.Service.fanqiang_ip_service - DEBUG - 开始测试50.63.132.239:31135
2018-09-19 18:23:03,765 - Server.Service.fanqiang_ip_service - DEBUG - 随机ip_port 50.63.132.239:31135 无法翻墙，从新获取
2018-09-19 18:23:03,789 - Server.Service.fanqiang_ip_service - DEBUG - 开始测试64.118.87.12:12650
2018-09-19 18:23:13,829 - Server.Service.fanqiang_ip_service - DEBUG - 随机ip_port 64.118.87.12:12650 无法翻墙，从新获取
2018-09-19 18:23:13,854 - Server.Service.fanqiang_ip_service - DEBUG - 开始测试132.148.129.183:10150
2018-09-19 18:23:15,409 - Server.Service.fanqiang_ip_service - DEBUG - 随机ip_port 132.148.129.183:10150 无法翻墙，从新获取
2018-09-19 18:23:15,434 - Server.Service.fanqiang_ip_service - DEBUG - 开始测试46.105.57.149:23299
2018-09-19 18:23:16,144 - Server.Service.fanqiang_ip_service - DEBUG - 随机ip_port 46.105.57.149:23299 无法翻墙，从新获取
2018-09-19 18:23:16,170 - Server.Service.fanqiang_ip_service - DEBUG - 开始测试192.169.224.196:32449
2018-09-19 18:23:29,928 - Server.Service.fanqiang_ip_service - DEBUG - 随机ip_port 192.169.224.196:32449 无法翻墙，从新获取
2018-09-19 18:23:29,954 - Server.Service.fanqiang_ip_service - DEBUG - 开始测试50.63.167.72:37140
2018-09-19 18:23:31,576 - Server.Service.fanqiang_ip_service - DEBUG - 随机ip_port 50.63.167.72:37140 无法翻墙，从新获取
2018-09-19 18:23:31,602 - Server.Service.fanqiang_ip_service - DEBUG - 开始测试176.118.131.136:6667
2018-09-19 18:44:00,655 - Server.Service.fanqiang_ip_service - DEBUG - 开始测试176.118.131.136:6667
2018-09-19 19:04:21,146 - Server.Service.fanqiang_ip_service - DEBUG - 开始测试176.118.131.136:6667
2018-09-19 19:35:07,686 - Server.Service.fanqiang_ip_service - DEBUG - 开始测试176.118.131.136:6667
2018-09-19 19:35:17,703 - Server.Service.user_service - DEBUG - 代理 176.118.131.136:6667 已失效
2018-09-19 19:35:17,754 - Server.Service.fanqiang_ip_service - DEBUG - 开始测试222.165.225.245:18959
2018-09-19 19:56:31,807 - Server.Service.fanqiang_ip_service - DEBUG - 开始测试222.165.225.245:18959
2018-09-19 19:57:11,080 - Server.Service.user_service - DEBUG - 代理 222.165.225.245:18959 已失效
2018-09-19 19:57:11,111 - Server.Service.fanqiang_ip_service - DEBUG - 开始测试18.191.110.209:54321
2018-09-19 19:57:21,351 - Server.Service.fanqiang_ip_service - DEBUG - 随机ip_port 18.191.110.209:54321 无法翻墙，从新获取
2018-09-19 19:57:21,375 - Server.Service.fanqiang_ip_service - DEBUG - 开始测试103.250.158.21:6667
2018-09-19 19:57:31,404 - Server.Service.fanqiang_ip_service - DEBUG - 随机ip_port 103.250.158.21:6667 无法翻墙，从新获取
2018-09-19 19:57:31,429 - Server.Service.fanqiang_ip_service - DEBUG - 开始测试132.148.129.183:4042
2018-09-19 19:57:32,939 - Server.Service.fanqiang_ip_service - DEBUG - 随机ip_port 132.148.129.183:4042 无法翻墙，从新获取
2018-09-19 19:57:32,963 - Server.Service.fanqiang_ip_service - DEBUG - 开始测试103.216.82.213:6667
2018-09-19 19:57:44,543 - Server.Service.fanqiang_ip_service - DEBUG - 随机ip_port 103.216.82.213:6667 无法翻墙，从新获取
2018-09-19 19:57:44,567 - Server.Service.fanqiang_ip_service - DEBUG - 开始测试74.123.23.40:11264
2018-09-19 19:57:46,340 - Server.Service.fanqiang_ip_service - DEBUG - 随机ip_port 74.123.23.40:11264 无法翻墙，从新获取
2018-09-19 19:57:46,365 - Server.Service.fanqiang_ip_service - DEBUG - 开始测试192.169.250.198:30336
2018-09-19 20:38:10,756 - Server.Service.fanqiang_ip_service - DEBUG - 开始测试192.169.250.198:30336
2018-09-19 20:38:20,773 - Server.Service.user_service - DEBUG - 代理 192.169.250.198:30336 已失效
2018-09-19 20:38:20,816 - Server.Service.fanqiang_ip_service - DEBUG - 开始测试173.254.242.5:4417
2018-09-19 20:38:22,605 - Server.Service.fanqiang_ip_service - DEBUG - 随机ip_port 173.254.242.5:4417 无法翻墙，从新获取
2018-09-19 20:38:22,629 - Server.Service.fanqiang_ip_service - DEBUG - 开始测试162.243.89.67:30575
2018-09-19 20:38:32,646 - Server.Service.fanqiang_ip_service - DEBUG - 随机ip_port 162.243.89.67:30575 无法翻墙，从新获取
2018-09-19 20:38:32,669 - Server.Service.fanqiang_ip_service - DEBUG - 开始测试192.169.244.29:32449
2018-09-19 21:09:19,327 - Server.Service.fanqiang_ip_service - DEBUG - 开始测试192.169.244.29:32449
2018-09-19 21:09:44,043 - Server.Service.user_service - DEBUG - 代理 192.169.244.29:32449 已失效
2018-09-19 21:09:44,078 - Server.Service.fanqiang_ip_service - DEBUG - 开始测试103.216.82.186:6667
2018-09-19 21:09:54,108 - Server.Service.fanqiang_ip_service - DEBUG - 随机ip_port 103.216.82.186:6667 无法翻墙，从新获取
2018-09-19 21:09:54,132 - Server.Service.fanqiang_ip_service - DEBUG - 开始测试192.169.140.100:62734
2018-09-19 21:09:58,004 - Server.Service.fanqiang_ip_service - DEBUG - 随机ip_port 192.169.140.100:62734 无法翻墙，从新获取
2018-09-19 21:09:58,028 - Server.Service.fanqiang_ip_service - DEBUG - 开始测试192.169.140.100:21747
2018-09-19 21:10:17,589 - Server.Service.fanqiang_ip_service - DEBUG - 随机ip_port 192.169.140.100:21747 无法翻墙，从新获取
2018-09-19 21:10:17,614 - Server.Service.fanqiang_ip_service - DEBUG - 开始测试206.223.248.143:42599
2018-09-19 21:10:23,976 - Server.Service.fanqiang_ip_service - DEBUG - 随机ip_port 206.223.248.143:42599 无法翻墙，从新获取
2018-09-19 21:10:24,001 - Server.Service.fanqiang_ip_service - DEBUG - 开始测试192.169.140.100:53052
2018-09-19 21:10:25,538 - Server.Service.fanqiang_ip_service - DEBUG - 随机ip_port 192.169.140.100:53052 无法翻墙，从新获取
2018-09-19 21:10:25,563 - Server.Service.fanqiang_ip_service - DEBUG - 开始测试18.191.110.209:54321
2018-09-19 21:10:35,807 - Server.Service.fanqiang_ip_service - DEBUG - 随机ip_port 18.191.110.209:54321 无法翻墙，从新获取
2018-09-19 21:10:35,833 - Server.Service.fanqiang_ip_service - DEBUG - 开始测试185.165.173.190:39880
2018-09-19 21:10:45,936 - Server.Service.fanqiang_ip_service - DEBUG - 随机ip_port 185.165.173.190:39880 无法翻墙，从新获取
2018-09-19 21:10:45,960 - Server.Service.fanqiang_ip_service - DEBUG - 开始测试50.63.153.173:46109
2018-09-19 22:22:01,101 - Server.Service.fanqiang_ip_service - DEBUG - 开始测试50.63.153.173:46109
2018-09-19 22:42:43,073 - Server.Service.fanqiang_ip_service - DEBUG - 开始测试50.63.153.173:46109
2018-09-19 22:43:18,497 - Server.Service.user_service - DEBUG - 代理 50.63.153.173:46109 已失效
2018-09-19 22:43:18,533 - Server.Service.fanqiang_ip_service - DEBUG - 开始测试192.169.244.29:43172
2018-09-19 22:43:34,543 - Server.Service.fanqiang_ip_service - DEBUG - 随机ip_port 192.169.244.29:43172 无法翻墙，从新获取
2018-09-19 22:43:34,568 - Server.Service.fanqiang_ip_service - DEBUG - 开始测试64.118.87.16:53344
2018-09-19 22:43:44,585 - Server.Service.fanqiang_ip_service - DEBUG - 随机ip_port 64.118.87.16:53344 无法翻墙，从新获取
2018-09-19 22:43:44,609 - Server.Service.fanqiang_ip_service - DEBUG - 开始测试95.143.128.178:39880
2018-09-19 22:43:46,571 - Server.Service.fanqiang_ip_service - DEBUG - 随机ip_port 95.143.128.178:39880 无法翻墙，从新获取
2018-09-19 22:43:46,595 - Server.Service.fanqiang_ip_service - DEBUG - 开始测试103.216.82.186:6667
2018-09-19 22:54:12,406 - Server.Service.fanqiang_ip_service - DEBUG - 开始测试103.216.82.186:6667
2018-09-19 23:04:32,801 - Server.Service.fanqiang_ip_service - DEBUG - 开始测试103.216.82.186:6667
2018-09-19 23:14:51,341 - Server.Service.fanqiang_ip_service - DEBUG - 开始测试103.216.82.186:6667
2018-09-19 23:15:01,718 - Server.Service.user_service - DEBUG - 代理 103.216.82.186:6667 已失效
2018-09-19 23:15:01,752 - Server.Service.fanqiang_ip_service - DEBUG - 开始测试192.169.244.29:43172
2018-09-19 23:15:13,474 - Server.Service.fanqiang_ip_service - DEBUG - 随机ip_port 192.169.244.29:43172 无法翻墙，从新获取
2018-09-19 23:15:13,497 - Server.Service.fanqiang_ip_service - DEBUG - 开始测试50.63.3.62:23085
2018-09-20 00:06:38,440 - Server.Service.fanqiang_ip_service - DEBUG - 开始测试50.63.3.62:23085
2018-09-20 00:17:15,975 - Server.Service.fanqiang_ip_service - DEBUG - 开始测试50.63.3.62:23085
2018-09-20 00:17:25,992 - Server.Service.user_service - DEBUG - 代理 50.63.3.62:23085 已失效
2018-09-20 00:17:26,039 - Server.Service.fanqiang_ip_service - DEBUG - 开始测试192.169.140.100:13851
2018-09-20 00:17:35,230 - Server.Service.fanqiang_ip_service - DEBUG - 随机ip_port 192.169.140.100:13851 无法翻墙，从新获取
2018-09-20 00:17:35,253 - Server.Service.fanqiang_ip_service - DEBUG - 开始测试24.143.237.186:31232
2018-09-20 00:17:36,782 - Server.Service.fanqiang_ip_service - DEBUG - 随机ip_port 24.143.237.186:31232 无法翻墙，从新获取
2018-09-20 00:17:36,805 - Server.Service.fanqiang_ip_service - DEBUG - 开始测试96.44.133.105:36577
2018-09-20 00:17:46,844 - Server.Service.fanqiang_ip_service - DEBUG - 随机ip_port 96.44.133.105:36577 无法翻墙，从新获取
2018-09-20 00:17:46,870 - Server.Service.fanqiang_ip_service - DEBUG - 开始测试138.68.143.47:44893
2018-09-20 00:17:49,105 - Server.Service.fanqiang_ip_service - DEBUG - 随机ip_port 138.68.143.47:44893 无法翻墙，从新获取
2018-09-20 00:17:49,130 - Server.Service.fanqiang_ip_service - DEBUG - 开始测试206.223.248.223:42599
2018-09-20 00:17:50,388 - Server.Service.fanqiang_ip_service - DEBUG - 随机ip_port 206.223.248.223:42599 无法翻墙，从新获取
2018-09-20 00:17:50,413 - Server.Service.fanqiang_ip_service - DEBUG - 开始测试34.207.196.193:9050
2018-09-20 00:18:01,025 - Server.Service.fanqiang_ip_service - DEBUG - 随机ip_port 34.207.196.193:9050 无法翻墙，从新获取
2018-09-20 00:18:01,050 - Server.Service.fanqiang_ip_service - DEBUG - 开始测试88.255.185.216:9050
2018-09-20 00:18:26,567 - Server.Service.fanqiang_ip_service - DEBUG - 随机ip_port 88.255.185.216:9050 无法翻墙，从新获取
2018-09-20 00:18:26,592 - Server.Service.fanqiang_ip_service - DEBUG - 开始测试190.151.87.42:39880
2018-09-20 00:18:28,920 - Server.Service.fanqiang_ip_service - DEBUG - 随机ip_port 190.151.87.42:39880 无法翻墙，从新获取
2018-09-20 00:18:28,947 - Server.Service.fanqiang_ip_service - DEBUG - 开始测试50.63.167.72:11183
2018-09-20 00:18:30,477 - Server.Service.fanqiang_ip_service - DEBUG - 随机ip_port 50.63.167.72:11183 无法翻墙，从新获取
2018-09-20 00:18:30,503 - Server.Service.fanqiang_ip_service - DEBUG - 开始测试46.4.88.203:9050
2018-09-20 00:18:40,521 - Server.Service.fanqiang_ip_service - DEBUG - 随机ip_port 46.4.88.203:9050 无法翻墙，从新获取
2018-09-20 00:18:40,548 - Server.Service.fanqiang_ip_service - DEBUG - 开始测试192.169.140.100:48647
2018-09-20 01:30:39,034 - Server.Service.fanqiang_ip_service - DEBUG - 开始测试192.169.140.100:48647
2018-09-20 01:41:00,684 - Server.Service.fanqiang_ip_service - DEBUG - 开始测试192.169.140.100:48647
2018-09-20 01:51:30,194 - Server.Service.fanqiang_ip_service - DEBUG - 开始测试192.169.140.100:48647
2018-09-20 06:55:07,446 - Server.Service.fanqiang_ip_service - DEBUG - 开始测试192.169.140.100:48647
2018-09-20 06:55:26,822 - Server.Service.user_service - DEBUG - 代理 192.169.140.100:48647 已失效
2018-09-20 06:55:26,892 - Server.Service.fanqiang_ip_service - DEBUG - 开始测试50.63.167.72:36015
2018-09-20 06:55:28,479 - Server.Service.fanqiang_ip_service - DEBUG - 随机ip_port 50.63.167.72:36015 无法翻墙，从新获取
2018-09-20 06:55:28,550 - Server.Service.fanqiang_ip_service - DEBUG - 开始测试173.219.43.147:55808
2018-09-20 06:55:30,377 - Server.Service.fanqiang_ip_service - DEBUG - 随机ip_port 173.219.43.147:55808 无法翻墙，从新获取
2018-09-20 06:55:30,402 - Server.Service.fanqiang_ip_service - DEBUG - 开始测试178.151.75.2:39880
2018-09-20 06:55:40,437 - Server.Service.fanqiang_ip_service - DEBUG - 随机ip_port 178.151.75.2:39880 无法翻墙，从新获取
2018-09-20 06:55:40,461 - Server.Service.fanqiang_ip_service - DEBUG - 开始测试75.149.165.245:61024
2018-09-20 06:55:42,020 - Server.Service.fanqiang_ip_service - DEBUG - 随机ip_port 75.149.165.245:61024 无法翻墙，从新获取
2018-09-20 06:55:42,046 - Server.Service.fanqiang_ip_service - DEBUG - 开始测试192.171.248.234:42599
2018-09-20 06:55:47,099 - Server.Service.fanqiang_ip_service - DEBUG - 随机ip_port 192.171.248.234:42599 无法翻墙，从新获取
2018-09-20 06:55:47,123 - Server.Service.fanqiang_ip_service - DEBUG - 开始测试61.170.151.217:1080
2018-09-20 06:55:57,151 - Server.Service.fanqiang_ip_service - DEBUG - 随机ip_port 61.170.151.217:1080 无法翻墙，从新获取
2018-09-20 06:55:57,175 - Server.Service.fanqiang_ip_service - DEBUG - 开始测试192.169.142.205:26456
2018-09-20 06:56:08,934 - Server.Service.fanqiang_ip_service - DEBUG - 随机ip_port 192.169.142.205:26456 无法翻墙，从新获取
2018-09-20 06:56:08,964 - Server.Service.fanqiang_ip_service - DEBUG - 开始测试76.72.236.30:51200
2018-09-20 06:56:10,728 - Server.Service.fanqiang_ip_service - DEBUG - 随机ip_port 76.72.236.30:51200 无法翻墙，从新获取
2018-09-20 06:56:10,753 - Server.Service.fanqiang_ip_service - DEBUG - 开始测试104.238.190.35:9050
2018-09-20 06:56:20,771 - Server.Service.fanqiang_ip_service - DEBUG - 随机ip_port 104.238.190.35:9050 无法翻墙，从新获取
2018-09-20 06:56:20,796 - Server.Service.fanqiang_ip_service - DEBUG - 开始测试216.113.24.90:49195
2018-09-20 06:56:30,813 - Server.Service.fanqiang_ip_service - DEBUG - 随机ip_port 216.113.24.90:49195 无法翻墙，从新获取
2018-09-20 06:56:32,330 - Server.Service.fanqiang_ip_service - DEBUG - 开始测试192.169.140.100:12740
2018-09-20 07:27:21,396 - Server.Service.fanqiang_ip_service - DEBUG - 开始测试192.169.140.100:12740
2018-09-20 09:18:48,739 - Server.Service.fanqiang_ip_service - DEBUG - 开始测试192.169.140.100:12740
2018-09-20 11:00:31,901 - Server.Service.fanqiang_ip_service - DEBUG - 开始测试192.169.140.100:12740
2018-09-20 11:00:43,972 - Server.Service.user_service - DEBUG - 代理 192.169.140.100:12740 已失效
2018-09-20 11:00:45,284 - Server.Service.fanqiang_ip_service - DEBUG - 开始测试206.223.248.121:42599
2018-09-20 11:00:48,131 - Server.Service.fanqiang_ip_service - DEBUG - 随机ip_port 206.223.248.121:42599 无法翻墙，从新获取
2018-09-20 11:00:48,315 - Server.Service.fanqiang_ip_service - DEBUG - 开始测试162.243.251.125:29320
2018-09-20 11:01:00,292 - Server.Service.fanqiang_ip_service - DEBUG - 随机ip_port 162.243.251.125:29320 无法翻墙，从新获取
2018-09-20 11:01:00,331 - Server.Service.fanqiang_ip_service - DEBUG - 开始测试206.223.248.76:42599
2018-09-20 11:01:10,582 - Server.Service.fanqiang_ip_service - DEBUG - 随机ip_port 206.223.248.76:42599 无法翻墙，从新获取
2018-09-20 11:01:10,658 - Server.Service.fanqiang_ip_service - DEBUG - 开始测试192.169.140.100:13851
2018-09-20 11:01:12,233 - Server.Service.fanqiang_ip_service - DEBUG - 随机ip_port 192.169.140.100:13851 无法翻墙，从新获取
2018-09-20 11:01:12,268 - Server.Service.fanqiang_ip_service - DEBUG - 开始测试47.148.113.244:15696
2018-09-20 11:01:13,821 - Server.Service.fanqiang_ip_service - DEBUG - 随机ip_port 47.148.113.244:15696 无法翻墙，从新获取
2018-09-20 11:01:13,847 - Server.Service.fanqiang_ip_service - DEBUG - 开始测试166.62.39.74:10080
2018-09-20 11:01:24,231 - Server.Service.fanqiang_ip_service - DEBUG - 随机ip_port 166.62.39.74:10080 无法翻墙，从新获取
2018-09-20 11:01:24,256 - Server.Service.fanqiang_ip_service - DEBUG - 开始测试24.35.20.53:44288
2018-09-20 11:01:26,208 - Server.Service.fanqiang_ip_service - DEBUG - 随机ip_port 24.35.20.53:44288 无法翻墙，从新获取
2018-09-20 11:01:26,234 - Server.Service.fanqiang_ip_service - DEBUG - 开始测试176.37.5.178:30569
2018-09-20 11:01:36,264 - Server.Service.fanqiang_ip_service - DEBUG - 随机ip_port 176.37.5.178:30569 无法翻墙，从新获取
2018-09-20 11:01:36,290 - Server.Service.fanqiang_ip_service - DEBUG - 开始测试46.105.57.149:53208
2018-09-20 11:01:37,139 - Server.Service.fanqiang_ip_service - DEBUG - 随机ip_port 46.105.57.149:53208 无法翻墙，从新获取
2018-09-20 11:01:37,167 - Server.Service.fanqiang_ip_service - DEBUG - 开始测试118.139.176.242:27274
2018-09-20 11:01:38,870 - Server.Service.fanqiang_ip_service - DEBUG - 随机ip_port 118.139.176.242:27274 无法翻墙，从新获取
2018-09-20 11:01:38,904 - Server.Service.fanqiang_ip_service - DEBUG - 开始测试173.255.223.218:5124
2018-09-20 11:01:48,923 - Server.Service.fanqiang_ip_service - DEBUG - 随机ip_port 173.255.223.218:5124 无法翻墙，从新获取
2018-09-20 11:01:48,951 - Server.Service.fanqiang_ip_service - DEBUG - 开始测试208.95.22.244:4352
2018-09-20 11:01:56,595 - Server.Service.fanqiang_ip_service - DEBUG - 随机ip_port 208.95.22.244:4352 无法翻墙，从新获取
2018-09-20 11:01:56,624 - Server.Service.fanqiang_ip_service - DEBUG - 开始测试100.37.125.183:1080
2018-09-20 11:02:06,655 - Server.Service.fanqiang_ip_service - DEBUG - 随机ip_port 100.37.125.183:1080 无法翻墙，从新获取
2018-09-20 11:02:06,680 - Server.Service.fanqiang_ip_service - DEBUG - 开始测试23.29.85.213:39880
2018-09-20 11:02:08,558 - Server.Service.fanqiang_ip_service - DEBUG - 随机ip_port 23.29.85.213:39880 无法翻墙，从新获取
2018-09-20 11:02:08,595 - Server.Service.fanqiang_ip_service - DEBUG - 开始测试188.191.33.34:39880
2018-09-20 11:02:27,854 - Server.Service.fanqiang_ip_service - DEBUG - 随机ip_port 188.191.33.34:39880 无法翻墙，从新获取
2018-09-20 11:02:27,882 - Server.Service.fanqiang_ip_service - DEBUG - 开始测试144.217.161.184:5566
2018-09-20 11:02:29,713 - Server.Service.fanqiang_ip_service - DEBUG - 随机ip_port 144.217.161.184:5566 无法翻墙，从新获取
2018-09-20 11:02:29,740 - Server.Service.fanqiang_ip_service - DEBUG - 开始测试18.191.110.209:54321
2018-09-20 11:02:42,996 - Server.Service.fanqiang_ip_service - DEBUG - 随机ip_port 18.191.110.209:54321 无法翻墙，从新获取
2018-09-20 11:02:43,027 - Server.Service.fanqiang_ip_service - DEBUG - 开始测试171.25.175.22:6667
2018-09-20 11:03:04,447 - Server.Service.fanqiang_ip_service - DEBUG - 随机ip_port 171.25.175.22:6667 无法翻墙，从新获取
2018-09-20 11:03:04,477 - Server.Service.fanqiang_ip_service - DEBUG - 开始测试73.169.212.106:40387
2018-09-20 11:03:06,081 - Server.Service.fanqiang_ip_service - DEBUG - 随机ip_port 73.169.212.106:40387 无法翻墙，从新获取
2018-09-20 11:03:06,112 - Server.Service.fanqiang_ip_service - DEBUG - 开始测试24.143.225.232:32256
2018-09-20 11:03:16,144 - Server.Service.fanqiang_ip_service - DEBUG - 随机ip_port 24.143.225.232:32256 无法翻墙，从新获取
2018-09-20 11:03:16,191 - Server.Service.fanqiang_ip_service - DEBUG - 开始测试216.212.224.157:48128
2018-09-20 11:03:17,875 - Server.Service.fanqiang_ip_service - DEBUG - 随机ip_port 216.212.224.157:48128 无法翻墙，从新获取
2018-09-20 11:03:17,905 - Server.Service.fanqiang_ip_service - DEBUG - 开始测试107.170.42.147:55817
2018-09-20 11:03:28,288 - Server.Service.fanqiang_ip_service - DEBUG - 随机ip_port 107.170.42.147:55817 无法翻墙，从新获取
2018-09-20 11:03:28,318 - Server.Service.fanqiang_ip_service - DEBUG - 开始测试138.68.109.211:9780
2018-09-20 11:03:38,361 - Server.Service.fanqiang_ip_service - DEBUG - 随机ip_port 138.68.109.211:9780 无法翻墙，从新获取
2018-09-20 11:03:38,403 - Server.Service.fanqiang_ip_service - DEBUG - 开始测试168.232.198.81:6667
2018-09-20 11:03:48,475 - Server.Service.fanqiang_ip_service - DEBUG - 随机ip_port 168.232.198.81:6667 无法翻墙，从新获取
2018-09-20 11:03:48,506 - Server.Service.fanqiang_ip_service - DEBUG - 开始测试206.225.138.221:48384
2018-09-20 11:03:50,503 - Server.Service.fanqiang_ip_service - DEBUG - 随机ip_port 206.225.138.221:48384 无法翻墙，从新获取
2018-09-20 11:03:50,560 - Server.Service.fanqiang_ip_service - DEBUG - 开始测试192.169.180.124:59326
2018-09-20 11:04:00,591 - Server.Service.fanqiang_ip_service - DEBUG - 随机ip_port 192.169.180.124:59326 无法翻墙，从新获取
2018-09-20 11:04:00,626 - Server.Service.fanqiang_ip_service - DEBUG - 开始测试50.63.13.254:37554
2018-09-20 16:57:29,960 - Server.Service.fanqiang_ip_service - DEBUG - 开始测试50.63.13.254:37554
2018-09-20 18:08:37,982 - Server.Service.fanqiang_ip_service - DEBUG - 开始测试50.63.13.254:37554
2018-09-20 22:21:49,801 - Server.Service.fanqiang_ip_service - DEBUG - 开始测试50.63.13.254:37554
2018-09-20 22:21:59,950 - Server.Service.user_service - DEBUG - 代理 50.63.13.254:37554 已失效
2018-09-20 22:22:10,525 - Server.Service.fanqiang_ip_service - DEBUG - 开始测试76.72.236.30:46080
2018-09-20 22:22:12,331 - Server.Service.fanqiang_ip_service - DEBUG - 随机ip_port 76.72.236.30:46080 无法翻墙，从新获取
2018-09-20 22:22:12,358 - Server.Service.fanqiang_ip_service - DEBUG - 开始测试206.223.248.102:42599
2018-09-20 22:22:25,699 - Server.Service.fanqiang_ip_service - DEBUG - 随机ip_port 206.223.248.102:42599 无法翻墙，从新获取
2018-09-20 22:22:25,721 - Server.Service.fanqiang_ip_service - DEBUG - 开始测试95.110.207.71:26187
2018-09-20 22:22:32,824 - Server.Service.fanqiang_ip_service - DEBUG - 随机ip_port 95.110.207.71:26187 无法翻墙，从新获取
2018-09-20 22:22:32,847 - Server.Service.fanqiang_ip_service - DEBUG - 开始测试192.169.182.200:22471
2018-09-20 22:22:34,459 - Server.Service.fanqiang_ip_service - DEBUG - 随机ip_port 192.169.182.200:22471 无法翻墙，从新获取
2018-09-20 22:22:34,482 - Server.Service.fanqiang_ip_service - DEBUG - 开始测试77.108.100.163:39880
2018-09-20 22:22:38,509 - Server.Service.fanqiang_ip_service - DEBUG - 随机ip_port 77.108.100.163:39880 无法翻墙，从新获取
2018-09-20 22:22:38,532 - Server.Service.fanqiang_ip_service - DEBUG - 开始测试132.148.130.208:20007
2018-09-20 22:22:48,551 - Server.Service.fanqiang_ip_service - DEBUG - 随机ip_port 132.148.130.208:20007 无法翻墙，从新获取
2018-09-20 22:22:48,575 - Server.Service.fanqiang_ip_service - DEBUG - 开始测试166.62.85.232:4145
2018-09-20 22:22:58,609 - Server.Service.fanqiang_ip_service - DEBUG - 随机ip_port 166.62.85.232:4145 无法翻墙，从新获取
2018-09-20 22:22:58,632 - Server.Service.fanqiang_ip_service - DEBUG - 开始测试23.29.85.213:39880
2018-09-20 22:23:00,273 - Server.Service.fanqiang_ip_service - DEBUG - 随机ip_port 23.29.85.213:39880 无法翻墙，从新获取
2018-09-20 22:23:00,297 - Server.Service.fanqiang_ip_service - DEBUG - 开始测试95.110.230.142:45379
2018-09-20 22:23:02,266 - Server.Service.fanqiang_ip_service - DEBUG - 随机ip_port 95.110.230.142:45379 无法翻墙，从新获取
2018-09-20 22:23:02,290 - Server.Service.fanqiang_ip_service - DEBUG - 开始测试64.118.87.53:53344
2018-09-20 22:23:12,323 - Server.Service.fanqiang_ip_service - DEBUG - 随机ip_port 64.118.87.53:53344 无法翻墙，从新获取
2018-09-20 22:23:12,347 - Server.Service.fanqiang_ip_service - DEBUG - 开始测试64.118.88.43:2447
2018-09-20 22:23:22,377 - Server.Service.fanqiang_ip_service - DEBUG - 随机ip_port 64.118.88.43:2447 无法翻墙，从新获取
2018-09-20 22:23:22,403 - Server.Service.fanqiang_ip_service - DEBUG - 开始测试192.169.182.200:22471
2018-09-20 22:23:32,459 - Server.Service.fanqiang_ip_service - DEBUG - 随机ip_port 192.169.182.200:22471 无法翻墙，从新获取
2018-09-20 22:23:32,484 - Server.Service.fanqiang_ip_service - DEBUG - 开始测试103.28.149.118:8088
2018-09-20 22:23:42,516 - Server.Service.fanqiang_ip_service - DEBUG - 随机ip_port 103.28.149.118:8088 无法翻墙，从新获取
2018-09-20 22:23:42,541 - Server.Service.fanqiang_ip_service - DEBUG - 开始测试192.169.182.200:49164
2018-09-21 09:19:12,273 - Server.Service.fanqiang_ip_service - DEBUG - 开始测试192.169.182.200:49164
2018-09-21 09:19:22,949 - Server.Service.user_service - DEBUG - 代理 192.169.182.200:49164 已失效
2018-09-21 09:19:24,054 - Server.Service.fanqiang_ip_service - DEBUG - 开始测试88.255.185.212:9050
2018-09-21 09:19:34,213 - Server.Service.fanqiang_ip_service - DEBUG - 随机ip_port 88.255.185.212:9050 无法翻墙，从新获取
2018-09-21 09:19:34,545 - Server.Service.fanqiang_ip_service - DEBUG - 开始测试194.219.124.242:1080
2018-09-21 09:19:35,634 - Server.Service.fanqiang_ip_service - DEBUG - 随机ip_port 194.219.124.242:1080 无法翻墙，从新获取
2018-09-21 09:19:35,750 - Server.Service.fanqiang_ip_service - DEBUG - 开始测试192.169.140.100:45349
2018-09-21 09:19:45,839 - Server.Service.fanqiang_ip_service - DEBUG - 随机ip_port 192.169.140.100:45349 无法翻墙，从新获取
2018-09-21 09:19:45,924 - Server.Service.fanqiang_ip_service - DEBUG - 开始测试204.116.20.9:59392
2018-09-21 09:19:47,812 - Server.Service.fanqiang_ip_service - DEBUG - 随机ip_port 204.116.20.9:59392 无法翻墙，从新获取
2018-09-21 09:19:47,892 - Server.Service.fanqiang_ip_service - DEBUG - 开始测试192.169.140.100:24004
2018-09-21 09:19:55,250 - Server.Service.fanqiang_ip_service - DEBUG - 随机ip_port 192.169.140.100:24004 无法翻墙，从新获取
2018-09-21 09:19:55,318 - Server.Service.fanqiang_ip_service - DEBUG - 开始测试148.251.238.35:1080
2018-09-21 09:19:56,097 - Server.Service.fanqiang_ip_service - DEBUG - 随机ip_port 148.251.238.35:1080 无法翻墙，从新获取
2018-09-21 09:19:56,166 - Server.Service.fanqiang_ip_service - DEBUG - 开始测试95.110.227.5:50538
2018-09-21 14:22:57,243 - Server.Service.fanqiang_ip_service - DEBUG - 开始测试95.110.227.5:50538
2018-09-21 16:54:59,417 - Server.Service.fanqiang_ip_service - DEBUG - 开始测试95.110.227.5:50538
2018-09-21 16:55:12,593 - Server.Service.user_service - DEBUG - 代理 95.110.227.5:50538 已失效
2018-09-21 16:55:15,132 - Server.Service.fanqiang_ip_service - DEBUG - 开始测试64.118.88.44:36370
2018-09-21 16:55:25,217 - Server.Service.fanqiang_ip_service - DEBUG - 随机ip_port 64.118.88.44:36370 无法翻墙，从新获取
2018-09-21 16:55:25,306 - Server.Service.fanqiang_ip_service - DEBUG - 开始测试192.169.250.198:13090
