2018-08-07 10:56:38,339 - Utils.log_utils - ERROR - Traceback (most recent call last):
  File "F:\scribe2\venv\lib\site-packages\socks.py", line 832, in connect
    super(socksocket, self).connect(proxy_addr)
socket.timeout: timed out

During handling of the above exception, another exception occurred:

Traceback (most recent call last):
  File "F:\scribe2\venv\lib\site-packages\urllib3\contrib\socks.py", line 88, in _new_conn
    **extra_kw
  File "F:\scribe2\venv\lib\site-packages\socks.py", line 262, in create_connection
    raise err
  File "F:\scribe2\venv\lib\site-packages\socks.py", line 252, in create_connection
    sock.connect((remote_host, remote_port))
  File "F:\scribe2\venv\lib\site-packages\socks.py", line 100, in wrapper
    return function(*args, **kwargs)
  File "F:\scribe2\venv\lib\site-packages\socks.py", line 844, in connect
    raise ProxyConnectionError(msg, error)
socks.ProxyConnectionError: Error connecting to SOCKS5 proxy 188.120.234.190:31214: timed out

During handling of the above exception, another exception occurred:

Traceback (most recent call last):
  File "F:\scribe2\venv\lib\site-packages\urllib3\connectionpool.py", line 601, in urlopen
    chunked=chunked)
  File "F:\scribe2\venv\lib\site-packages\urllib3\connectionpool.py", line 346, in _make_request
    self._validate_conn(conn)
  File "F:\scribe2\venv\lib\site-packages\urllib3\connectionpool.py", line 850, in _validate_conn
    conn.connect()
  File "F:\scribe2\venv\lib\site-packages\urllib3\connection.py", line 284, in connect
    conn = self._new_conn()
  File "F:\scribe2\venv\lib\site-packages\urllib3\contrib\socks.py", line 105, in _new_conn
    (self.host, self.timeout)
urllib3.exceptions.ConnectTimeoutError: (<urllib3.contrib.socks.SOCKSHTTPSConnection object at 0x0000000006189CC0>, 'Connection to www.baidu.com timed out. (connect timeout=10)')

During handling of the above exception, another exception occurred:

Traceback (most recent call last):
  File "F:\scribe2\venv\lib\site-packages\requests\adapters.py", line 440, in send
    timeout=timeout
  File "F:\scribe2\venv\lib\site-packages\urllib3\connectionpool.py", line 639, in urlopen
    _stacktrace=sys.exc_info()[2])
  File "F:\scribe2\venv\lib\site-packages\urllib3\util\retry.py", line 388, in increment
    raise MaxRetryError(_pool, url, error or ResponseError(cause))
urllib3.exceptions.MaxRetryError: SOCKSHTTPSConnectionPool(host='www.baidu.com', port=443): Max retries exceeded with url: / (Caused by ConnectTimeoutError(<urllib3.contrib.socks.SOCKSHTTPSConnection object at 0x0000000006189CC0>, 'Connection to www.baidu.com timed out. (connect timeout=10)'))

During handling of the above exception, another exception occurred:

Traceback (most recent call last):
  File "F:\scribe2\Server\Service\fanqiang_ip_service.py", line 20, in get_random_ip_port_dict
    test_proxy(ip_port_dict)
  File "F:\scribe2\Server\Service\fanqiang_ip_service.py", line 65, in test_proxy
    timeout=10)
  File "F:\scribe2\venv\lib\site-packages\requests\api.py", line 72, in get
    return request('get', url, params=params, **kwargs)
  File "F:\scribe2\venv\lib\site-packages\requests\api.py", line 58, in request
    return session.request(method=method, url=url, **kwargs)
  File "F:\scribe2\venv\lib\site-packages\requests\sessions.py", line 508, in request
    resp = self.send(prep, **send_kwargs)
  File "F:\scribe2\venv\lib\site-packages\requests\sessions.py", line 618, in send
    r = adapter.send(request, **kwargs)
  File "F:\scribe2\venv\lib\site-packages\requests\adapters.py", line 496, in send
    raise ConnectTimeout(e, request=request)
requests.exceptions.ConnectTimeout: SOCKSHTTPSConnectionPool(host='www.baidu.com', port=443): Max retries exceeded with url: / (Caused by ConnectTimeoutError(<urllib3.contrib.socks.SOCKSHTTPSConnection object at 0x0000000006189CC0>, 'Connection to www.baidu.com timed out. (connect timeout=10)'))

During handling of the above exception, another exception occurred:

Traceback (most recent call last):
  File "F:/scribe2/Server/server.py", line 28, in get_lans_data
    ip_with_port=fanqiang_ip_service.get_random_ip_port_dict()
  File "F:\scribe2\Server\Service\fanqiang_ip_service.py", line 24, in get_random_ip_port_dict
    return get_random_ip_port_dict()
  File "F:\scribe2\Server\Service\fanqiang_ip_service.py", line 20, in get_random_ip_port_dict
    test_proxy(ip_port_dict)
  File "F:\scribe2\Server\Service\fanqiang_ip_service.py", line 67, in test_proxy
    location = scribe_utils.get_location(ip_with_port.split(':')[0])
  File "F:\scribe2\Utils\scribe_utils.py", line 215, in get_location
    reader = geoip2.database.Reader('file/GeoLite2-City_20180501/GeoLite2-City.mmdb')
  File "F:\scribe2\venv\lib\site-packages\geoip2\database.py", line 86, in __init__
    self._db_reader = maxminddb.open_database(fileish, mode)
  File "F:\scribe2\venv\lib\site-packages\maxminddb\__init__.py", line 41, in open_database
    return maxminddb.reader.Reader(database, mode)
  File "F:\scribe2\venv\lib\site-packages\maxminddb\reader.py", line 52, in __init__
    with open(database, 'rb') as db_file:
FileNotFoundError: [Errno 2] No such file or directory: 'file/GeoLite2-City_20180501/GeoLite2-City.mmdb'

2018-08-07 11:00:04,126 - Utils.log_utils - ERROR - Traceback (most recent call last):
  File "F:\scribe2\venv\lib\site-packages\socks.py", line 832, in connect
    super(socksocket, self).connect(proxy_addr)
socket.timeout: timed out

During handling of the above exception, another exception occurred:

Traceback (most recent call last):
  File "F:\scribe2\venv\lib\site-packages\urllib3\contrib\socks.py", line 88, in _new_conn
    **extra_kw
  File "F:\scribe2\venv\lib\site-packages\socks.py", line 262, in create_connection
    raise err
  File "F:\scribe2\venv\lib\site-packages\socks.py", line 252, in create_connection
    sock.connect((remote_host, remote_port))
  File "F:\scribe2\venv\lib\site-packages\socks.py", line 100, in wrapper
    return function(*args, **kwargs)
  File "F:\scribe2\venv\lib\site-packages\socks.py", line 844, in connect
    raise ProxyConnectionError(msg, error)
socks.ProxyConnectionError: Error connecting to SOCKS5 proxy 188.120.224.172:51036: timed out

During handling of the above exception, another exception occurred:

Traceback (most recent call last):
  File "F:\scribe2\venv\lib\site-packages\urllib3\connectionpool.py", line 601, in urlopen
    chunked=chunked)
  File "F:\scribe2\venv\lib\site-packages\urllib3\connectionpool.py", line 346, in _make_request
    self._validate_conn(conn)
  File "F:\scribe2\venv\lib\site-packages\urllib3\connectionpool.py", line 850, in _validate_conn
    conn.connect()
  File "F:\scribe2\venv\lib\site-packages\urllib3\connection.py", line 284, in connect
    conn = self._new_conn()
  File "F:\scribe2\venv\lib\site-packages\urllib3\contrib\socks.py", line 105, in _new_conn
    (self.host, self.timeout)
urllib3.exceptions.ConnectTimeoutError: (<urllib3.contrib.socks.SOCKSHTTPSConnection object at 0x0000000006542C18>, 'Connection to www.baidu.com timed out. (connect timeout=10)')

During handling of the above exception, another exception occurred:

Traceback (most recent call last):
  File "F:\scribe2\venv\lib\site-packages\requests\adapters.py", line 440, in send
    timeout=timeout
  File "F:\scribe2\venv\lib\site-packages\urllib3\connectionpool.py", line 639, in urlopen
    _stacktrace=sys.exc_info()[2])
  File "F:\scribe2\venv\lib\site-packages\urllib3\util\retry.py", line 388, in increment
    raise MaxRetryError(_pool, url, error or ResponseError(cause))
urllib3.exceptions.MaxRetryError: SOCKSHTTPSConnectionPool(host='www.baidu.com', port=443): Max retries exceeded with url: / (Caused by ConnectTimeoutError(<urllib3.contrib.socks.SOCKSHTTPSConnection object at 0x0000000006542C18>, 'Connection to www.baidu.com timed out. (connect timeout=10)'))

During handling of the above exception, another exception occurred:

Traceback (most recent call last):
  File "F:\scribe2\Server\Service\fanqiang_ip_service.py", line 20, in get_random_ip_port_dict
    test_proxy(ip_port_dict)
  File "F:\scribe2\Server\Service\fanqiang_ip_service.py", line 65, in test_proxy
    timeout=10)
  File "F:\scribe2\venv\lib\site-packages\requests\api.py", line 72, in get
    return request('get', url, params=params, **kwargs)
  File "F:\scribe2\venv\lib\site-packages\requests\api.py", line 58, in request
    return session.request(method=method, url=url, **kwargs)
  File "F:\scribe2\venv\lib\site-packages\requests\sessions.py", line 508, in request
    resp = self.send(prep, **send_kwargs)
  File "F:\scribe2\venv\lib\site-packages\requests\sessions.py", line 618, in send
    r = adapter.send(request, **kwargs)
  File "F:\scribe2\venv\lib\site-packages\requests\adapters.py", line 496, in send
    raise ConnectTimeout(e, request=request)
requests.exceptions.ConnectTimeout: SOCKSHTTPSConnectionPool(host='www.baidu.com', port=443): Max retries exceeded with url: / (Caused by ConnectTimeoutError(<urllib3.contrib.socks.SOCKSHTTPSConnection object at 0x0000000006542C18>, 'Connection to www.baidu.com timed out. (connect timeout=10)'))

During handling of the above exception, another exception occurred:

Traceback (most recent call last):
  File "F:/scribe2/Server/server.py", line 28, in get_lans_data
    ip_with_port=fanqiang_ip_service.get_random_ip_port_dict()
  File "F:\scribe2\Server\Service\fanqiang_ip_service.py", line 24, in get_random_ip_port_dict
    return get_random_ip_port_dict()
  File "F:\scribe2\Server\Service\fanqiang_ip_service.py", line 20, in get_random_ip_port_dict
    test_proxy(ip_port_dict)
  File "F:\scribe2\Server\Service\fanqiang_ip_service.py", line 67, in test_proxy
    location = scribe_utils.get_location(ip_with_port.split(':')[0])
  File "F:\scribe2\Utils\scribe_utils.py", line 215, in get_location
    reader = geoip2.database.Reader('file/GeoLite2-City_20180501/GeoLite2-City.mmdb')
  File "F:\scribe2\venv\lib\site-packages\geoip2\database.py", line 86, in __init__
    self._db_reader = maxminddb.open_database(fileish, mode)
  File "F:\scribe2\venv\lib\site-packages\maxminddb\__init__.py", line 41, in open_database
    return maxminddb.reader.Reader(database, mode)
  File "F:\scribe2\venv\lib\site-packages\maxminddb\reader.py", line 52, in __init__
    with open(database, 'rb') as db_file:
FileNotFoundError: [Errno 2] No such file or directory: 'file/GeoLite2-City_20180501/GeoLite2-City.mmdb'

2018-08-07 14:56:33,594 - Utils.log_utils - ERROR - f8891082-9a0e-11e8-96b7-005056c00008 - Traceback (most recent call last):
  File "F:\scribe2\venv\lib\site-packages\socks.py", line 832, in connect
    super(socksocket, self).connect(proxy_addr)
socket.timeout: timed out

During handling of the above exception, another exception occurred:

Traceback (most recent call last):
  File "F:\scribe2\venv\lib\site-packages\urllib3\contrib\socks.py", line 88, in _new_conn
    **extra_kw
  File "F:\scribe2\venv\lib\site-packages\socks.py", line 262, in create_connection
    raise err
  File "F:\scribe2\venv\lib\site-packages\socks.py", line 252, in create_connection
    sock.connect((remote_host, remote_port))
  File "F:\scribe2\venv\lib\site-packages\socks.py", line 100, in wrapper
    return function(*args, **kwargs)
  File "F:\scribe2\venv\lib\site-packages\socks.py", line 844, in connect
    raise ProxyConnectionError(msg, error)
socks.ProxyConnectionError: Error connecting to SOCKS5 proxy 132.148.129.183:47617: timed out

During handling of the above exception, another exception occurred:

Traceback (most recent call last):
  File "F:\scribe2\venv\lib\site-packages\urllib3\connectionpool.py", line 601, in urlopen
    chunked=chunked)
  File "F:\scribe2\venv\lib\site-packages\urllib3\connectionpool.py", line 346, in _make_request
    self._validate_conn(conn)
  File "F:\scribe2\venv\lib\site-packages\urllib3\connectionpool.py", line 850, in _validate_conn
    conn.connect()
  File "F:\scribe2\venv\lib\site-packages\urllib3\connection.py", line 284, in connect
    conn = self._new_conn()
  File "F:\scribe2\venv\lib\site-packages\urllib3\contrib\socks.py", line 105, in _new_conn
    (self.host, self.timeout)
urllib3.exceptions.ConnectTimeoutError: (<urllib3.contrib.socks.SOCKSHTTPSConnection object at 0x00000000072162E8>, 'Connection to www.baidu.com timed out. (connect timeout=10)')

During handling of the above exception, another exception occurred:

Traceback (most recent call last):
  File "F:\scribe2\venv\lib\site-packages\requests\adapters.py", line 440, in send
    timeout=timeout
  File "F:\scribe2\venv\lib\site-packages\urllib3\connectionpool.py", line 639, in urlopen
    _stacktrace=sys.exc_info()[2])
  File "F:\scribe2\venv\lib\site-packages\urllib3\util\retry.py", line 388, in increment
    raise MaxRetryError(_pool, url, error or ResponseError(cause))
urllib3.exceptions.MaxRetryError: SOCKSHTTPSConnectionPool(host='www.baidu.com', port=443): Max retries exceeded with url: / (Caused by ConnectTimeoutError(<urllib3.contrib.socks.SOCKSHTTPSConnection object at 0x00000000072162E8>, 'Connection to www.baidu.com timed out. (connect timeout=10)'))

During handling of the above exception, another exception occurred:

Traceback (most recent call last):
  File "F:\scribe2\Server\Service\fanqiang_ip_service.py", line 21, in get_random_ip_port_dict
    test_proxy(ip_port_dict)
  File "F:\scribe2\Server\Service\fanqiang_ip_service.py", line 42, in test_proxy
    timeout=10)
  File "F:\scribe2\venv\lib\site-packages\requests\api.py", line 72, in get
    return request('get', url, params=params, **kwargs)
  File "F:\scribe2\venv\lib\site-packages\requests\api.py", line 58, in request
    return session.request(method=method, url=url, **kwargs)
  File "F:\scribe2\venv\lib\site-packages\requests\sessions.py", line 508, in request
    resp = self.send(prep, **send_kwargs)
  File "F:\scribe2\venv\lib\site-packages\requests\sessions.py", line 618, in send
    r = adapter.send(request, **kwargs)
  File "F:\scribe2\venv\lib\site-packages\requests\adapters.py", line 496, in send
    raise ConnectTimeout(e, request=request)
requests.exceptions.ConnectTimeout: SOCKSHTTPSConnectionPool(host='www.baidu.com', port=443): Max retries exceeded with url: / (Caused by ConnectTimeoutError(<urllib3.contrib.socks.SOCKSHTTPSConnection object at 0x00000000072162E8>, 'Connection to www.baidu.com timed out. (connect timeout=10)'))

During handling of the above exception, another exception occurred:

Traceback (most recent call last):
  File "F:\scribe2\venv\lib\site-packages\urllib3\contrib\socks.py", line 88, in _new_conn
    **extra_kw
  File "F:\scribe2\venv\lib\site-packages\socks.py", line 262, in create_connection
    raise err
  File "F:\scribe2\venv\lib\site-packages\socks.py", line 252, in create_connection
    sock.connect((remote_host, remote_port))
  File "F:\scribe2\venv\lib\site-packages\socks.py", line 100, in wrapper
    return function(*args, **kwargs)
  File "F:\scribe2\venv\lib\site-packages\socks.py", line 844, in connect
    raise ProxyConnectionError(msg, error)
socks.ProxyConnectionError: Error connecting to SOCKS5 proxy 103.216.82.148:6667: timed out

During handling of the above exception, another exception occurred:

Traceback (most recent call last):
  File "F:\scribe2\venv\lib\site-packages\urllib3\connectionpool.py", line 601, in urlopen
    chunked=chunked)
  File "F:\scribe2\venv\lib\site-packages\urllib3\connectionpool.py", line 346, in _make_request
    self._validate_conn(conn)
  File "F:\scribe2\venv\lib\site-packages\urllib3\connectionpool.py", line 850, in _validate_conn
    conn.connect()
  File "F:\scribe2\venv\lib\site-packages\urllib3\connection.py", line 284, in connect
    conn = self._new_conn()
  File "F:\scribe2\venv\lib\site-packages\urllib3\contrib\socks.py", line 105, in _new_conn
    (self.host, self.timeout)
urllib3.exceptions.ConnectTimeoutError: (<urllib3.contrib.socks.SOCKSHTTPSConnection object at 0x0000000007299630>, 'Connection to www.baidu.com timed out. (connect timeout=10)')

During handling of the above exception, another exception occurred:

Traceback (most recent call last):
  File "F:\scribe2\venv\lib\site-packages\requests\adapters.py", line 440, in send
    timeout=timeout
  File "F:\scribe2\venv\lib\site-packages\urllib3\connectionpool.py", line 639, in urlopen
    _stacktrace=sys.exc_info()[2])
  File "F:\scribe2\venv\lib\site-packages\urllib3\util\retry.py", line 388, in increment
    raise MaxRetryError(_pool, url, error or ResponseError(cause))
urllib3.exceptions.MaxRetryError: SOCKSHTTPSConnectionPool(host='www.baidu.com', port=443): Max retries exceeded with url: / (Caused by ConnectTimeoutError(<urllib3.contrib.socks.SOCKSHTTPSConnection object at 0x0000000007299630>, 'Connection to www.baidu.com timed out. (connect timeout=10)'))

During handling of the above exception, another exception occurred:

Traceback (most recent call last):
  File "F:\scribe2\Server\Service\fanqiang_ip_service.py", line 21, in get_random_ip_port_dict
    test_proxy(ip_port_dict)
  File "F:\scribe2\Server\Service\fanqiang_ip_service.py", line 42, in test_proxy
    timeout=10)
  File "F:\scribe2\venv\lib\site-packages\requests\api.py", line 72, in get
    return request('get', url, params=params, **kwargs)
  File "F:\scribe2\venv\lib\site-packages\requests\api.py", line 58, in request
    return session.request(method=method, url=url, **kwargs)
  File "F:\scribe2\venv\lib\site-packages\requests\sessions.py", line 508, in request
    resp = self.send(prep, **send_kwargs)
  File "F:\scribe2\venv\lib\site-packages\requests\sessions.py", line 618, in send
    r = adapter.send(request, **kwargs)
  File "F:\scribe2\venv\lib\site-packages\requests\adapters.py", line 496, in send
    raise ConnectTimeout(e, request=request)
requests.exceptions.ConnectTimeout: SOCKSHTTPSConnectionPool(host='www.baidu.com', port=443): Max retries exceeded with url: / (Caused by ConnectTimeoutError(<urllib3.contrib.socks.SOCKSHTTPSConnection object at 0x0000000007299630>, 'Connection to www.baidu.com timed out. (connect timeout=10)'))

During handling of the above exception, another exception occurred:

Traceback (most recent call last):
  File "F:/scribe2/Server/server.py", line 28, in get_lans_data
    ip_with_port=fanqiang_ip_service.get_random_ip_port_dict()
  File "F:\scribe2\Server\Service\fanqiang_ip_service.py", line 25, in get_random_ip_port_dict
    return get_random_ip_port_dict()
  File "F:\scribe2\Server\Service\fanqiang_ip_service.py", line 25, in get_random_ip_port_dict
    return get_random_ip_port_dict()
  File "F:\scribe2\Server\Service\fanqiang_ip_service.py", line 19, in get_random_ip_port_dict
    ip_port_dict = ip_list[math.floor(random.random() * len(ip_list))]
IndexError: list index out of range

2018-08-07 14:56:38,005 - Utils.log_utils - ERROR - c3671322-9a0e-11e8-a41f-005056c00008 - Traceback (most recent call last):
  File "F:\scribe2\venv\lib\site-packages\socks.py", line 832, in connect
    super(socksocket, self).connect(proxy_addr)
socket.timeout: timed out

During handling of the above exception, another exception occurred:

Traceback (most recent call last):
  File "F:\scribe2\venv\lib\site-packages\urllib3\contrib\socks.py", line 88, in _new_conn
    **extra_kw
  File "F:\scribe2\venv\lib\site-packages\socks.py", line 262, in create_connection
    raise err
  File "F:\scribe2\venv\lib\site-packages\socks.py", line 252, in create_connection
    sock.connect((remote_host, remote_port))
  File "F:\scribe2\venv\lib\site-packages\socks.py", line 100, in wrapper
    return function(*args, **kwargs)
  File "F:\scribe2\venv\lib\site-packages\socks.py", line 844, in connect
    raise ProxyConnectionError(msg, error)
socks.ProxyConnectionError: Error connecting to SOCKS5 proxy 192.169.180.124:1342: timed out

During handling of the above exception, another exception occurred:

Traceback (most recent call last):
  File "F:\scribe2\venv\lib\site-packages\urllib3\connectionpool.py", line 601, in urlopen
    chunked=chunked)
  File "F:\scribe2\venv\lib\site-packages\urllib3\connectionpool.py", line 346, in _make_request
    self._validate_conn(conn)
  File "F:\scribe2\venv\lib\site-packages\urllib3\connectionpool.py", line 850, in _validate_conn
    conn.connect()
  File "F:\scribe2\venv\lib\site-packages\urllib3\connection.py", line 284, in connect
    conn = self._new_conn()
  File "F:\scribe2\venv\lib\site-packages\urllib3\contrib\socks.py", line 105, in _new_conn
    (self.host, self.timeout)
urllib3.exceptions.ConnectTimeoutError: (<urllib3.contrib.socks.SOCKSHTTPSConnection object at 0x0000000006AACA90>, 'Connection to www.baidu.com timed out. (connect timeout=10)')

During handling of the above exception, another exception occurred:

Traceback (most recent call last):
  File "F:\scribe2\venv\lib\site-packages\requests\adapters.py", line 440, in send
    timeout=timeout
  File "F:\scribe2\venv\lib\site-packages\urllib3\connectionpool.py", line 639, in urlopen
    _stacktrace=sys.exc_info()[2])
  File "F:\scribe2\venv\lib\site-packages\urllib3\util\retry.py", line 388, in increment
    raise MaxRetryError(_pool, url, error or ResponseError(cause))
urllib3.exceptions.MaxRetryError: SOCKSHTTPSConnectionPool(host='www.baidu.com', port=443): Max retries exceeded with url: / (Caused by ConnectTimeoutError(<urllib3.contrib.socks.SOCKSHTTPSConnection object at 0x0000000006AACA90>, 'Connection to www.baidu.com timed out. (connect timeout=10)'))

During handling of the above exception, another exception occurred:

Traceback (most recent call last):
  File "F:\scribe2\Server\Service\fanqiang_ip_service.py", line 21, in get_random_ip_port_dict
    test_proxy(ip_port_dict)
  File "F:\scribe2\Server\Service\fanqiang_ip_service.py", line 42, in test_proxy
    timeout=10)
  File "F:\scribe2\venv\lib\site-packages\requests\api.py", line 72, in get
    return request('get', url, params=params, **kwargs)
  File "F:\scribe2\venv\lib\site-packages\requests\api.py", line 58, in request
    return session.request(method=method, url=url, **kwargs)
  File "F:\scribe2\venv\lib\site-packages\requests\sessions.py", line 508, in request
    resp = self.send(prep, **send_kwargs)
  File "F:\scribe2\venv\lib\site-packages\requests\sessions.py", line 618, in send
    r = adapter.send(request, **kwargs)
  File "F:\scribe2\venv\lib\site-packages\requests\adapters.py", line 496, in send
    raise ConnectTimeout(e, request=request)
requests.exceptions.ConnectTimeout: SOCKSHTTPSConnectionPool(host='www.baidu.com', port=443): Max retries exceeded with url: / (Caused by ConnectTimeoutError(<urllib3.contrib.socks.SOCKSHTTPSConnection object at 0x0000000006AACA90>, 'Connection to www.baidu.com timed out. (connect timeout=10)'))

During handling of the above exception, another exception occurred:

Traceback (most recent call last):
  File "F:\scribe2\venv\lib\site-packages\urllib3\contrib\socks.py", line 88, in _new_conn
    **extra_kw
  File "F:\scribe2\venv\lib\site-packages\socks.py", line 262, in create_connection
    raise err
  File "F:\scribe2\venv\lib\site-packages\socks.py", line 252, in create_connection
    sock.connect((remote_host, remote_port))
  File "F:\scribe2\venv\lib\site-packages\socks.py", line 100, in wrapper
    return function(*args, **kwargs)
  File "F:\scribe2\venv\lib\site-packages\socks.py", line 844, in connect
    raise ProxyConnectionError(msg, error)
socks.ProxyConnectionError: Error connecting to SOCKS5 proxy 132.148.129.183:1628: timed out

During handling of the above exception, another exception occurred:

Traceback (most recent call last):
  File "F:\scribe2\venv\lib\site-packages\urllib3\connectionpool.py", line 601, in urlopen
    chunked=chunked)
  File "F:\scribe2\venv\lib\site-packages\urllib3\connectionpool.py", line 346, in _make_request
    self._validate_conn(conn)
  File "F:\scribe2\venv\lib\site-packages\urllib3\connectionpool.py", line 850, in _validate_conn
    conn.connect()
  File "F:\scribe2\venv\lib\site-packages\urllib3\connection.py", line 284, in connect
    conn = self._new_conn()
  File "F:\scribe2\venv\lib\site-packages\urllib3\contrib\socks.py", line 105, in _new_conn
    (self.host, self.timeout)
urllib3.exceptions.ConnectTimeoutError: (<urllib3.contrib.socks.SOCKSHTTPSConnection object at 0x0000000006B22828>, 'Connection to www.baidu.com timed out. (connect timeout=10)')

During handling of the above exception, another exception occurred:

Traceback (most recent call last):
  File "F:\scribe2\venv\lib\site-packages\requests\adapters.py", line 440, in send
    timeout=timeout
  File "F:\scribe2\venv\lib\site-packages\urllib3\connectionpool.py", line 639, in urlopen
    _stacktrace=sys.exc_info()[2])
  File "F:\scribe2\venv\lib\site-packages\urllib3\util\retry.py", line 388, in increment
    raise MaxRetryError(_pool, url, error or ResponseError(cause))
urllib3.exceptions.MaxRetryError: SOCKSHTTPSConnectionPool(host='www.baidu.com', port=443): Max retries exceeded with url: / (Caused by ConnectTimeoutError(<urllib3.contrib.socks.SOCKSHTTPSConnection object at 0x0000000006B22828>, 'Connection to www.baidu.com timed out. (connect timeout=10)'))

During handling of the above exception, another exception occurred:

Traceback (most recent call last):
  File "F:\scribe2\Server\Service\fanqiang_ip_service.py", line 21, in get_random_ip_port_dict
    test_proxy(ip_port_dict)
  File "F:\scribe2\Server\Service\fanqiang_ip_service.py", line 42, in test_proxy
    timeout=10)
  File "F:\scribe2\venv\lib\site-packages\requests\api.py", line 72, in get
    return request('get', url, params=params, **kwargs)
  File "F:\scribe2\venv\lib\site-packages\requests\api.py", line 58, in request
    return session.request(method=method, url=url, **kwargs)
  File "F:\scribe2\venv\lib\site-packages\requests\sessions.py", line 508, in request
    resp = self.send(prep, **send_kwargs)
  File "F:\scribe2\venv\lib\site-packages\requests\sessions.py", line 618, in send
    r = adapter.send(request, **kwargs)
  File "F:\scribe2\venv\lib\site-packages\requests\adapters.py", line 496, in send
    raise ConnectTimeout(e, request=request)
requests.exceptions.ConnectTimeout: SOCKSHTTPSConnectionPool(host='www.baidu.com', port=443): Max retries exceeded with url: / (Caused by ConnectTimeoutError(<urllib3.contrib.socks.SOCKSHTTPSConnection object at 0x0000000006B22828>, 'Connection to www.baidu.com timed out. (connect timeout=10)'))

During handling of the above exception, another exception occurred:

Traceback (most recent call last):
  File "F:\scribe2\venv\lib\site-packages\urllib3\contrib\socks.py", line 88, in _new_conn
    **extra_kw
  File "F:\scribe2\venv\lib\site-packages\socks.py", line 262, in create_connection
    raise err
  File "F:\scribe2\venv\lib\site-packages\socks.py", line 252, in create_connection
    sock.connect((remote_host, remote_port))
  File "F:\scribe2\venv\lib\site-packages\socks.py", line 100, in wrapper
    return function(*args, **kwargs)
  File "F:\scribe2\venv\lib\site-packages\socks.py", line 844, in connect
    raise ProxyConnectionError(msg, error)
socks.ProxyConnectionError: Error connecting to SOCKS5 proxy 195.25.25.132:58920: timed out

During handling of the above exception, another exception occurred:

Traceback (most recent call last):
  File "F:\scribe2\venv\lib\site-packages\urllib3\connectionpool.py", line 601, in urlopen
    chunked=chunked)
  File "F:\scribe2\venv\lib\site-packages\urllib3\connectionpool.py", line 346, in _make_request
    self._validate_conn(conn)
  File "F:\scribe2\venv\lib\site-packages\urllib3\connectionpool.py", line 850, in _validate_conn
    conn.connect()
  File "F:\scribe2\venv\lib\site-packages\urllib3\connection.py", line 284, in connect
    conn = self._new_conn()
  File "F:\scribe2\venv\lib\site-packages\urllib3\contrib\socks.py", line 105, in _new_conn
    (self.host, self.timeout)
urllib3.exceptions.ConnectTimeoutError: (<urllib3.contrib.socks.SOCKSHTTPSConnection object at 0x0000000006D80320>, 'Connection to www.baidu.com timed out. (connect timeout=10)')

During handling of the above exception, another exception occurred:

Traceback (most recent call last):
  File "F:\scribe2\venv\lib\site-packages\requests\adapters.py", line 440, in send
    timeout=timeout
  File "F:\scribe2\venv\lib\site-packages\urllib3\connectionpool.py", line 639, in urlopen
    _stacktrace=sys.exc_info()[2])
  File "F:\scribe2\venv\lib\site-packages\urllib3\util\retry.py", line 388, in increment
    raise MaxRetryError(_pool, url, error or ResponseError(cause))
urllib3.exceptions.MaxRetryError: SOCKSHTTPSConnectionPool(host='www.baidu.com', port=443): Max retries exceeded with url: / (Caused by ConnectTimeoutError(<urllib3.contrib.socks.SOCKSHTTPSConnection object at 0x0000000006D80320>, 'Connection to www.baidu.com timed out. (connect timeout=10)'))

During handling of the above exception, another exception occurred:

Traceback (most recent call last):
  File "F:\scribe2\Server\Service\fanqiang_ip_service.py", line 21, in get_random_ip_port_dict
    test_proxy(ip_port_dict)
  File "F:\scribe2\Server\Service\fanqiang_ip_service.py", line 42, in test_proxy
    timeout=10)
  File "F:\scribe2\venv\lib\site-packages\requests\api.py", line 72, in get
    return request('get', url, params=params, **kwargs)
  File "F:\scribe2\venv\lib\site-packages\requests\api.py", line 58, in request
    return session.request(method=method, url=url, **kwargs)
  File "F:\scribe2\venv\lib\site-packages\requests\sessions.py", line 508, in request
    resp = self.send(prep, **send_kwargs)
  File "F:\scribe2\venv\lib\site-packages\requests\sessions.py", line 618, in send
    r = adapter.send(request, **kwargs)
  File "F:\scribe2\venv\lib\site-packages\requests\adapters.py", line 496, in send
    raise ConnectTimeout(e, request=request)
requests.exceptions.ConnectTimeout: SOCKSHTTPSConnectionPool(host='www.baidu.com', port=443): Max retries exceeded with url: / (Caused by ConnectTimeoutError(<urllib3.contrib.socks.SOCKSHTTPSConnection object at 0x0000000006D80320>, 'Connection to www.baidu.com timed out. (connect timeout=10)'))

During handling of the above exception, another exception occurred:

Traceback (most recent call last):
  File "F:\scribe2\venv\lib\site-packages\urllib3\contrib\socks.py", line 88, in _new_conn
    **extra_kw
  File "F:\scribe2\venv\lib\site-packages\socks.py", line 262, in create_connection
    raise err
  File "F:\scribe2\venv\lib\site-packages\socks.py", line 252, in create_connection
    sock.connect((remote_host, remote_port))
  File "F:\scribe2\venv\lib\site-packages\socks.py", line 100, in wrapper
    return function(*args, **kwargs)
  File "F:\scribe2\venv\lib\site-packages\socks.py", line 844, in connect
    raise ProxyConnectionError(msg, error)
socks.ProxyConnectionError: Error connecting to SOCKS5 proxy 109.200.132.144:8888: timed out

During handling of the above exception, another exception occurred:

Traceback (most recent call last):
  File "F:\scribe2\venv\lib\site-packages\urllib3\connectionpool.py", line 601, in urlopen
    chunked=chunked)
  File "F:\scribe2\venv\lib\site-packages\urllib3\connectionpool.py", line 346, in _make_request
    self._validate_conn(conn)
  File "F:\scribe2\venv\lib\site-packages\urllib3\connectionpool.py", line 850, in _validate_conn
    conn.connect()
  File "F:\scribe2\venv\lib\site-packages\urllib3\connection.py", line 284, in connect
    conn = self._new_conn()
  File "F:\scribe2\venv\lib\site-packages\urllib3\contrib\socks.py", line 105, in _new_conn
    (self.host, self.timeout)
urllib3.exceptions.ConnectTimeoutError: (<urllib3.contrib.socks.SOCKSHTTPSConnection object at 0x0000000006DC8C50>, 'Connection to www.baidu.com timed out. (connect timeout=10)')

During handling of the above exception, another exception occurred:

Traceback (most recent call last):
  File "F:\scribe2\venv\lib\site-packages\requests\adapters.py", line 440, in send
    timeout=timeout
  File "F:\scribe2\venv\lib\site-packages\urllib3\connectionpool.py", line 639, in urlopen
    _stacktrace=sys.exc_info()[2])
  File "F:\scribe2\venv\lib\site-packages\urllib3\util\retry.py", line 388, in increment
    raise MaxRetryError(_pool, url, error or ResponseError(cause))
urllib3.exceptions.MaxRetryError: SOCKSHTTPSConnectionPool(host='www.baidu.com', port=443): Max retries exceeded with url: / (Caused by ConnectTimeoutError(<urllib3.contrib.socks.SOCKSHTTPSConnection object at 0x0000000006DC8C50>, 'Connection to www.baidu.com timed out. (connect timeout=10)'))

During handling of the above exception, another exception occurred:

Traceback (most recent call last):
  File "F:\scribe2\Server\Service\fanqiang_ip_service.py", line 21, in get_random_ip_port_dict
    test_proxy(ip_port_dict)
  File "F:\scribe2\Server\Service\fanqiang_ip_service.py", line 42, in test_proxy
    timeout=10)
  File "F:\scribe2\venv\lib\site-packages\requests\api.py", line 72, in get
    return request('get', url, params=params, **kwargs)
  File "F:\scribe2\venv\lib\site-packages\requests\api.py", line 58, in request
    return session.request(method=method, url=url, **kwargs)
  File "F:\scribe2\venv\lib\site-packages\requests\sessions.py", line 508, in request
    resp = self.send(prep, **send_kwargs)
  File "F:\scribe2\venv\lib\site-packages\requests\sessions.py", line 618, in send
    r = adapter.send(request, **kwargs)
  File "F:\scribe2\venv\lib\site-packages\requests\adapters.py", line 496, in send
    raise ConnectTimeout(e, request=request)
requests.exceptions.ConnectTimeout: SOCKSHTTPSConnectionPool(host='www.baidu.com', port=443): Max retries exceeded with url: / (Caused by ConnectTimeoutError(<urllib3.contrib.socks.SOCKSHTTPSConnection object at 0x0000000006DC8C50>, 'Connection to www.baidu.com timed out. (connect timeout=10)'))

During handling of the above exception, another exception occurred:

Traceback (most recent call last):
  File "F:\scribe2\venv\lib\site-packages\urllib3\contrib\socks.py", line 88, in _new_conn
    **extra_kw
  File "F:\scribe2\venv\lib\site-packages\socks.py", line 262, in create_connection
    raise err
  File "F:\scribe2\venv\lib\site-packages\socks.py", line 252, in create_connection
    sock.connect((remote_host, remote_port))
  File "F:\scribe2\venv\lib\site-packages\socks.py", line 100, in wrapper
    return function(*args, **kwargs)
  File "F:\scribe2\venv\lib\site-packages\socks.py", line 844, in connect
    raise ProxyConnectionError(msg, error)
socks.ProxyConnectionError: Error connecting to SOCKS5 proxy 185.87.49.185:46918: timed out

During handling of the above exception, another exception occurred:

Traceback (most recent call last):
  File "F:\scribe2\venv\lib\site-packages\urllib3\connectionpool.py", line 601, in urlopen
    chunked=chunked)
  File "F:\scribe2\venv\lib\site-packages\urllib3\connectionpool.py", line 346, in _make_request
    self._validate_conn(conn)
  File "F:\scribe2\venv\lib\site-packages\urllib3\connectionpool.py", line 850, in _validate_conn
    conn.connect()
  File "F:\scribe2\venv\lib\site-packages\urllib3\connection.py", line 284, in connect
    conn = self._new_conn()
  File "F:\scribe2\venv\lib\site-packages\urllib3\contrib\socks.py", line 105, in _new_conn
    (self.host, self.timeout)
urllib3.exceptions.ConnectTimeoutError: (<urllib3.contrib.socks.SOCKSHTTPSConnection object at 0x0000000006E15438>, 'Connection to www.baidu.com timed out. (connect timeout=10)')

During handling of the above exception, another exception occurred:

Traceback (most recent call last):
  File "F:\scribe2\venv\lib\site-packages\requests\adapters.py", line 440, in send
    timeout=timeout
  File "F:\scribe2\venv\lib\site-packages\urllib3\connectionpool.py", line 639, in urlopen
    _stacktrace=sys.exc_info()[2])
  File "F:\scribe2\venv\lib\site-packages\urllib3\util\retry.py", line 388, in increment
    raise MaxRetryError(_pool, url, error or ResponseError(cause))
urllib3.exceptions.MaxRetryError: SOCKSHTTPSConnectionPool(host='www.baidu.com', port=443): Max retries exceeded with url: / (Caused by ConnectTimeoutError(<urllib3.contrib.socks.SOCKSHTTPSConnection object at 0x0000000006E15438>, 'Connection to www.baidu.com timed out. (connect timeout=10)'))

During handling of the above exception, another exception occurred:

Traceback (most recent call last):
  File "F:\scribe2\Server\Service\fanqiang_ip_service.py", line 21, in get_random_ip_port_dict
    test_proxy(ip_port_dict)
  File "F:\scribe2\Server\Service\fanqiang_ip_service.py", line 42, in test_proxy
    timeout=10)
  File "F:\scribe2\venv\lib\site-packages\requests\api.py", line 72, in get
    return request('get', url, params=params, **kwargs)
  File "F:\scribe2\venv\lib\site-packages\requests\api.py", line 58, in request
    return session.request(method=method, url=url, **kwargs)
  File "F:\scribe2\venv\lib\site-packages\requests\sessions.py", line 508, in request
    resp = self.send(prep, **send_kwargs)
  File "F:\scribe2\venv\lib\site-packages\requests\sessions.py", line 618, in send
    r = adapter.send(request, **kwargs)
  File "F:\scribe2\venv\lib\site-packages\requests\adapters.py", line 496, in send
    raise ConnectTimeout(e, request=request)
requests.exceptions.ConnectTimeout: SOCKSHTTPSConnectionPool(host='www.baidu.com', port=443): Max retries exceeded with url: / (Caused by ConnectTimeoutError(<urllib3.contrib.socks.SOCKSHTTPSConnection object at 0x0000000006E15438>, 'Connection to www.baidu.com timed out. (connect timeout=10)'))

During handling of the above exception, another exception occurred:

Traceback (most recent call last):
  File "F:\scribe2\venv\lib\site-packages\urllib3\contrib\socks.py", line 88, in _new_conn
    **extra_kw
  File "F:\scribe2\venv\lib\site-packages\socks.py", line 262, in create_connection
    raise err
  File "F:\scribe2\venv\lib\site-packages\socks.py", line 252, in create_connection
    sock.connect((remote_host, remote_port))
  File "F:\scribe2\venv\lib\site-packages\socks.py", line 100, in wrapper
    return function(*args, **kwargs)
  File "F:\scribe2\venv\lib\site-packages\socks.py", line 844, in connect
    raise ProxyConnectionError(msg, error)
socks.ProxyConnectionError: Error connecting to SOCKS5 proxy 192.169.189.215:7432: timed out

During handling of the above exception, another exception occurred:

Traceback (most recent call last):
  File "F:\scribe2\venv\lib\site-packages\urllib3\connectionpool.py", line 601, in urlopen
    chunked=chunked)
  File "F:\scribe2\venv\lib\site-packages\urllib3\connectionpool.py", line 346, in _make_request
    self._validate_conn(conn)
  File "F:\scribe2\venv\lib\site-packages\urllib3\connectionpool.py", line 850, in _validate_conn
    conn.connect()
  File "F:\scribe2\venv\lib\site-packages\urllib3\connection.py", line 284, in connect
    conn = self._new_conn()
  File "F:\scribe2\venv\lib\site-packages\urllib3\contrib\socks.py", line 105, in _new_conn
    (self.host, self.timeout)
urllib3.exceptions.ConnectTimeoutError: (<urllib3.contrib.socks.SOCKSHTTPSConnection object at 0x0000000006E5CA58>, 'Connection to www.baidu.com timed out. (connect timeout=10)')

During handling of the above exception, another exception occurred:

Traceback (most recent call last):
  File "F:\scribe2\venv\lib\site-packages\requests\adapters.py", line 440, in send
    timeout=timeout
  File "F:\scribe2\venv\lib\site-packages\urllib3\connectionpool.py", line 639, in urlopen
    _stacktrace=sys.exc_info()[2])
  File "F:\scribe2\venv\lib\site-packages\urllib3\util\retry.py", line 388, in increment
    raise MaxRetryError(_pool, url, error or ResponseError(cause))
urllib3.exceptions.MaxRetryError: SOCKSHTTPSConnectionPool(host='www.baidu.com', port=443): Max retries exceeded with url: / (Caused by ConnectTimeoutError(<urllib3.contrib.socks.SOCKSHTTPSConnection object at 0x0000000006E5CA58>, 'Connection to www.baidu.com timed out. (connect timeout=10)'))

During handling of the above exception, another exception occurred:

Traceback (most recent call last):
  File "F:\scribe2\Server\Service\fanqiang_ip_service.py", line 21, in get_random_ip_port_dict
    test_proxy(ip_port_dict)
  File "F:\scribe2\Server\Service\fanqiang_ip_service.py", line 42, in test_proxy
    timeout=10)
  File "F:\scribe2\venv\lib\site-packages\requests\api.py", line 72, in get
    return request('get', url, params=params, **kwargs)
  File "F:\scribe2\venv\lib\site-packages\requests\api.py", line 58, in request
    return session.request(method=method, url=url, **kwargs)
  File "F:\scribe2\venv\lib\site-packages\requests\sessions.py", line 508, in request
    resp = self.send(prep, **send_kwargs)
  File "F:\scribe2\venv\lib\site-packages\requests\sessions.py", line 618, in send
    r = adapter.send(request, **kwargs)
  File "F:\scribe2\venv\lib\site-packages\requests\adapters.py", line 496, in send
    raise ConnectTimeout(e, request=request)
requests.exceptions.ConnectTimeout: SOCKSHTTPSConnectionPool(host='www.baidu.com', port=443): Max retries exceeded with url: / (Caused by ConnectTimeoutError(<urllib3.contrib.socks.SOCKSHTTPSConnection object at 0x0000000006E5CA58>, 'Connection to www.baidu.com timed out. (connect timeout=10)'))

During handling of the above exception, another exception occurred:

Traceback (most recent call last):
  File "F:\scribe2\venv\lib\site-packages\urllib3\contrib\socks.py", line 88, in _new_conn
    **extra_kw
  File "F:\scribe2\venv\lib\site-packages\socks.py", line 262, in create_connection
    raise err
  File "F:\scribe2\venv\lib\site-packages\socks.py", line 252, in create_connection
    sock.connect((remote_host, remote_port))
  File "F:\scribe2\venv\lib\site-packages\socks.py", line 100, in wrapper
    return function(*args, **kwargs)
  File "F:\scribe2\venv\lib\site-packages\socks.py", line 844, in connect
    raise ProxyConnectionError(msg, error)
socks.ProxyConnectionError: Error connecting to SOCKS5 proxy 192.169.182.200:24408: timed out

During handling of the above exception, another exception occurred:

Traceback (most recent call last):
  File "F:\scribe2\venv\lib\site-packages\urllib3\connectionpool.py", line 601, in urlopen
    chunked=chunked)
  File "F:\scribe2\venv\lib\site-packages\urllib3\connectionpool.py", line 346, in _make_request
    self._validate_conn(conn)
  File "F:\scribe2\venv\lib\site-packages\urllib3\connectionpool.py", line 850, in _validate_conn
    conn.connect()
  File "F:\scribe2\venv\lib\site-packages\urllib3\connection.py", line 284, in connect
    conn = self._new_conn()
  File "F:\scribe2\venv\lib\site-packages\urllib3\contrib\socks.py", line 105, in _new_conn
    (self.host, self.timeout)
urllib3.exceptions.ConnectTimeoutError: (<urllib3.contrib.socks.SOCKSHTTPSConnection object at 0x00000000070DCB38>, 'Connection to www.baidu.com timed out. (connect timeout=10)')

During handling of the above exception, another exception occurred:

Traceback (most recent call last):
  File "F:\scribe2\venv\lib\site-packages\requests\adapters.py", line 440, in send
    timeout=timeout
  File "F:\scribe2\venv\lib\site-packages\urllib3\connectionpool.py", line 639, in urlopen
    _stacktrace=sys.exc_info()[2])
  File "F:\scribe2\venv\lib\site-packages\urllib3\util\retry.py", line 388, in increment
    raise MaxRetryError(_pool, url, error or ResponseError(cause))
urllib3.exceptions.MaxRetryError: SOCKSHTTPSConnectionPool(host='www.baidu.com', port=443): Max retries exceeded with url: / (Caused by ConnectTimeoutError(<urllib3.contrib.socks.SOCKSHTTPSConnection object at 0x00000000070DCB38>, 'Connection to www.baidu.com timed out. (connect timeout=10)'))

During handling of the above exception, another exception occurred:

Traceback (most recent call last):
  File "F:\scribe2\Server\Service\fanqiang_ip_service.py", line 21, in get_random_ip_port_dict
    test_proxy(ip_port_dict)
  File "F:\scribe2\Server\Service\fanqiang_ip_service.py", line 42, in test_proxy
    timeout=10)
  File "F:\scribe2\venv\lib\site-packages\requests\api.py", line 72, in get
    return request('get', url, params=params, **kwargs)
  File "F:\scribe2\venv\lib\site-packages\requests\api.py", line 58, in request
    return session.request(method=method, url=url, **kwargs)
  File "F:\scribe2\venv\lib\site-packages\requests\sessions.py", line 508, in request
    resp = self.send(prep, **send_kwargs)
  File "F:\scribe2\venv\lib\site-packages\requests\sessions.py", line 618, in send
    r = adapter.send(request, **kwargs)
  File "F:\scribe2\venv\lib\site-packages\requests\adapters.py", line 496, in send
    raise ConnectTimeout(e, request=request)
requests.exceptions.ConnectTimeout: SOCKSHTTPSConnectionPool(host='www.baidu.com', port=443): Max retries exceeded with url: / (Caused by ConnectTimeoutError(<urllib3.contrib.socks.SOCKSHTTPSConnection object at 0x00000000070DCB38>, 'Connection to www.baidu.com timed out. (connect timeout=10)'))

During handling of the above exception, another exception occurred:

Traceback (most recent call last):
  File "F:\scribe2\venv\lib\site-packages\urllib3\contrib\socks.py", line 88, in _new_conn
    **extra_kw
  File "F:\scribe2\venv\lib\site-packages\socks.py", line 262, in create_connection
    raise err
  File "F:\scribe2\venv\lib\site-packages\socks.py", line 252, in create_connection
    sock.connect((remote_host, remote_port))
  File "F:\scribe2\venv\lib\site-packages\socks.py", line 100, in wrapper
    return function(*args, **kwargs)
  File "F:\scribe2\venv\lib\site-packages\socks.py", line 844, in connect
    raise ProxyConnectionError(msg, error)
socks.ProxyConnectionError: Error connecting to SOCKS5 proxy 94.177.216.219:8888: timed out

During handling of the above exception, another exception occurred:

Traceback (most recent call last):
  File "F:\scribe2\venv\lib\site-packages\urllib3\connectionpool.py", line 601, in urlopen
    chunked=chunked)
  File "F:\scribe2\venv\lib\site-packages\urllib3\connectionpool.py", line 346, in _make_request
    self._validate_conn(conn)
  File "F:\scribe2\venv\lib\site-packages\urllib3\connectionpool.py", line 850, in _validate_conn
    conn.connect()
  File "F:\scribe2\venv\lib\site-packages\urllib3\connection.py", line 284, in connect
    conn = self._new_conn()
  File "F:\scribe2\venv\lib\site-packages\urllib3\contrib\socks.py", line 105, in _new_conn
    (self.host, self.timeout)
urllib3.exceptions.ConnectTimeoutError: (<urllib3.contrib.socks.SOCKSHTTPSConnection object at 0x000000000715B198>, 'Connection to www.baidu.com timed out. (connect timeout=10)')

During handling of the above exception, another exception occurred:

Traceback (most recent call last):
  File "F:\scribe2\venv\lib\site-packages\requests\adapters.py", line 440, in send
    timeout=timeout
  File "F:\scribe2\venv\lib\site-packages\urllib3\connectionpool.py", line 639, in urlopen
    _stacktrace=sys.exc_info()[2])
  File "F:\scribe2\venv\lib\site-packages\urllib3\util\retry.py", line 388, in increment
    raise MaxRetryError(_pool, url, error or ResponseError(cause))
urllib3.exceptions.MaxRetryError: SOCKSHTTPSConnectionPool(host='www.baidu.com', port=443): Max retries exceeded with url: / (Caused by ConnectTimeoutError(<urllib3.contrib.socks.SOCKSHTTPSConnection object at 0x000000000715B198>, 'Connection to www.baidu.com timed out. (connect timeout=10)'))

During handling of the above exception, another exception occurred:

Traceback (most recent call last):
  File "F:\scribe2\Server\Service\fanqiang_ip_service.py", line 21, in get_random_ip_port_dict
    test_proxy(ip_port_dict)
  File "F:\scribe2\Server\Service\fanqiang_ip_service.py", line 42, in test_proxy
    timeout=10)
  File "F:\scribe2\venv\lib\site-packages\requests\api.py", line 72, in get
    return request('get', url, params=params, **kwargs)
  File "F:\scribe2\venv\lib\site-packages\requests\api.py", line 58, in request
    return session.request(method=method, url=url, **kwargs)
  File "F:\scribe2\venv\lib\site-packages\requests\sessions.py", line 508, in request
    resp = self.send(prep, **send_kwargs)
  File "F:\scribe2\venv\lib\site-packages\requests\sessions.py", line 618, in send
    r = adapter.send(request, **kwargs)
  File "F:\scribe2\venv\lib\site-packages\requests\adapters.py", line 496, in send
    raise ConnectTimeout(e, request=request)
requests.exceptions.ConnectTimeout: SOCKSHTTPSConnectionPool(host='www.baidu.com', port=443): Max retries exceeded with url: / (Caused by ConnectTimeoutError(<urllib3.contrib.socks.SOCKSHTTPSConnection object at 0x000000000715B198>, 'Connection to www.baidu.com timed out. (connect timeout=10)'))

During handling of the above exception, another exception occurred:

Traceback (most recent call last):
  File "F:\scribe2\venv\lib\site-packages\urllib3\contrib\socks.py", line 88, in _new_conn
    **extra_kw
  File "F:\scribe2\venv\lib\site-packages\socks.py", line 262, in create_connection
    raise err
  File "F:\scribe2\venv\lib\site-packages\socks.py", line 252, in create_connection
    sock.connect((remote_host, remote_port))
  File "F:\scribe2\venv\lib\site-packages\socks.py", line 100, in wrapper
    return function(*args, **kwargs)
  File "F:\scribe2\venv\lib\site-packages\socks.py", line 855, in connect
    raise GeneralProxyError("Socket error", error)
socks.GeneralProxyError: Socket error: timed out

During handling of the above exception, another exception occurred:

Traceback (most recent call last):
  File "F:\scribe2\venv\lib\site-packages\urllib3\connectionpool.py", line 601, in urlopen
    chunked=chunked)
  File "F:\scribe2\venv\lib\site-packages\urllib3\connectionpool.py", line 346, in _make_request
    self._validate_conn(conn)
  File "F:\scribe2\venv\lib\site-packages\urllib3\connectionpool.py", line 850, in _validate_conn
    conn.connect()
  File "F:\scribe2\venv\lib\site-packages\urllib3\connection.py", line 284, in connect
    conn = self._new_conn()
  File "F:\scribe2\venv\lib\site-packages\urllib3\contrib\socks.py", line 105, in _new_conn
    (self.host, self.timeout)
urllib3.exceptions.ConnectTimeoutError: (<urllib3.contrib.socks.SOCKSHTTPSConnection object at 0x0000000007183E80>, 'Connection to www.baidu.com timed out. (connect timeout=10)')

During handling of the above exception, another exception occurred:

Traceback (most recent call last):
  File "F:\scribe2\venv\lib\site-packages\requests\adapters.py", line 440, in send
    timeout=timeout
  File "F:\scribe2\venv\lib\site-packages\urllib3\connectionpool.py", line 639, in urlopen
    _stacktrace=sys.exc_info()[2])
  File "F:\scribe2\venv\lib\site-packages\urllib3\util\retry.py", line 388, in increment
    raise MaxRetryError(_pool, url, error or ResponseError(cause))
urllib3.exceptions.MaxRetryError: SOCKSHTTPSConnectionPool(host='www.baidu.com', port=443): Max retries exceeded with url: / (Caused by ConnectTimeoutError(<urllib3.contrib.socks.SOCKSHTTPSConnection object at 0x0000000007183E80>, 'Connection to www.baidu.com timed out. (connect timeout=10)'))

During handling of the above exception, another exception occurred:

Traceback (most recent call last):
  File "F:\scribe2\Server\Service\fanqiang_ip_service.py", line 21, in get_random_ip_port_dict
    test_proxy(ip_port_dict)
  File "F:\scribe2\Server\Service\fanqiang_ip_service.py", line 42, in test_proxy
    timeout=10)
  File "F:\scribe2\venv\lib\site-packages\requests\api.py", line 72, in get
    return request('get', url, params=params, **kwargs)
  File "F:\scribe2\venv\lib\site-packages\requests\api.py", line 58, in request
    return session.request(method=method, url=url, **kwargs)
  File "F:\scribe2\venv\lib\site-packages\requests\sessions.py", line 508, in request
    resp = self.send(prep, **send_kwargs)
  File "F:\scribe2\venv\lib\site-packages\requests\sessions.py", line 618, in send
    r = adapter.send(request, **kwargs)
  File "F:\scribe2\venv\lib\site-packages\requests\adapters.py", line 496, in send
    raise ConnectTimeout(e, request=request)
requests.exceptions.ConnectTimeout: SOCKSHTTPSConnectionPool(host='www.baidu.com', port=443): Max retries exceeded with url: / (Caused by ConnectTimeoutError(<urllib3.contrib.socks.SOCKSHTTPSConnection object at 0x0000000007183E80>, 'Connection to www.baidu.com timed out. (connect timeout=10)'))

During handling of the above exception, another exception occurred:

Traceback (most recent call last):
  File "F:\scribe2\venv\lib\site-packages\urllib3\contrib\socks.py", line 88, in _new_conn
    **extra_kw
  File "F:\scribe2\venv\lib\site-packages\socks.py", line 262, in create_connection
    raise err
  File "F:\scribe2\venv\lib\site-packages\socks.py", line 252, in create_connection
    sock.connect((remote_host, remote_port))
  File "F:\scribe2\venv\lib\site-packages\socks.py", line 100, in wrapper
    return function(*args, **kwargs)
  File "F:\scribe2\venv\lib\site-packages\socks.py", line 844, in connect
    raise ProxyConnectionError(msg, error)
socks.ProxyConnectionError: Error connecting to SOCKS5 proxy 192.169.188.105:7432: timed out

During handling of the above exception, another exception occurred:

Traceback (most recent call last):
  File "F:\scribe2\venv\lib\site-packages\urllib3\connectionpool.py", line 601, in urlopen
    chunked=chunked)
  File "F:\scribe2\venv\lib\site-packages\urllib3\connectionpool.py", line 346, in _make_request
    self._validate_conn(conn)
  File "F:\scribe2\venv\lib\site-packages\urllib3\connectionpool.py", line 850, in _validate_conn
    conn.connect()
  File "F:\scribe2\venv\lib\site-packages\urllib3\connection.py", line 284, in connect
    conn = self._new_conn()
  File "F:\scribe2\venv\lib\site-packages\urllib3\contrib\socks.py", line 105, in _new_conn
    (self.host, self.timeout)
urllib3.exceptions.ConnectTimeoutError: (<urllib3.contrib.socks.SOCKSHTTPSConnection object at 0x0000000007216FD0>, 'Connection to www.baidu.com timed out. (connect timeout=10)')

During handling of the above exception, another exception occurred:

Traceback (most recent call last):
  File "F:\scribe2\venv\lib\site-packages\requests\adapters.py", line 440, in send
    timeout=timeout
  File "F:\scribe2\venv\lib\site-packages\urllib3\connectionpool.py", line 639, in urlopen
    _stacktrace=sys.exc_info()[2])
  File "F:\scribe2\venv\lib\site-packages\urllib3\util\retry.py", line 388, in increment
    raise MaxRetryError(_pool, url, error or ResponseError(cause))
urllib3.exceptions.MaxRetryError: SOCKSHTTPSConnectionPool(host='www.baidu.com', port=443): Max retries exceeded with url: / (Caused by ConnectTimeoutError(<urllib3.contrib.socks.SOCKSHTTPSConnection object at 0x0000000007216FD0>, 'Connection to www.baidu.com timed out. (connect timeout=10)'))

During handling of the above exception, another exception occurred:

Traceback (most recent call last):
  File "F:\scribe2\Server\Service\fanqiang_ip_service.py", line 21, in get_random_ip_port_dict
    test_proxy(ip_port_dict)
  File "F:\scribe2\Server\Service\fanqiang_ip_service.py", line 42, in test_proxy
    timeout=10)
  File "F:\scribe2\venv\lib\site-packages\requests\api.py", line 72, in get
    return request('get', url, params=params, **kwargs)
  File "F:\scribe2\venv\lib\site-packages\requests\api.py", line 58, in request
    return session.request(method=method, url=url, **kwargs)
  File "F:\scribe2\venv\lib\site-packages\requests\sessions.py", line 508, in request
    resp = self.send(prep, **send_kwargs)
  File "F:\scribe2\venv\lib\site-packages\requests\sessions.py", line 618, in send
    r = adapter.send(request, **kwargs)
  File "F:\scribe2\venv\lib\site-packages\requests\adapters.py", line 496, in send
    raise ConnectTimeout(e, request=request)
requests.exceptions.ConnectTimeout: SOCKSHTTPSConnectionPool(host='www.baidu.com', port=443): Max retries exceeded with url: / (Caused by ConnectTimeoutError(<urllib3.contrib.socks.SOCKSHTTPSConnection object at 0x0000000007216FD0>, 'Connection to www.baidu.com timed out. (connect timeout=10)'))

During handling of the above exception, another exception occurred:

Traceback (most recent call last):
  File "F:\scribe2\venv\lib\site-packages\urllib3\contrib\socks.py", line 88, in _new_conn
    **extra_kw
  File "F:\scribe2\venv\lib\site-packages\socks.py", line 262, in create_connection
    raise err
  File "F:\scribe2\venv\lib\site-packages\socks.py", line 252, in create_connection
    sock.connect((remote_host, remote_port))
  File "F:\scribe2\venv\lib\site-packages\socks.py", line 100, in wrapper
    return function(*args, **kwargs)
  File "F:\scribe2\venv\lib\site-packages\socks.py", line 844, in connect
    raise ProxyConnectionError(msg, error)
socks.ProxyConnectionError: Error connecting to SOCKS5 proxy 103.216.82.148:6667: timed out

During handling of the above exception, another exception occurred:

Traceback (most recent call last):
  File "F:\scribe2\venv\lib\site-packages\urllib3\connectionpool.py", line 601, in urlopen
    chunked=chunked)
  File "F:\scribe2\venv\lib\site-packages\urllib3\connectionpool.py", line 346, in _make_request
    self._validate_conn(conn)
  File "F:\scribe2\venv\lib\site-packages\urllib3\connectionpool.py", line 850, in _validate_conn
    conn.connect()
  File "F:\scribe2\venv\lib\site-packages\urllib3\connection.py", line 284, in connect
    conn = self._new_conn()
  File "F:\scribe2\venv\lib\site-packages\urllib3\contrib\socks.py", line 105, in _new_conn
    (self.host, self.timeout)
urllib3.exceptions.ConnectTimeoutError: (<urllib3.contrib.socks.SOCKSHTTPSConnection object at 0x0000000007299F60>, 'Connection to www.baidu.com timed out. (connect timeout=10)')

During handling of the above exception, another exception occurred:

Traceback (most recent call last):
  File "F:\scribe2\venv\lib\site-packages\requests\adapters.py", line 440, in send
    timeout=timeout
  File "F:\scribe2\venv\lib\site-packages\urllib3\connectionpool.py", line 639, in urlopen
    _stacktrace=sys.exc_info()[2])
  File "F:\scribe2\venv\lib\site-packages\urllib3\util\retry.py", line 388, in increment
    raise MaxRetryError(_pool, url, error or ResponseError(cause))
urllib3.exceptions.MaxRetryError: SOCKSHTTPSConnectionPool(host='www.baidu.com', port=443): Max retries exceeded with url: / (Caused by ConnectTimeoutError(<urllib3.contrib.socks.SOCKSHTTPSConnection object at 0x0000000007299F60>, 'Connection to www.baidu.com timed out. (connect timeout=10)'))

During handling of the above exception, another exception occurred:

Traceback (most recent call last):
  File "F:\scribe2\Server\Service\fanqiang_ip_service.py", line 21, in get_random_ip_port_dict
    test_proxy(ip_port_dict)
  File "F:\scribe2\Server\Service\fanqiang_ip_service.py", line 42, in test_proxy
    timeout=10)
  File "F:\scribe2\venv\lib\site-packages\requests\api.py", line 72, in get
    return request('get', url, params=params, **kwargs)
  File "F:\scribe2\venv\lib\site-packages\requests\api.py", line 58, in request
    return session.request(method=method, url=url, **kwargs)
  File "F:\scribe2\venv\lib\site-packages\requests\sessions.py", line 508, in request
    resp = self.send(prep, **send_kwargs)
  File "F:\scribe2\venv\lib\site-packages\requests\sessions.py", line 618, in send
    r = adapter.send(request, **kwargs)
  File "F:\scribe2\venv\lib\site-packages\requests\adapters.py", line 496, in send
    raise ConnectTimeout(e, request=request)
requests.exceptions.ConnectTimeout: SOCKSHTTPSConnectionPool(host='www.baidu.com', port=443): Max retries exceeded with url: / (Caused by ConnectTimeoutError(<urllib3.contrib.socks.SOCKSHTTPSConnection object at 0x0000000007299F60>, 'Connection to www.baidu.com timed out. (connect timeout=10)'))

During handling of the above exception, another exception occurred:

Traceback (most recent call last):
  File "F:/scribe2/Server/server.py", line 28, in get_lans_data
    ip_with_port=fanqiang_ip_service.get_random_ip_port_dict()
  File "F:\scribe2\Server\Service\fanqiang_ip_service.py", line 25, in get_random_ip_port_dict
    return get_random_ip_port_dict()
  File "F:\scribe2\Server\Service\fanqiang_ip_service.py", line 25, in get_random_ip_port_dict
    return get_random_ip_port_dict()
  File "F:\scribe2\Server\Service\fanqiang_ip_service.py", line 25, in get_random_ip_port_dict
    return get_random_ip_port_dict()
  [Previous line repeated 7 more times]
  File "F:\scribe2\Server\Service\fanqiang_ip_service.py", line 19, in get_random_ip_port_dict
    ip_port_dict = ip_list[math.floor(random.random() * len(ip_list))]
IndexError: list index out of range

2018-08-07 14:56:42,094 - Utils.log_utils - ERROR - e5bce674-9a0e-11e8-b843-005056c00008 - Traceback (most recent call last):
  File "F:\scribe2\venv\lib\site-packages\socks.py", line 832, in connect
    super(socksocket, self).connect(proxy_addr)
socket.timeout: timed out

During handling of the above exception, another exception occurred:

Traceback (most recent call last):
  File "F:\scribe2\venv\lib\site-packages\urllib3\contrib\socks.py", line 88, in _new_conn
    **extra_kw
  File "F:\scribe2\venv\lib\site-packages\socks.py", line 262, in create_connection
    raise err
  File "F:\scribe2\venv\lib\site-packages\socks.py", line 252, in create_connection
    sock.connect((remote_host, remote_port))
  File "F:\scribe2\venv\lib\site-packages\socks.py", line 100, in wrapper
    return function(*args, **kwargs)
  File "F:\scribe2\venv\lib\site-packages\socks.py", line 844, in connect
    raise ProxyConnectionError(msg, error)
socks.ProxyConnectionError: Error connecting to SOCKS5 proxy 192.169.182.200:24408: timed out

During handling of the above exception, another exception occurred:

Traceback (most recent call last):
  File "F:\scribe2\venv\lib\site-packages\urllib3\connectionpool.py", line 601, in urlopen
    chunked=chunked)
  File "F:\scribe2\venv\lib\site-packages\urllib3\connectionpool.py", line 346, in _make_request
    self._validate_conn(conn)
  File "F:\scribe2\venv\lib\site-packages\urllib3\connectionpool.py", line 850, in _validate_conn
    conn.connect()
  File "F:\scribe2\venv\lib\site-packages\urllib3\connection.py", line 284, in connect
    conn = self._new_conn()
  File "F:\scribe2\venv\lib\site-packages\urllib3\contrib\socks.py", line 105, in _new_conn
    (self.host, self.timeout)
urllib3.exceptions.ConnectTimeoutError: (<urllib3.contrib.socks.SOCKSHTTPSConnection object at 0x0000000006EA96D8>, 'Connection to www.baidu.com timed out. (connect timeout=10)')

During handling of the above exception, another exception occurred:

Traceback (most recent call last):
  File "F:\scribe2\venv\lib\site-packages\requests\adapters.py", line 440, in send
    timeout=timeout
  File "F:\scribe2\venv\lib\site-packages\urllib3\connectionpool.py", line 639, in urlopen
    _stacktrace=sys.exc_info()[2])
  File "F:\scribe2\venv\lib\site-packages\urllib3\util\retry.py", line 388, in increment
    raise MaxRetryError(_pool, url, error or ResponseError(cause))
urllib3.exceptions.MaxRetryError: SOCKSHTTPSConnectionPool(host='www.baidu.com', port=443): Max retries exceeded with url: / (Caused by ConnectTimeoutError(<urllib3.contrib.socks.SOCKSHTTPSConnection object at 0x0000000006EA96D8>, 'Connection to www.baidu.com timed out. (connect timeout=10)'))

During handling of the above exception, another exception occurred:

Traceback (most recent call last):
  File "F:\scribe2\Server\Service\fanqiang_ip_service.py", line 21, in get_random_ip_port_dict
    test_proxy(ip_port_dict)
  File "F:\scribe2\Server\Service\fanqiang_ip_service.py", line 42, in test_proxy
    timeout=10)
  File "F:\scribe2\venv\lib\site-packages\requests\api.py", line 72, in get
    return request('get', url, params=params, **kwargs)
  File "F:\scribe2\venv\lib\site-packages\requests\api.py", line 58, in request
    return session.request(method=method, url=url, **kwargs)
  File "F:\scribe2\venv\lib\site-packages\requests\sessions.py", line 508, in request
    resp = self.send(prep, **send_kwargs)
  File "F:\scribe2\venv\lib\site-packages\requests\sessions.py", line 618, in send
    r = adapter.send(request, **kwargs)
  File "F:\scribe2\venv\lib\site-packages\requests\adapters.py", line 496, in send
    raise ConnectTimeout(e, request=request)
requests.exceptions.ConnectTimeout: SOCKSHTTPSConnectionPool(host='www.baidu.com', port=443): Max retries exceeded with url: / (Caused by ConnectTimeoutError(<urllib3.contrib.socks.SOCKSHTTPSConnection object at 0x0000000006EA96D8>, 'Connection to www.baidu.com timed out. (connect timeout=10)'))

During handling of the above exception, another exception occurred:

Traceback (most recent call last):
  File "F:\scribe2\venv\lib\site-packages\urllib3\contrib\socks.py", line 88, in _new_conn
    **extra_kw
  File "F:\scribe2\venv\lib\site-packages\socks.py", line 262, in create_connection
    raise err
  File "F:\scribe2\venv\lib\site-packages\socks.py", line 252, in create_connection
    sock.connect((remote_host, remote_port))
  File "F:\scribe2\venv\lib\site-packages\socks.py", line 100, in wrapper
    return function(*args, **kwargs)
  File "F:\scribe2\venv\lib\site-packages\socks.py", line 844, in connect
    raise ProxyConnectionError(msg, error)
socks.ProxyConnectionError: Error connecting to SOCKS5 proxy 95.110.227.5:57201: timed out

During handling of the above exception, another exception occurred:

Traceback (most recent call last):
  File "F:\scribe2\venv\lib\site-packages\urllib3\connectionpool.py", line 601, in urlopen
    chunked=chunked)
  File "F:\scribe2\venv\lib\site-packages\urllib3\connectionpool.py", line 346, in _make_request
    self._validate_conn(conn)
  File "F:\scribe2\venv\lib\site-packages\urllib3\connectionpool.py", line 850, in _validate_conn
    conn.connect()
  File "F:\scribe2\venv\lib\site-packages\urllib3\connection.py", line 284, in connect
    conn = self._new_conn()
  File "F:\scribe2\venv\lib\site-packages\urllib3\contrib\socks.py", line 105, in _new_conn
    (self.host, self.timeout)
urllib3.exceptions.ConnectTimeoutError: (<urllib3.contrib.socks.SOCKSHTTPSConnection object at 0x0000000007118E48>, 'Connection to www.baidu.com timed out. (connect timeout=10)')

During handling of the above exception, another exception occurred:

Traceback (most recent call last):
  File "F:\scribe2\venv\lib\site-packages\requests\adapters.py", line 440, in send
    timeout=timeout
  File "F:\scribe2\venv\lib\site-packages\urllib3\connectionpool.py", line 639, in urlopen
    _stacktrace=sys.exc_info()[2])
  File "F:\scribe2\venv\lib\site-packages\urllib3\util\retry.py", line 388, in increment
    raise MaxRetryError(_pool, url, error or ResponseError(cause))
urllib3.exceptions.MaxRetryError: SOCKSHTTPSConnectionPool(host='www.baidu.com', port=443): Max retries exceeded with url: / (Caused by ConnectTimeoutError(<urllib3.contrib.socks.SOCKSHTTPSConnection object at 0x0000000007118E48>, 'Connection to www.baidu.com timed out. (connect timeout=10)'))

During handling of the above exception, another exception occurred:

Traceback (most recent call last):
  File "F:\scribe2\Server\Service\fanqiang_ip_service.py", line 21, in get_random_ip_port_dict
    test_proxy(ip_port_dict)
  File "F:\scribe2\Server\Service\fanqiang_ip_service.py", line 42, in test_proxy
    timeout=10)
  File "F:\scribe2\venv\lib\site-packages\requests\api.py", line 72, in get
    return request('get', url, params=params, **kwargs)
  File "F:\scribe2\venv\lib\site-packages\requests\api.py", line 58, in request
    return session.request(method=method, url=url, **kwargs)
  File "F:\scribe2\venv\lib\site-packages\requests\sessions.py", line 508, in request
    resp = self.send(prep, **send_kwargs)
  File "F:\scribe2\venv\lib\site-packages\requests\sessions.py", line 618, in send
    r = adapter.send(request, **kwargs)
  File "F:\scribe2\venv\lib\site-packages\requests\adapters.py", line 496, in send
    raise ConnectTimeout(e, request=request)
requests.exceptions.ConnectTimeout: SOCKSHTTPSConnectionPool(host='www.baidu.com', port=443): Max retries exceeded with url: / (Caused by ConnectTimeoutError(<urllib3.contrib.socks.SOCKSHTTPSConnection object at 0x0000000007118E48>, 'Connection to www.baidu.com timed out. (connect timeout=10)'))

During handling of the above exception, another exception occurred:

Traceback (most recent call last):
  File "F:\scribe2\venv\lib\site-packages\urllib3\contrib\socks.py", line 88, in _new_conn
    **extra_kw
  File "F:\scribe2\venv\lib\site-packages\socks.py", line 262, in create_connection
    raise err
  File "F:\scribe2\venv\lib\site-packages\socks.py", line 252, in create_connection
    sock.connect((remote_host, remote_port))
  File "F:\scribe2\venv\lib\site-packages\socks.py", line 100, in wrapper
    return function(*args, **kwargs)
  File "F:\scribe2\venv\lib\site-packages\socks.py", line 844, in connect
    raise ProxyConnectionError(msg, error)
socks.ProxyConnectionError: Error connecting to SOCKS5 proxy 146.252.241.90:56037: timed out

During handling of the above exception, another exception occurred:

Traceback (most recent call last):
  File "F:\scribe2\venv\lib\site-packages\urllib3\connectionpool.py", line 601, in urlopen
    chunked=chunked)
  File "F:\scribe2\venv\lib\site-packages\urllib3\connectionpool.py", line 346, in _make_request
    self._validate_conn(conn)
  File "F:\scribe2\venv\lib\site-packages\urllib3\connectionpool.py", line 850, in _validate_conn
    conn.connect()
  File "F:\scribe2\venv\lib\site-packages\urllib3\connection.py", line 284, in connect
    conn = self._new_conn()
  File "F:\scribe2\venv\lib\site-packages\urllib3\contrib\socks.py", line 105, in _new_conn
    (self.host, self.timeout)
urllib3.exceptions.ConnectTimeoutError: (<urllib3.contrib.socks.SOCKSHTTPSConnection object at 0x0000000006D800B8>, 'Connection to www.baidu.com timed out. (connect timeout=10)')

During handling of the above exception, another exception occurred:

Traceback (most recent call last):
  File "F:\scribe2\venv\lib\site-packages\requests\adapters.py", line 440, in send
    timeout=timeout
  File "F:\scribe2\venv\lib\site-packages\urllib3\connectionpool.py", line 639, in urlopen
    _stacktrace=sys.exc_info()[2])
  File "F:\scribe2\venv\lib\site-packages\urllib3\util\retry.py", line 388, in increment
    raise MaxRetryError(_pool, url, error or ResponseError(cause))
urllib3.exceptions.MaxRetryError: SOCKSHTTPSConnectionPool(host='www.baidu.com', port=443): Max retries exceeded with url: / (Caused by ConnectTimeoutError(<urllib3.contrib.socks.SOCKSHTTPSConnection object at 0x0000000006D800B8>, 'Connection to www.baidu.com timed out. (connect timeout=10)'))

During handling of the above exception, another exception occurred:

Traceback (most recent call last):
  File "F:\scribe2\Server\Service\fanqiang_ip_service.py", line 21, in get_random_ip_port_dict
    test_proxy(ip_port_dict)
  File "F:\scribe2\Server\Service\fanqiang_ip_service.py", line 42, in test_proxy
    timeout=10)
  File "F:\scribe2\venv\lib\site-packages\requests\api.py", line 72, in get
    return request('get', url, params=params, **kwargs)
  File "F:\scribe2\venv\lib\site-packages\requests\api.py", line 58, in request
    return session.request(method=method, url=url, **kwargs)
  File "F:\scribe2\venv\lib\site-packages\requests\sessions.py", line 508, in request
    resp = self.send(prep, **send_kwargs)
  File "F:\scribe2\venv\lib\site-packages\requests\sessions.py", line 618, in send
    r = adapter.send(request, **kwargs)
  File "F:\scribe2\venv\lib\site-packages\requests\adapters.py", line 496, in send
    raise ConnectTimeout(e, request=request)
requests.exceptions.ConnectTimeout: SOCKSHTTPSConnectionPool(host='www.baidu.com', port=443): Max retries exceeded with url: / (Caused by ConnectTimeoutError(<urllib3.contrib.socks.SOCKSHTTPSConnection object at 0x0000000006D800B8>, 'Connection to www.baidu.com timed out. (connect timeout=10)'))

During handling of the above exception, another exception occurred:

Traceback (most recent call last):
  File "F:\scribe2\venv\lib\site-packages\urllib3\contrib\socks.py", line 88, in _new_conn
    **extra_kw
  File "F:\scribe2\venv\lib\site-packages\socks.py", line 262, in create_connection
    raise err
  File "F:\scribe2\venv\lib\site-packages\socks.py", line 252, in create_connection
    sock.connect((remote_host, remote_port))
  File "F:\scribe2\venv\lib\site-packages\socks.py", line 100, in wrapper
    return function(*args, **kwargs)
  File "F:\scribe2\venv\lib\site-packages\socks.py", line 844, in connect
    raise ProxyConnectionError(msg, error)
socks.ProxyConnectionError: Error connecting to SOCKS5 proxy 192.169.217.40:35968: timed out

During handling of the above exception, another exception occurred:

Traceback (most recent call last):
  File "F:\scribe2\venv\lib\site-packages\urllib3\connectionpool.py", line 601, in urlopen
    chunked=chunked)
  File "F:\scribe2\venv\lib\site-packages\urllib3\connectionpool.py", line 346, in _make_request
    self._validate_conn(conn)
  File "F:\scribe2\venv\lib\site-packages\urllib3\connectionpool.py", line 850, in _validate_conn
    conn.connect()
  File "F:\scribe2\venv\lib\site-packages\urllib3\connection.py", line 284, in connect
    conn = self._new_conn()
  File "F:\scribe2\venv\lib\site-packages\urllib3\contrib\socks.py", line 105, in _new_conn
    (self.host, self.timeout)
urllib3.exceptions.ConnectTimeoutError: (<urllib3.contrib.socks.SOCKSHTTPSConnection object at 0x00000000071CCEF0>, 'Connection to www.baidu.com timed out. (connect timeout=10)')

During handling of the above exception, another exception occurred:

Traceback (most recent call last):
  File "F:\scribe2\venv\lib\site-packages\requests\adapters.py", line 440, in send
    timeout=timeout
  File "F:\scribe2\venv\lib\site-packages\urllib3\connectionpool.py", line 639, in urlopen
    _stacktrace=sys.exc_info()[2])
  File "F:\scribe2\venv\lib\site-packages\urllib3\util\retry.py", line 388, in increment
    raise MaxRetryError(_pool, url, error or ResponseError(cause))
urllib3.exceptions.MaxRetryError: SOCKSHTTPSConnectionPool(host='www.baidu.com', port=443): Max retries exceeded with url: / (Caused by ConnectTimeoutError(<urllib3.contrib.socks.SOCKSHTTPSConnection object at 0x00000000071CCEF0>, 'Connection to www.baidu.com timed out. (connect timeout=10)'))

During handling of the above exception, another exception occurred:

Traceback (most recent call last):
  File "F:\scribe2\Server\Service\fanqiang_ip_service.py", line 21, in get_random_ip_port_dict
    test_proxy(ip_port_dict)
  File "F:\scribe2\Server\Service\fanqiang_ip_service.py", line 42, in test_proxy
    timeout=10)
  File "F:\scribe2\venv\lib\site-packages\requests\api.py", line 72, in get
    return request('get', url, params=params, **kwargs)
  File "F:\scribe2\venv\lib\site-packages\requests\api.py", line 58, in request
    return session.request(method=method, url=url, **kwargs)
  File "F:\scribe2\venv\lib\site-packages\requests\sessions.py", line 508, in request
    resp = self.send(prep, **send_kwargs)
  File "F:\scribe2\venv\lib\site-packages\requests\sessions.py", line 618, in send
    r = adapter.send(request, **kwargs)
  File "F:\scribe2\venv\lib\site-packages\requests\adapters.py", line 496, in send
    raise ConnectTimeout(e, request=request)
requests.exceptions.ConnectTimeout: SOCKSHTTPSConnectionPool(host='www.baidu.com', port=443): Max retries exceeded with url: / (Caused by ConnectTimeoutError(<urllib3.contrib.socks.SOCKSHTTPSConnection object at 0x00000000071CCEF0>, 'Connection to www.baidu.com timed out. (connect timeout=10)'))

During handling of the above exception, another exception occurred:

Traceback (most recent call last):
  File "F:\scribe2\venv\lib\site-packages\urllib3\contrib\socks.py", line 88, in _new_conn
    **extra_kw
  File "F:\scribe2\venv\lib\site-packages\socks.py", line 262, in create_connection
    raise err
  File "F:\scribe2\venv\lib\site-packages\socks.py", line 252, in create_connection
    sock.connect((remote_host, remote_port))
  File "F:\scribe2\venv\lib\site-packages\socks.py", line 100, in wrapper
    return function(*args, **kwargs)
  File "F:\scribe2\venv\lib\site-packages\socks.py", line 844, in connect
    raise ProxyConnectionError(msg, error)
socks.ProxyConnectionError: Error connecting to SOCKS5 proxy 192.169.188.105:7432: timed out

During handling of the above exception, another exception occurred:

Traceback (most recent call last):
  File "F:\scribe2\venv\lib\site-packages\urllib3\connectionpool.py", line 601, in urlopen
    chunked=chunked)
  File "F:\scribe2\venv\lib\site-packages\urllib3\connectionpool.py", line 346, in _make_request
    self._validate_conn(conn)
  File "F:\scribe2\venv\lib\site-packages\urllib3\connectionpool.py", line 850, in _validate_conn
    conn.connect()
  File "F:\scribe2\venv\lib\site-packages\urllib3\connection.py", line 284, in connect
    conn = self._new_conn()
  File "F:\scribe2\venv\lib\site-packages\urllib3\contrib\socks.py", line 105, in _new_conn
    (self.host, self.timeout)
urllib3.exceptions.ConnectTimeoutError: (<urllib3.contrib.socks.SOCKSHTTPSConnection object at 0x0000000007258AC8>, 'Connection to www.baidu.com timed out. (connect timeout=10)')

During handling of the above exception, another exception occurred:

Traceback (most recent call last):
  File "F:\scribe2\venv\lib\site-packages\requests\adapters.py", line 440, in send
    timeout=timeout
  File "F:\scribe2\venv\lib\site-packages\urllib3\connectionpool.py", line 639, in urlopen
    _stacktrace=sys.exc_info()[2])
  File "F:\scribe2\venv\lib\site-packages\urllib3\util\retry.py", line 388, in increment
    raise MaxRetryError(_pool, url, error or ResponseError(cause))
urllib3.exceptions.MaxRetryError: SOCKSHTTPSConnectionPool(host='www.baidu.com', port=443): Max retries exceeded with url: / (Caused by ConnectTimeoutError(<urllib3.contrib.socks.SOCKSHTTPSConnection object at 0x0000000007258AC8>, 'Connection to www.baidu.com timed out. (connect timeout=10)'))

During handling of the above exception, another exception occurred:

Traceback (most recent call last):
  File "F:\scribe2\Server\Service\fanqiang_ip_service.py", line 21, in get_random_ip_port_dict
    test_proxy(ip_port_dict)
  File "F:\scribe2\Server\Service\fanqiang_ip_service.py", line 42, in test_proxy
    timeout=10)
  File "F:\scribe2\venv\lib\site-packages\requests\api.py", line 72, in get
    return request('get', url, params=params, **kwargs)
  File "F:\scribe2\venv\lib\site-packages\requests\api.py", line 58, in request
    return session.request(method=method, url=url, **kwargs)
  File "F:\scribe2\venv\lib\site-packages\requests\sessions.py", line 508, in request
    resp = self.send(prep, **send_kwargs)
  File "F:\scribe2\venv\lib\site-packages\requests\sessions.py", line 618, in send
    r = adapter.send(request, **kwargs)
  File "F:\scribe2\venv\lib\site-packages\requests\adapters.py", line 496, in send
    raise ConnectTimeout(e, request=request)
requests.exceptions.ConnectTimeout: SOCKSHTTPSConnectionPool(host='www.baidu.com', port=443): Max retries exceeded with url: / (Caused by ConnectTimeoutError(<urllib3.contrib.socks.SOCKSHTTPSConnection object at 0x0000000007258AC8>, 'Connection to www.baidu.com timed out. (connect timeout=10)'))

During handling of the above exception, another exception occurred:

Traceback (most recent call last):
  File "F:\scribe2\venv\lib\site-packages\urllib3\contrib\socks.py", line 88, in _new_conn
    **extra_kw
  File "F:\scribe2\venv\lib\site-packages\socks.py", line 262, in create_connection
    raise err
  File "F:\scribe2\venv\lib\site-packages\socks.py", line 252, in create_connection
    sock.connect((remote_host, remote_port))
  File "F:\scribe2\venv\lib\site-packages\socks.py", line 100, in wrapper
    return function(*args, **kwargs)
  File "F:\scribe2\venv\lib\site-packages\socks.py", line 844, in connect
    raise ProxyConnectionError(msg, error)
socks.ProxyConnectionError: Error connecting to SOCKS5 proxy 103.216.82.148:6667: timed out

During handling of the above exception, another exception occurred:

Traceback (most recent call last):
  File "F:\scribe2\venv\lib\site-packages\urllib3\connectionpool.py", line 601, in urlopen
    chunked=chunked)
  File "F:\scribe2\venv\lib\site-packages\urllib3\connectionpool.py", line 346, in _make_request
    self._validate_conn(conn)
  File "F:\scribe2\venv\lib\site-packages\urllib3\connectionpool.py", line 850, in _validate_conn
    conn.connect()
  File "F:\scribe2\venv\lib\site-packages\urllib3\connection.py", line 284, in connect
    conn = self._new_conn()
  File "F:\scribe2\venv\lib\site-packages\urllib3\contrib\socks.py", line 105, in _new_conn
    (self.host, self.timeout)
urllib3.exceptions.ConnectTimeoutError: (<urllib3.contrib.socks.SOCKSHTTPSConnection object at 0x00000000072EE8D0>, 'Connection to www.baidu.com timed out. (connect timeout=10)')

During handling of the above exception, another exception occurred:

Traceback (most recent call last):
  File "F:\scribe2\venv\lib\site-packages\requests\adapters.py", line 440, in send
    timeout=timeout
  File "F:\scribe2\venv\lib\site-packages\urllib3\connectionpool.py", line 639, in urlopen
    _stacktrace=sys.exc_info()[2])
  File "F:\scribe2\venv\lib\site-packages\urllib3\util\retry.py", line 388, in increment
    raise MaxRetryError(_pool, url, error or ResponseError(cause))
urllib3.exceptions.MaxRetryError: SOCKSHTTPSConnectionPool(host='www.baidu.com', port=443): Max retries exceeded with url: / (Caused by ConnectTimeoutError(<urllib3.contrib.socks.SOCKSHTTPSConnection object at 0x00000000072EE8D0>, 'Connection to www.baidu.com timed out. (connect timeout=10)'))

During handling of the above exception, another exception occurred:

Traceback (most recent call last):
  File "F:\scribe2\Server\Service\fanqiang_ip_service.py", line 21, in get_random_ip_port_dict
    test_proxy(ip_port_dict)
  File "F:\scribe2\Server\Service\fanqiang_ip_service.py", line 42, in test_proxy
    timeout=10)
  File "F:\scribe2\venv\lib\site-packages\requests\api.py", line 72, in get
    return request('get', url, params=params, **kwargs)
  File "F:\scribe2\venv\lib\site-packages\requests\api.py", line 58, in request
    return session.request(method=method, url=url, **kwargs)
  File "F:\scribe2\venv\lib\site-packages\requests\sessions.py", line 508, in request
    resp = self.send(prep, **send_kwargs)
  File "F:\scribe2\venv\lib\site-packages\requests\sessions.py", line 618, in send
    r = adapter.send(request, **kwargs)
  File "F:\scribe2\venv\lib\site-packages\requests\adapters.py", line 496, in send
    raise ConnectTimeout(e, request=request)
requests.exceptions.ConnectTimeout: SOCKSHTTPSConnectionPool(host='www.baidu.com', port=443): Max retries exceeded with url: / (Caused by ConnectTimeoutError(<urllib3.contrib.socks.SOCKSHTTPSConnection object at 0x00000000072EE8D0>, 'Connection to www.baidu.com timed out. (connect timeout=10)'))

During handling of the above exception, another exception occurred:

Traceback (most recent call last):
  File "F:/scribe2/Server/server.py", line 28, in get_lans_data
    ip_with_port=fanqiang_ip_service.get_random_ip_port_dict()
  File "F:\scribe2\Server\Service\fanqiang_ip_service.py", line 25, in get_random_ip_port_dict
    return get_random_ip_port_dict()
  File "F:\scribe2\Server\Service\fanqiang_ip_service.py", line 25, in get_random_ip_port_dict
    return get_random_ip_port_dict()
  File "F:\scribe2\Server\Service\fanqiang_ip_service.py", line 25, in get_random_ip_port_dict
    return get_random_ip_port_dict()
  [Previous line repeated 2 more times]
  File "F:\scribe2\Server\Service\fanqiang_ip_service.py", line 19, in get_random_ip_port_dict
    ip_port_dict = ip_list[math.floor(random.random() * len(ip_list))]
IndexError: list index out of range

2018-08-09 10:41:02,731 - Utils.log_utils - ERROR - a7672c34-9b7d-11e8-9073-005056c00008 - Traceback (most recent call last):
  File "F:/scribe2/Server/server.py", line 36, in get_new_ip_port
    ip_with_port_1,ip_with_port_2 = user_service.update_and_get_using_ip_port(account)
  File "F:\scribe2\Server\Service\user_service.py", line 30, in update_and_get_using_ip_port
    ip_port_1 , ip_port_2 = ''
ValueError: not enough values to unpack (expected 2, got 0)

2018-08-09 10:41:02,731 - Utils.log_utils - ERROR - a7672c34-9b7d-11e8-9073-005056c00008 - Traceback (most recent call last):
  File "F:/scribe2/Server/server.py", line 36, in get_new_ip_port
    ip_with_port_1,ip_with_port_2 = user_service.update_and_get_using_ip_port(account)
  File "F:\scribe2\Server\Service\user_service.py", line 30, in update_and_get_using_ip_port
    ip_port_1 , ip_port_2 = ''
ValueError: not enough values to unpack (expected 2, got 0)

2018-08-17 14:28:25,954 - Server.Service.fanqiang_ip_service - DEBUG - 开始测试123.206.56.247:1080
2018-08-17 14:29:41,914 - Server.Service.fanqiang_ip_service - DEBUG - 开始测试47.97.45.181:1080
2018-08-17 14:29:42,023 - Server.Service.fanqiang_ip_service - DEBUG - 开始测试45.195.200.132:1080
2018-08-17 14:29:42,048 - Server.Service.fanqiang_ip_service - DEBUG - 开始测试188.120.239.196:12249
2018-08-17 14:29:42,074 - Server.Service.fanqiang_ip_service - DEBUG - 开始测试192.169.217.40:5756
2018-08-17 14:29:42,083 - Server.Service.fanqiang_ip_service - DEBUG - 开始测试45.195.200.132:1080
2018-08-17 14:29:42,095 - Server.Service.fanqiang_ip_service - DEBUG - 开始测试50.63.153.173:12510
2018-08-17 14:29:42,108 - Server.Service.fanqiang_ip_service - DEBUG - 开始测试192.169.199.36:15199
2018-08-17 14:29:42,133 - Server.Service.fanqiang_ip_service - DEBUG - 开始测试103.216.82.186:6667
2018-08-17 14:29:42,148 - Server.Service.fanqiang_ip_service - DEBUG - 45.195.200.132:1080 失败
2018-08-17 14:29:42,203 - Server.Service.fanqiang_ip_service - DEBUG - 开始测试192.169.199.36:15199
2018-08-17 14:29:42,223 - Server.Service.fanqiang_ip_service - DEBUG - 开始测试109.200.132.146:8888
2018-08-17 14:29:42,227 - Server.Service.fanqiang_ip_service - DEBUG - 开始测试114.67.131.222:1080
2018-08-17 14:29:42,233 - Server.Service.fanqiang_ip_service - DEBUG - 开始测试176.118.131.136:6667
2018-08-17 14:29:42,239 - Server.Service.fanqiang_ip_service - DEBUG - 开始测试114.67.131.222:1080
2018-08-17 14:29:42,241 - Server.Service.fanqiang_ip_service - DEBUG - 开始测试192.169.189.215:60962
2018-08-17 14:29:42,258 - Server.Service.fanqiang_ip_service - DEBUG - 开始测试50.63.153.173:12510
2018-08-17 14:29:42,264 - Server.Service.fanqiang_ip_service - DEBUG - 45.195.200.132:1080 失败
2018-08-17 14:29:42,276 - Server.Service.fanqiang_ip_service - DEBUG - 开始测试192.169.189.215:60962
2018-08-17 14:29:42,285 - Server.Service.fanqiang_ip_service - DEBUG - 开始测试103.216.82.213:6667
2018-08-17 14:29:42,309 - Server.Service.fanqiang_ip_service - DEBUG - 开始测试50.63.167.72:48038
2018-08-17 14:29:42,322 - Server.Service.fanqiang_ip_service - DEBUG - 开始测试118.139.176.242:40440
2018-08-17 14:29:42,343 - Server.Service.fanqiang_ip_service - DEBUG - 开始测试47.97.45.181:1080
2018-08-17 14:29:42,351 - Server.Service.fanqiang_ip_service - DEBUG - 开始测试50.63.153.173:12510
2018-08-17 14:29:42,407 - Server.Service.fanqiang_ip_service - DEBUG - 开始测试91.142.208.125:9910
2018-08-17 14:29:43,144 - Server.Service.fanqiang_ip_service - DEBUG - 114.67.131.222:1080 失败
2018-08-17 14:29:43,149 - Server.Service.fanqiang_ip_service - DEBUG - 开始测试103.216.82.206:6667
2018-08-17 14:29:43,795 - Server.Service.fanqiang_ip_service - DEBUG - 50.63.153.173:12510 失败
2018-08-17 14:29:43,798 - Server.Service.fanqiang_ip_service - DEBUG - 开始测试103.216.82.199:6667
2018-08-17 14:29:43,827 - Server.Service.fanqiang_ip_service - DEBUG - 192.169.199.36:15199 失败
2018-08-17 14:29:43,830 - Server.Service.fanqiang_ip_service - DEBUG - 开始测试47.97.45.181:1080
2018-08-17 14:29:43,946 - Server.Service.fanqiang_ip_service - DEBUG - 192.169.199.36:15199 失败
2018-08-17 14:29:43,956 - Server.Service.fanqiang_ip_service - DEBUG - 开始测试50.63.167.72:48038
2018-08-17 14:29:44,001 - Server.Service.fanqiang_ip_service - DEBUG - 50.63.167.72:48038 失败
2018-08-17 14:29:44,006 - Server.Service.fanqiang_ip_service - DEBUG - 开始测试103.216.82.206:6667
2018-08-17 14:29:44,024 - Server.Service.fanqiang_ip_service - DEBUG - 50.63.153.173:12510 失败
2018-08-17 14:29:44,027 - Server.Service.fanqiang_ip_service - DEBUG - 开始测试192.169.233.2:3898
2018-08-17 14:29:44,098 - Server.Service.fanqiang_ip_service - DEBUG - 50.63.153.173:12510 失败
2018-08-17 14:29:44,101 - Server.Service.fanqiang_ip_service - DEBUG - 开始测试64.118.86.56:12890
2018-08-17 14:29:44,536 - Server.Service.fanqiang_ip_service - DEBUG - 91.142.208.125:9910 失败
2018-08-17 14:29:44,538 - Server.Service.fanqiang_ip_service - DEBUG - 开始测试192.169.233.2:3898
2018-08-17 14:29:44,772 - Server.Service.fanqiang_ip_service - DEBUG - 114.67.131.222:1080 失败
2018-08-17 14:29:44,774 - Server.Service.fanqiang_ip_service - DEBUG - 开始测试118.139.176.242:40440
2018-08-17 14:29:45,517 - Server.Service.fanqiang_ip_service - DEBUG - 50.63.167.72:48038 失败
2018-08-17 14:29:45,520 - Server.Service.fanqiang_ip_service - DEBUG - 开始测试103.216.82.186:6667
2018-08-17 14:29:45,569 - Server.Service.fanqiang_ip_service - DEBUG - 192.169.233.2:3898 失败
2018-08-17 14:29:45,571 - Server.Service.fanqiang_ip_service - DEBUG - 开始测试192.169.217.40:5756
2018-08-17 14:29:45,923 - Server.Service.fanqiang_ip_service - DEBUG - 64.118.86.56:12890 失败
2018-08-17 14:29:45,926 - Server.Service.fanqiang_ip_service - DEBUG - 开始测试132.148.130.208:17502
2018-08-17 14:29:46,064 - Server.Service.fanqiang_ip_service - DEBUG - 192.169.233.2:3898 失败
2018-08-17 14:29:46,067 - Server.Service.fanqiang_ip_service - DEBUG - 开始测试103.216.82.186:6667
2018-08-17 14:29:47,453 - Server.Service.fanqiang_ip_service - DEBUG - 132.148.130.208:17502 失败
2018-08-17 14:29:47,455 - Server.Service.fanqiang_ip_service - DEBUG - 开始测试103.216.82.199:6667
2018-08-17 14:29:52,250 - Server.Service.fanqiang_ip_service - DEBUG - 103.216.82.186:6667 失败
2018-08-17 14:29:52,252 - Server.Service.fanqiang_ip_service - DEBUG - 开始测试103.216.82.199:6667
2018-08-17 14:29:52,346 - Server.Service.fanqiang_ip_service - DEBUG - 109.200.132.146:8888 失败
2018-08-17 14:29:52,348 - Server.Service.fanqiang_ip_service - DEBUG - 开始测试103.85.92.132:1080
2018-08-17 14:29:53,169 - Server.Service.fanqiang_ip_service - DEBUG - 103.216.82.206:6667 失败
2018-08-17 14:29:53,171 - Server.Service.fanqiang_ip_service - DEBUG - 开始测试123.112.203.209:1080
2018-08-17 14:29:53,814 - Server.Service.fanqiang_ip_service - DEBUG - 103.216.82.199:6667 失败
2018-08-17 14:29:53,817 - Server.Service.fanqiang_ip_service - DEBUG - 开始测试64.118.87.12:12890
2018-08-17 14:29:54,028 - Server.Service.fanqiang_ip_service - DEBUG - 103.216.82.206:6667 失败
2018-08-17 14:29:54,031 - Server.Service.fanqiang_ip_service - DEBUG - 开始测试123.206.56.247:1080
2018-08-17 14:29:55,139 - Server.Service.fanqiang_ip_service - DEBUG - 103.85.92.132:1080 失败
2018-08-17 14:29:55,142 - Server.Service.fanqiang_ip_service - DEBUG - 开始测试188.120.239.196:12249
2018-08-17 14:29:55,495 - Server.Service.fanqiang_ip_service - DEBUG - 64.118.87.12:12890 失败
2018-08-17 14:29:55,498 - Server.Service.fanqiang_ip_service - DEBUG - 开始测试124.195.19.18:1080
2018-08-17 14:30:03,190 - Server.Service.fanqiang_ip_service - DEBUG - 123.112.203.209:1080 失败
2018-08-17 14:30:03,193 - Server.Service.fanqiang_ip_service - DEBUG - 开始测试118.139.164.224:1864
2018-08-17 14:30:04,927 - Server.Service.fanqiang_ip_service - DEBUG - 118.139.164.224:1864 失败
2018-08-17 14:30:04,929 - Server.Service.fanqiang_ip_service - DEBUG - 开始测试188.120.234.190:9261
2018-08-17 14:30:05,519 - Server.Service.fanqiang_ip_service - DEBUG - 124.195.19.18:1080 失败
2018-08-17 14:30:05,522 - Server.Service.fanqiang_ip_service - DEBUG - 开始测试192.169.189.215:60962
2018-08-17 17:31:42,071 - __main__ - ERROR - 58e96e6c-a200-11e8-b5e4-005056c00008 - Traceback (most recent call last):
  File "F:/scribe2/Server/server.py", line 36, in get_new_ip_port
    vertify_pass,not_pass_reason = user_service.vertify_user(account,password)
ValueError: too many values to unpack (expected 2)

2018-08-17 17:35:17,702 - __main__ - ERROR - b20d8f8a-a200-11e8-8d0a-005056c00008 - Traceback (most recent call last):
  File "F:/scribe2/Server/server.py", line 36, in get_new_ip_port
    vertify_pass,not_pass_reason = user_service.vertify_user(account,password)[:1]
ValueError: not enough values to unpack (expected 2, got 1)

2018-08-17 17:44:02,919 - Server.Service.fanqiang_ip_service - DEBUG - 开始测试123.206.56.247:1080
